Not Found: /favicon.ico
"GET /favicon.ico HTTP/1.1" 404 2440
Not Found: /favicon.ico
"GET /favicon.ico HTTP/1.1" 404 2440
Internal Server Error: /core/patient/schedule_appointment/
Traceback (most recent call last):
  File "C:\Users\Rodrigo\Desktop\appointment_management\venv\Lib\site-packages\django\core\handlers\exception.py", line 55, in inner
    response = get_response(request)
               ^^^^^^^^^^^^^^^^^^^^^
  File "C:\Users\Rodrigo\Desktop\appointment_management\venv\Lib\site-packages\django\core\handlers\base.py", line 197, in _get_response
    response = wrapped_callback(request, *callback_args, **callback_kwargs)
               ^^^^^^^^^^^^^^^^^^^^^^^^^^^^^^^^^^^^^^^^^^^^^^^^^^^^^^^^^^^^
  File "C:\Users\Rodrigo\Desktop\appointment_management\venv\Lib\site-packages\django\contrib\auth\decorators.py", line 23, in _wrapper_view
    return view_func(request, *args, **kwargs)
           ^^^^^^^^^^^^^^^^^^^^^^^^^^^^^^^^^^^
  File "C:\Users\Rodrigo\Desktop\appointment_management\venv\Lib\site-packages\django\contrib\auth\decorators.py", line 23, in _wrapper_view
    return view_func(request, *args, **kwargs)
           ^^^^^^^^^^^^^^^^^^^^^^^^^^^^^^^^^^^
  File "C:\Users\Rodrigo\Desktop\appointment_management\core\views.py", line 52, in schedule_appointment_patient
    return render(request, 'patient/schedule_appointment.html', {
           ^^^^^^^^^^^^^^^^^^^^^^^^^^^^^^^^^^^^^^^^^^^^^^^^^^^^^^
  File "C:\Users\Rodrigo\Desktop\appointment_management\venv\Lib\site-packages\django\shortcuts.py", line 25, in render
    content = loader.render_to_string(template_name, context, request, using=using)
              ^^^^^^^^^^^^^^^^^^^^^^^^^^^^^^^^^^^^^^^^^^^^^^^^^^^^^^^^^^^^^^^^^^^^^
  File "C:\Users\Rodrigo\Desktop\appointment_management\venv\Lib\site-packages\django\template\loader.py", line 61, in render_to_string
    template = get_template(template_name, using=using)
               ^^^^^^^^^^^^^^^^^^^^^^^^^^^^^^^^^^^^^^^^
  File "C:\Users\Rodrigo\Desktop\appointment_management\venv\Lib\site-packages\django\template\loader.py", line 15, in get_template
    return engine.get_template(template_name)
           ^^^^^^^^^^^^^^^^^^^^^^^^^^^^^^^^^^
  File "C:\Users\Rodrigo\Desktop\appointment_management\venv\Lib\site-packages\django\template\backends\django.py", line 33, in get_template
    return Template(self.engine.get_template(template_name), self)
                    ^^^^^^^^^^^^^^^^^^^^^^^^^^^^^^^^^^^^^^^
  File "C:\Users\Rodrigo\Desktop\appointment_management\venv\Lib\site-packages\django\template\engine.py", line 177, in get_template
    template, origin = self.find_template(template_name)
                       ^^^^^^^^^^^^^^^^^^^^^^^^^^^^^^^^^
  File "C:\Users\Rodrigo\Desktop\appointment_management\venv\Lib\site-packages\django\template\engine.py", line 159, in find_template
    template = loader.get_template(name, skip=skip)
               ^^^^^^^^^^^^^^^^^^^^^^^^^^^^^^^^^^^^
  File "C:\Users\Rodrigo\Desktop\appointment_management\venv\Lib\site-packages\django\template\loaders\cached.py", line 57, in get_template
    template = super().get_template(template_name, skip)
               ^^^^^^^^^^^^^^^^^^^^^^^^^^^^^^^^^^^^^^^^^
  File "C:\Users\Rodrigo\Desktop\appointment_management\venv\Lib\site-packages\django\template\loaders\base.py", line 28, in get_template
    return Template(
           ^^^^^^^^^
  File "C:\Users\Rodrigo\Desktop\appointment_management\venv\Lib\site-packages\django\template\base.py", line 154, in __init__
    self.nodelist = self.compile_nodelist()
                    ^^^^^^^^^^^^^^^^^^^^^^^
  File "C:\Users\Rodrigo\Desktop\appointment_management\venv\Lib\site-packages\django\template\base.py", line 196, in compile_nodelist
    return parser.parse()
           ^^^^^^^^^^^^^^
  File "C:\Users\Rodrigo\Desktop\appointment_management\venv\Lib\site-packages\django\template\base.py", line 511, in parse
    self.extend_nodelist(nodelist, compiled_result, token)
  File "C:\Users\Rodrigo\Desktop\appointment_management\venv\Lib\site-packages\django\template\base.py", line 528, in extend_nodelist
    raise self.error(
django.template.exceptions.TemplateSyntaxError: <ExtendsNode: extends 'base.html'> must be the first tag in the template.
"GET /core/patient/schedule_appointment/ HTTP/1.1" 500 151855
"GET /static/js/schedule_appointment HTTP/1.1" 404 1828
"GET /static/js/schedule_appointment HTTP/1.1" 404 1828
"GET /static/js/schedule_appointment HTTP/1.1" 404 1828
"GET /static/js/schedule_appointment HTTP/1.1" 404 1828
Not Found: /get-available-times/
"GET /get-available-times/?doctor_id=3&date=2024-09-20 HTTP/1.1" 404 2499
Not Found: /get-available-times/
"GET /get-available-times/?doctor_id=3&date=2024-09-26 HTTP/1.1" 404 2499
Not Found: /get-doctors-by-specialty/
"GET /get-doctors-by-specialty/?specialty_id=1 HTTP/1.1" 404 2497
Not Found: /get-doctors-by-specialty/
"GET /get-doctors-by-specialty/?specialty_id=1 HTTP/1.1" 404 2497
Not Found: /get-doctors-by-specialty/
"GET /get-doctors-by-specialty/?specialty_id=2 HTTP/1.1" 404 2497
Not Found: /get-doctors-by-specialty/
"GET /get-doctors-by-specialty/?specialty_id=1 HTTP/1.1" 404 2497
Not Found: /get-doctors-by-specialty/
"GET /get-doctors-by-specialty/?specialty_id=1 HTTP/1.1" 404 2497
Not Found: /favicon.ico
"GET /favicon.ico HTTP/1.1" 404 2440
Not Found: /get-doctors-by-specialty/
"GET /get-doctors-by-specialty/?specialty_id=1 HTTP/1.1" 404 2497
Internal Server Error: /core/patient/get-doctors-by-specialty/
Traceback (most recent call last):
  File "C:\Users\Rodrigo\Desktop\appointment_management\venv\Lib\site-packages\django\core\handlers\exception.py", line 55, in inner
    response = get_response(request)
               ^^^^^^^^^^^^^^^^^^^^^
  File "C:\Users\Rodrigo\Desktop\appointment_management\venv\Lib\site-packages\django\core\handlers\base.py", line 197, in _get_response
    response = wrapped_callback(request, *callback_args, **callback_kwargs)
               ^^^^^^^^^^^^^^^^^^^^^^^^^^^^^^^^^^^^^^^^^^^^^^^^^^^^^^^^^^^^
  File "C:\Users\Rodrigo\Desktop\appointment_management\venv\Lib\site-packages\django\contrib\auth\decorators.py", line 23, in _wrapper_view
    return view_func(request, *args, **kwargs)
           ^^^^^^^^^^^^^^^^^^^^^^^^^^^^^^^^^^^
  File "C:\Users\Rodrigo\Desktop\appointment_management\core\views.py", line 152, in get_doctors_by_specialty
    doctors = Doctor.objects.filter(
              ^^^^^^^^^^^^^^^^^^^^^^
  File "C:\Users\Rodrigo\Desktop\appointment_management\venv\Lib\site-packages\django\db\models\manager.py", line 87, in manager_method
    return getattr(self.get_queryset(), name)(*args, **kwargs)
           ^^^^^^^^^^^^^^^^^^^^^^^^^^^^^^^^^^^^^^^^^^^^^^^^^^^
  File "C:\Users\Rodrigo\Desktop\appointment_management\venv\Lib\site-packages\django\db\models\query.py", line 1476, in filter
    return self._filter_or_exclude(False, args, kwargs)
           ^^^^^^^^^^^^^^^^^^^^^^^^^^^^^^^^^^^^^^^^^^^^
  File "C:\Users\Rodrigo\Desktop\appointment_management\venv\Lib\site-packages\django\db\models\query.py", line 1494, in _filter_or_exclude
    clone._filter_or_exclude_inplace(negate, args, kwargs)
  File "C:\Users\Rodrigo\Desktop\appointment_management\venv\Lib\site-packages\django\db\models\query.py", line 1501, in _filter_or_exclude_inplace
    self._query.add_q(Q(*args, **kwargs))
  File "C:\Users\Rodrigo\Desktop\appointment_management\venv\Lib\site-packages\django\db\models\sql\query.py", line 1613, in add_q
    clause, _ = self._add_q(q_object, self.used_aliases)
                ^^^^^^^^^^^^^^^^^^^^^^^^^^^^^^^^^^^^^^^^
  File "C:\Users\Rodrigo\Desktop\appointment_management\venv\Lib\site-packages\django\db\models\sql\query.py", line 1645, in _add_q
    child_clause, needed_inner = self.build_filter(
                                 ^^^^^^^^^^^^^^^^^^
  File "C:\Users\Rodrigo\Desktop\appointment_management\venv\Lib\site-packages\django\db\models\sql\query.py", line 1495, in build_filter
    lookups, parts, reffed_expression = self.solve_lookup_type(arg, summarize)
                                        ^^^^^^^^^^^^^^^^^^^^^^^^^^^^^^^^^^^^^^
  File "C:\Users\Rodrigo\Desktop\appointment_management\venv\Lib\site-packages\django\db\models\sql\query.py", line 1307, in solve_lookup_type
    _, field, _, lookup_parts = self.names_to_path(lookup_splitted, self.get_meta())
                                ^^^^^^^^^^^^^^^^^^^^^^^^^^^^^^^^^^^^^^^^^^^^^^^^^^^^
  File "C:\Users\Rodrigo\Desktop\appointment_management\venv\Lib\site-packages\django\db\models\sql\query.py", line 1772, in names_to_path
    raise FieldError(
django.core.exceptions.FieldError: Cannot resolve keyword 'speciality_id' into field. Choices are: actionlog, address, birth_date, city, created_at, date_joined, doctor_appointments, email, emailaddress, first_name, genre, groups, id, identification, is_active, is_staff, is_superuser, issued_prescriptions, last_login, last_name, logentry, maternal_surname, medical_histories, middle_name, modified_at, modified_by, modified_by_id, modified_doctors, modified_histories, password, patient_appointments, phone_number, socialaccount, specialities, speciality, user_permissions, user_ptr, user_ptr_id, username
"GET /core/patient/get-doctors-by-specialty/?specialty_id=1 HTTP/1.1" 500 121566
Internal Server Error: /core/patient/get-doctors-by-specialty/
Traceback (most recent call last):
  File "C:\Users\Rodrigo\Desktop\appointment_management\venv\Lib\site-packages\django\core\handlers\exception.py", line 55, in inner
    response = get_response(request)
               ^^^^^^^^^^^^^^^^^^^^^
  File "C:\Users\Rodrigo\Desktop\appointment_management\venv\Lib\site-packages\django\core\handlers\base.py", line 197, in _get_response
    response = wrapped_callback(request, *callback_args, **callback_kwargs)
               ^^^^^^^^^^^^^^^^^^^^^^^^^^^^^^^^^^^^^^^^^^^^^^^^^^^^^^^^^^^^
  File "C:\Users\Rodrigo\Desktop\appointment_management\venv\Lib\site-packages\django\contrib\auth\decorators.py", line 23, in _wrapper_view
    return view_func(request, *args, **kwargs)
           ^^^^^^^^^^^^^^^^^^^^^^^^^^^^^^^^^^^
  File "C:\Users\Rodrigo\Desktop\appointment_management\core\views.py", line 152, in get_doctors_by_specialty
    doctors = Doctor.objects.filter(
              ^^^^^^^^^^^^^^^^^^^^^^
  File "C:\Users\Rodrigo\Desktop\appointment_management\venv\Lib\site-packages\django\db\models\manager.py", line 87, in manager_method
    return getattr(self.get_queryset(), name)(*args, **kwargs)
           ^^^^^^^^^^^^^^^^^^^^^^^^^^^^^^^^^^^^^^^^^^^^^^^^^^^
  File "C:\Users\Rodrigo\Desktop\appointment_management\venv\Lib\site-packages\django\db\models\query.py", line 1476, in filter
    return self._filter_or_exclude(False, args, kwargs)
           ^^^^^^^^^^^^^^^^^^^^^^^^^^^^^^^^^^^^^^^^^^^^
  File "C:\Users\Rodrigo\Desktop\appointment_management\venv\Lib\site-packages\django\db\models\query.py", line 1494, in _filter_or_exclude
    clone._filter_or_exclude_inplace(negate, args, kwargs)
  File "C:\Users\Rodrigo\Desktop\appointment_management\venv\Lib\site-packages\django\db\models\query.py", line 1501, in _filter_or_exclude_inplace
    self._query.add_q(Q(*args, **kwargs))
  File "C:\Users\Rodrigo\Desktop\appointment_management\venv\Lib\site-packages\django\db\models\sql\query.py", line 1613, in add_q
    clause, _ = self._add_q(q_object, self.used_aliases)
                ^^^^^^^^^^^^^^^^^^^^^^^^^^^^^^^^^^^^^^^^
  File "C:\Users\Rodrigo\Desktop\appointment_management\venv\Lib\site-packages\django\db\models\sql\query.py", line 1645, in _add_q
    child_clause, needed_inner = self.build_filter(
                                 ^^^^^^^^^^^^^^^^^^
  File "C:\Users\Rodrigo\Desktop\appointment_management\venv\Lib\site-packages\django\db\models\sql\query.py", line 1495, in build_filter
    lookups, parts, reffed_expression = self.solve_lookup_type(arg, summarize)
                                        ^^^^^^^^^^^^^^^^^^^^^^^^^^^^^^^^^^^^^^
  File "C:\Users\Rodrigo\Desktop\appointment_management\venv\Lib\site-packages\django\db\models\sql\query.py", line 1307, in solve_lookup_type
    _, field, _, lookup_parts = self.names_to_path(lookup_splitted, self.get_meta())
                                ^^^^^^^^^^^^^^^^^^^^^^^^^^^^^^^^^^^^^^^^^^^^^^^^^^^^
  File "C:\Users\Rodrigo\Desktop\appointment_management\venv\Lib\site-packages\django\db\models\sql\query.py", line 1772, in names_to_path
    raise FieldError(
django.core.exceptions.FieldError: Cannot resolve keyword 'speciality_id' into field. Choices are: actionlog, address, birth_date, city, created_at, date_joined, doctor_appointments, email, emailaddress, first_name, genre, groups, id, identification, is_active, is_staff, is_superuser, issued_prescriptions, last_login, last_name, logentry, maternal_surname, medical_histories, middle_name, modified_at, modified_by, modified_by_id, modified_doctors, modified_histories, password, patient_appointments, phone_number, socialaccount, specialities, speciality, user_permissions, user_ptr, user_ptr_id, username
"GET /core/patient/get-doctors-by-specialty/?specialty_id=2 HTTP/1.1" 500 121566
Not Found: /favicon.ico
"GET /favicon.ico HTTP/1.1" 404 2440
Bad Request: /core/get-available-times/
"GET /core/get-available-times/ HTTP/1.1" 400 43
Not Found: /core/patient/get-doctors-by-specialty/
"GET /core/patient/get-doctors-by-specialty/?specialty_id=1 HTTP/1.1" 404 5119
Not Found: /core/patient/get-doctors-by-specialty
"GET /core/patient/get-doctors-by-specialty HTTP/1.1" 404 5101
Bad Request: /core/get-doctors-by-specialty/
"GET /core/get-doctors-by-specialty/ HTTP/1.1" 400 36
Internal Server Error: /core/get-doctors-by-specialty/2
Traceback (most recent call last):
  File "C:\Users\Rodrigo\Desktop\appointment_management\venv\Lib\site-packages\django\core\handlers\exception.py", line 55, in inner
    response = get_response(request)
               ^^^^^^^^^^^^^^^^^^^^^
  File "C:\Users\Rodrigo\Desktop\appointment_management\venv\Lib\site-packages\django\core\handlers\base.py", line 197, in _get_response
    response = wrapped_callback(request, *callback_args, **callback_kwargs)
               ^^^^^^^^^^^^^^^^^^^^^^^^^^^^^^^^^^^^^^^^^^^^^^^^^^^^^^^^^^^^
  File "C:\Users\Rodrigo\Desktop\appointment_management\venv\Lib\site-packages\django\contrib\auth\decorators.py", line 23, in _wrapper_view
    return view_func(request, *args, **kwargs)
           ^^^^^^^^^^^^^^^^^^^^^^^^^^^^^^^^^^^
  File "C:\Users\Rodrigo\Desktop\appointment_management\core\views.py", line 147, in get_doctors_by_specialty
    doctors = list(Doctor.objects.filter(specialty_id=specialty_id).values())
                   ^^^^^^^^^^^^^^^^^^^^^^^^^^^^^^^^^^^^^^^^^^^^^^^^
  File "C:\Users\Rodrigo\Desktop\appointment_management\venv\Lib\site-packages\django\db\models\manager.py", line 87, in manager_method
    return getattr(self.get_queryset(), name)(*args, **kwargs)
           ^^^^^^^^^^^^^^^^^^^^^^^^^^^^^^^^^^^^^^^^^^^^^^^^^^^
  File "C:\Users\Rodrigo\Desktop\appointment_management\venv\Lib\site-packages\django\db\models\query.py", line 1476, in filter
    return self._filter_or_exclude(False, args, kwargs)
           ^^^^^^^^^^^^^^^^^^^^^^^^^^^^^^^^^^^^^^^^^^^^
  File "C:\Users\Rodrigo\Desktop\appointment_management\venv\Lib\site-packages\django\db\models\query.py", line 1494, in _filter_or_exclude
    clone._filter_or_exclude_inplace(negate, args, kwargs)
  File "C:\Users\Rodrigo\Desktop\appointment_management\venv\Lib\site-packages\django\db\models\query.py", line 1501, in _filter_or_exclude_inplace
    self._query.add_q(Q(*args, **kwargs))
  File "C:\Users\Rodrigo\Desktop\appointment_management\venv\Lib\site-packages\django\db\models\sql\query.py", line 1613, in add_q
    clause, _ = self._add_q(q_object, self.used_aliases)
                ^^^^^^^^^^^^^^^^^^^^^^^^^^^^^^^^^^^^^^^^
  File "C:\Users\Rodrigo\Desktop\appointment_management\venv\Lib\site-packages\django\db\models\sql\query.py", line 1645, in _add_q
    child_clause, needed_inner = self.build_filter(
                                 ^^^^^^^^^^^^^^^^^^
  File "C:\Users\Rodrigo\Desktop\appointment_management\venv\Lib\site-packages\django\db\models\sql\query.py", line 1495, in build_filter
    lookups, parts, reffed_expression = self.solve_lookup_type(arg, summarize)
                                        ^^^^^^^^^^^^^^^^^^^^^^^^^^^^^^^^^^^^^^
  File "C:\Users\Rodrigo\Desktop\appointment_management\venv\Lib\site-packages\django\db\models\sql\query.py", line 1307, in solve_lookup_type
    _, field, _, lookup_parts = self.names_to_path(lookup_splitted, self.get_meta())
                                ^^^^^^^^^^^^^^^^^^^^^^^^^^^^^^^^^^^^^^^^^^^^^^^^^^^^
  File "C:\Users\Rodrigo\Desktop\appointment_management\venv\Lib\site-packages\django\db\models\sql\query.py", line 1772, in names_to_path
    raise FieldError(
django.core.exceptions.FieldError: Cannot resolve keyword 'specialty_id' into field. Choices are: actionlog, address, birth_date, city, created_at, date_joined, doctor_appointments, email, emailaddress, first_name, genre, groups, id, identification, is_active, is_staff, is_superuser, issued_prescriptions, last_login, last_name, logentry, maternal_surname, medical_histories, middle_name, modified_at, modified_by, modified_by_id, modified_doctors, modified_histories, password, patient_appointments, phone_number, socialaccount, specialities, speciality, user_permissions, user_ptr, user_ptr_id, username
"GET /core/get-doctors-by-specialty/2 HTTP/1.1" 500 121743
Not Found: /core/
"GET /core/ HTTP/1.1" 404 5029
Not Found: /core
"GET /core HTTP/1.1" 404 2419
Not Found: /favicon.ico
"GET /favicon.ico HTTP/1.1" 404 2440
Not Found: /core/patient/schedule_appointment/specialities
"GET /core/patient/schedule_appointment/specialities HTTP/1.1" 404 5342
Not Found: /core/patient/schedule_appointment/patient/specialities
"GET /core/patient/schedule_appointment/patient/specialities HTTP/1.1" 404 5366
Not Found: /core/patient/schedule_appointment/patient/specialities
"GET /core/patient/schedule_appointment/patient/specialities HTTP/1.1" 404 5366
Not Found: /core/patient/schedule_appointment/patient/specialities
"GET /core/patient/schedule_appointment/patient/specialities HTTP/1.1" 404 5366
Not Found: /core/patient/schedule_appointment/patient/specialities
"GET /core/patient/schedule_appointment/patient/specialities HTTP/1.1" 404 5366
Not Found: /core/patient/schedule_appointment/patient/specialities
"GET /core/patient/schedule_appointment/patient/specialities HTTP/1.1" 404 5366
Not Found: /core/patient/schedule_appointment/patient/specialities
"GET /core/patient/schedule_appointment/patient/specialities HTTP/1.1" 404 5366
Not Found: /core/patient/schedule_appointment/specialities
"GET /core/patient/schedule_appointment/specialities HTTP/1.1" 404 5342
Not Found: /core/patient/schedule_appointment/specialities
"GET /core/patient/schedule_appointment/specialities HTTP/1.1" 404 5342
Not Found: /core/patient/schedule_appointment/core/specialities
"GET /core/patient/schedule_appointment/core/specialities HTTP/1.1" 404 5357
Not Found: /core/patient/specialities
"GET /core/patient/specialities HTTP/1.1" 404 5279
Not Found: /core/patient/specialities
"GET /core/patient/specialities HTTP/1.1" 404 5279
Not Found: /core/patient/specialities
"GET /core/patient/specialities HTTP/1.1" 404 5279
Not Found: /core/patient/specialities
"GET /core/patient/specialities HTTP/1.1" 404 5279
Not Found: /core/patient/specialities
"GET /core/patient/specialities HTTP/1.1" 404 5279
Not Found: /favicon.ico
"GET /favicon.ico HTTP/1.1" 404 2440
Not Found: /favicon.ico
"GET /favicon.ico HTTP/1.1" 404 2440
Not Found: /favicon.ico
"GET /favicon.ico HTTP/1.1" 404 2440
Not Found: /favicon.ico
"GET /favicon.ico HTTP/1.1" 404 2440
Internal Server Error: /core/patient/schedule_appointment/
Traceback (most recent call last):
  File "C:\Users\Rodrigo\Desktop\appointment_management\venv\Lib\site-packages\django\core\handlers\exception.py", line 55, in inner
    response = get_response(request)
               ^^^^^^^^^^^^^^^^^^^^^
  File "C:\Users\Rodrigo\Desktop\appointment_management\venv\Lib\site-packages\django\core\handlers\base.py", line 197, in _get_response
    response = wrapped_callback(request, *callback_args, **callback_kwargs)
               ^^^^^^^^^^^^^^^^^^^^^^^^^^^^^^^^^^^^^^^^^^^^^^^^^^^^^^^^^^^^
  File "C:\Users\Rodrigo\Desktop\appointment_management\venv\Lib\site-packages\django\contrib\auth\decorators.py", line 23, in _wrapper_view
    return view_func(request, *args, **kwargs)
           ^^^^^^^^^^^^^^^^^^^^^^^^^^^^^^^^^^^
  File "C:\Users\Rodrigo\Desktop\appointment_management\venv\Lib\site-packages\django\contrib\auth\decorators.py", line 23, in _wrapper_view
    return view_func(request, *args, **kwargs)
           ^^^^^^^^^^^^^^^^^^^^^^^^^^^^^^^^^^^
  File "C:\Users\Rodrigo\Desktop\appointment_management\core\views.py", line 50, in schedule_appointment_patient
    return render(request, 'patient/schedule_appointment.html', {
           ^^^^^^^^^^^^^^^^^^^^^^^^^^^^^^^^^^^^^^^^^^^^^^^^^^^^^^
  File "C:\Users\Rodrigo\Desktop\appointment_management\venv\Lib\site-packages\django\shortcuts.py", line 25, in render
    content = loader.render_to_string(template_name, context, request, using=using)
              ^^^^^^^^^^^^^^^^^^^^^^^^^^^^^^^^^^^^^^^^^^^^^^^^^^^^^^^^^^^^^^^^^^^^^
  File "C:\Users\Rodrigo\Desktop\appointment_management\venv\Lib\site-packages\django\template\loader.py", line 62, in render_to_string
    return template.render(context, request)
           ^^^^^^^^^^^^^^^^^^^^^^^^^^^^^^^^^
  File "C:\Users\Rodrigo\Desktop\appointment_management\venv\Lib\site-packages\django\template\backends\django.py", line 61, in render
    return self.template.render(context)
           ^^^^^^^^^^^^^^^^^^^^^^^^^^^^^
  File "C:\Users\Rodrigo\Desktop\appointment_management\venv\Lib\site-packages\django\template\base.py", line 171, in render
    return self._render(context)
           ^^^^^^^^^^^^^^^^^^^^^
  File "C:\Users\Rodrigo\Desktop\appointment_management\venv\Lib\site-packages\django\template\base.py", line 163, in _render
    return self.nodelist.render(context)
           ^^^^^^^^^^^^^^^^^^^^^^^^^^^^^
  File "C:\Users\Rodrigo\Desktop\appointment_management\venv\Lib\site-packages\django\template\base.py", line 1000, in render
    return SafeString("".join([node.render_annotated(context) for node in self]))
                              ^^^^^^^^^^^^^^^^^^^^^^^^^^^^^^^^^^^^^^^^^^^^^^^^^
  File "C:\Users\Rodrigo\Desktop\appointment_management\venv\Lib\site-packages\django\template\base.py", line 1000, in <listcomp>
    return SafeString("".join([node.render_annotated(context) for node in self]))
                               ^^^^^^^^^^^^^^^^^^^^^^^^^^^^^^
  File "C:\Users\Rodrigo\Desktop\appointment_management\venv\Lib\site-packages\django\template\base.py", line 961, in render_annotated
    return self.render(context)
           ^^^^^^^^^^^^^^^^^^^^
  File "C:\Users\Rodrigo\Desktop\appointment_management\venv\Lib\site-packages\django\template\loader_tags.py", line 159, in render
    return compiled_parent._render(context)
           ^^^^^^^^^^^^^^^^^^^^^^^^^^^^^^^^
  File "C:\Users\Rodrigo\Desktop\appointment_management\venv\Lib\site-packages\django\template\base.py", line 163, in _render
    return self.nodelist.render(context)
           ^^^^^^^^^^^^^^^^^^^^^^^^^^^^^
  File "C:\Users\Rodrigo\Desktop\appointment_management\venv\Lib\site-packages\django\template\base.py", line 1000, in render
    return SafeString("".join([node.render_annotated(context) for node in self]))
                              ^^^^^^^^^^^^^^^^^^^^^^^^^^^^^^^^^^^^^^^^^^^^^^^^^
  File "C:\Users\Rodrigo\Desktop\appointment_management\venv\Lib\site-packages\django\template\base.py", line 1000, in <listcomp>
    return SafeString("".join([node.render_annotated(context) for node in self]))
                               ^^^^^^^^^^^^^^^^^^^^^^^^^^^^^^
  File "C:\Users\Rodrigo\Desktop\appointment_management\venv\Lib\site-packages\django\template\base.py", line 961, in render_annotated
    return self.render(context)
           ^^^^^^^^^^^^^^^^^^^^
  File "C:\Users\Rodrigo\Desktop\appointment_management\venv\Lib\site-packages\django\template\loader_tags.py", line 65, in render
    result = block.nodelist.render(context)
             ^^^^^^^^^^^^^^^^^^^^^^^^^^^^^^
  File "C:\Users\Rodrigo\Desktop\appointment_management\venv\Lib\site-packages\django\template\base.py", line 1000, in render
    return SafeString("".join([node.render_annotated(context) for node in self]))
                              ^^^^^^^^^^^^^^^^^^^^^^^^^^^^^^^^^^^^^^^^^^^^^^^^^
  File "C:\Users\Rodrigo\Desktop\appointment_management\venv\Lib\site-packages\django\template\base.py", line 1000, in <listcomp>
    return SafeString("".join([node.render_annotated(context) for node in self]))
                               ^^^^^^^^^^^^^^^^^^^^^^^^^^^^^^
  File "C:\Users\Rodrigo\Desktop\appointment_management\venv\Lib\site-packages\django\template\base.py", line 961, in render_annotated
    return self.render(context)
           ^^^^^^^^^^^^^^^^^^^^
  File "C:\Users\Rodrigo\Desktop\appointment_management\venv\Lib\site-packages\django\template\defaulttags.py", line 479, in render
    url = reverse(view_name, args=args, kwargs=kwargs, current_app=current_app)
          ^^^^^^^^^^^^^^^^^^^^^^^^^^^^^^^^^^^^^^^^^^^^^^^^^^^^^^^^^^^^^^^^^^^^^
  File "C:\Users\Rodrigo\Desktop\appointment_management\venv\Lib\site-packages\django\urls\base.py", line 88, in reverse
    return resolver._reverse_with_prefix(view, prefix, *args, **kwargs)
           ^^^^^^^^^^^^^^^^^^^^^^^^^^^^^^^^^^^^^^^^^^^^^^^^^^^^^^^^^^^^
  File "C:\Users\Rodrigo\Desktop\appointment_management\venv\Lib\site-packages\django\urls\resolvers.py", line 851, in _reverse_with_prefix
    raise NoReverseMatch(msg)
django.urls.exceptions.NoReverseMatch: Reverse for 'book_appointment' not found. 'book_appointment' is not a valid view function or pattern name.
"GET /core/patient/schedule_appointment/ HTTP/1.1" 500 180240
Internal Server Error: /core/book-appointment/
Traceback (most recent call last):
  File "C:\Users\Rodrigo\Desktop\appointment_management\venv\Lib\site-packages\django\core\handlers\exception.py", line 55, in inner
    response = get_response(request)
               ^^^^^^^^^^^^^^^^^^^^^
  File "C:\Users\Rodrigo\Desktop\appointment_management\venv\Lib\site-packages\django\core\handlers\base.py", line 197, in _get_response
    response = wrapped_callback(request, *callback_args, **callback_kwargs)
               ^^^^^^^^^^^^^^^^^^^^^^^^^^^^^^^^^^^^^^^^^^^^^^^^^^^^^^^^^^^^
  File "C:\Users\Rodrigo\Desktop\appointment_management\venv\Lib\site-packages\django\contrib\auth\decorators.py", line 23, in _wrapper_view
    return view_func(request, *args, **kwargs)
           ^^^^^^^^^^^^^^^^^^^^^^^^^^^^^^^^^^^
  File "C:\Users\Rodrigo\Desktop\appointment_management\core\views.py", line 185, in book_appointment
    patient = User.objects.get(id=patient_id)
              ^^^^^^^^^^^^^^^^^^^^^^^^^^^^^^^
  File "C:\Users\Rodrigo\Desktop\appointment_management\venv\Lib\site-packages\django\db\models\manager.py", line 87, in manager_method
    return getattr(self.get_queryset(), name)(*args, **kwargs)
           ^^^^^^^^^^^^^^^^^^^^^^^^^^^^^^^^^^^^^^^^^^^^^^^^^^^
  File "C:\Users\Rodrigo\Desktop\appointment_management\venv\Lib\site-packages\django\db\models\query.py", line 649, in get
    raise self.model.DoesNotExist(
core.models.User.DoesNotExist: User matching query does not exist.
"POST /core/book-appointment/ HTTP/1.1" 500 85652
Internal Server Error: /core/book-appointment/
Traceback (most recent call last):
  File "C:\Users\Rodrigo\Desktop\appointment_management\venv\Lib\site-packages\django\core\handlers\exception.py", line 55, in inner
    response = get_response(request)
               ^^^^^^^^^^^^^^^^^^^^^
  File "C:\Users\Rodrigo\Desktop\appointment_management\venv\Lib\site-packages\django\core\handlers\base.py", line 197, in _get_response
    response = wrapped_callback(request, *callback_args, **callback_kwargs)
               ^^^^^^^^^^^^^^^^^^^^^^^^^^^^^^^^^^^^^^^^^^^^^^^^^^^^^^^^^^^^
  File "C:\Users\Rodrigo\Desktop\appointment_management\venv\Lib\site-packages\django\contrib\auth\decorators.py", line 23, in _wrapper_view
    return view_func(request, *args, **kwargs)
           ^^^^^^^^^^^^^^^^^^^^^^^^^^^^^^^^^^^
  File "C:\Users\Rodrigo\Desktop\appointment_management\core\views.py", line 194, in book_appointment
    appointment = Appointment.objects.create(
                  ^^^^^^^^^^^^^^^^^^^^^^^^^^^
  File "C:\Users\Rodrigo\Desktop\appointment_management\venv\Lib\site-packages\django\db\models\manager.py", line 87, in manager_method
    return getattr(self.get_queryset(), name)(*args, **kwargs)
           ^^^^^^^^^^^^^^^^^^^^^^^^^^^^^^^^^^^^^^^^^^^^^^^^^^^
  File "C:\Users\Rodrigo\Desktop\appointment_management\venv\Lib\site-packages\django\db\models\query.py", line 679, in create
    obj.save(force_insert=True, using=self.db)
  File "C:\Users\Rodrigo\Desktop\appointment_management\core\models.py", line 119, in save
    self.full_clean()
  File "C:\Users\Rodrigo\Desktop\appointment_management\venv\Lib\site-packages\django\db\models\base.py", line 1556, in full_clean
    raise ValidationError(errors)
django.core.exceptions.ValidationError: {'speciality': ['Este campo no puede ser nulo.']}
"POST /core/book-appointment/ HTTP/1.1" 500 94816
Internal Server Error: /core/book-appointment/
Traceback (most recent call last):
  File "C:\Users\Rodrigo\Desktop\appointment_management\venv\Lib\site-packages\django\core\handlers\exception.py", line 55, in inner
    response = get_response(request)
               ^^^^^^^^^^^^^^^^^^^^^
  File "C:\Users\Rodrigo\Desktop\appointment_management\venv\Lib\site-packages\django\core\handlers\base.py", line 197, in _get_response
    response = wrapped_callback(request, *callback_args, **callback_kwargs)
               ^^^^^^^^^^^^^^^^^^^^^^^^^^^^^^^^^^^^^^^^^^^^^^^^^^^^^^^^^^^^
  File "C:\Users\Rodrigo\Desktop\appointment_management\venv\Lib\site-packages\django\contrib\auth\decorators.py", line 23, in _wrapper_view
    return view_func(request, *args, **kwargs)
           ^^^^^^^^^^^^^^^^^^^^^^^^^^^^^^^^^^^
  File "C:\Users\Rodrigo\Desktop\appointment_management\core\views.py", line 194, in book_appointment
    appointment = Appointment.objects.create(
                  ^^^^^^^^^^^^^^^^^^^^^^^^^^^
  File "C:\Users\Rodrigo\Desktop\appointment_management\venv\Lib\site-packages\django\db\models\manager.py", line 87, in manager_method
    return getattr(self.get_queryset(), name)(*args, **kwargs)
           ^^^^^^^^^^^^^^^^^^^^^^^^^^^^^^^^^^^^^^^^^^^^^^^^^^^
  File "C:\Users\Rodrigo\Desktop\appointment_management\venv\Lib\site-packages\django\db\models\query.py", line 679, in create
    obj.save(force_insert=True, using=self.db)
  File "C:\Users\Rodrigo\Desktop\appointment_management\core\models.py", line 119, in save
    self.full_clean()
  File "C:\Users\Rodrigo\Desktop\appointment_management\venv\Lib\site-packages\django\db\models\base.py", line 1556, in full_clean
    raise ValidationError(errors)
django.core.exceptions.ValidationError: {'speciality': ['Este campo no puede ser nulo.']}
"POST /core/book-appointment/ HTTP/1.1" 500 94816
Internal Server Error: /core/book-appointment/
Traceback (most recent call last):
  File "C:\Users\Rodrigo\Desktop\appointment_management\venv\Lib\site-packages\django\core\handlers\exception.py", line 55, in inner
    response = get_response(request)
               ^^^^^^^^^^^^^^^^^^^^^
  File "C:\Users\Rodrigo\Desktop\appointment_management\venv\Lib\site-packages\django\core\handlers\base.py", line 197, in _get_response
    response = wrapped_callback(request, *callback_args, **callback_kwargs)
               ^^^^^^^^^^^^^^^^^^^^^^^^^^^^^^^^^^^^^^^^^^^^^^^^^^^^^^^^^^^^
  File "C:\Users\Rodrigo\Desktop\appointment_management\venv\Lib\site-packages\django\contrib\auth\decorators.py", line 23, in _wrapper_view
    return view_func(request, *args, **kwargs)
           ^^^^^^^^^^^^^^^^^^^^^^^^^^^^^^^^^^^
  File "C:\Users\Rodrigo\Desktop\appointment_management\core\views.py", line 193, in book_appointment
    appointment = Appointment.objects.create(
                  ^^^^^^^^^^^^^^^^^^^^^^^^^^^
  File "C:\Users\Rodrigo\Desktop\appointment_management\venv\Lib\site-packages\django\db\models\manager.py", line 87, in manager_method
    return getattr(self.get_queryset(), name)(*args, **kwargs)
           ^^^^^^^^^^^^^^^^^^^^^^^^^^^^^^^^^^^^^^^^^^^^^^^^^^^
  File "C:\Users\Rodrigo\Desktop\appointment_management\venv\Lib\site-packages\django\db\models\query.py", line 679, in create
    obj.save(force_insert=True, using=self.db)
  File "C:\Users\Rodrigo\Desktop\appointment_management\core\models.py", line 119, in save
    self.full_clean()
  File "C:\Users\Rodrigo\Desktop\appointment_management\venv\Lib\site-packages\django\db\models\base.py", line 1556, in full_clean
    raise ValidationError(errors)
django.core.exceptions.ValidationError: {'speciality': ['Este campo no puede ser nulo.']}
"POST /core/book-appointment/ HTTP/1.1" 500 94825
Internal Server Error: /core/book-appointment/
Traceback (most recent call last):
  File "C:\Users\Rodrigo\Desktop\appointment_management\venv\Lib\site-packages\django\core\handlers\exception.py", line 55, in inner
    response = get_response(request)
               ^^^^^^^^^^^^^^^^^^^^^
  File "C:\Users\Rodrigo\Desktop\appointment_management\venv\Lib\site-packages\django\core\handlers\base.py", line 197, in _get_response
    response = wrapped_callback(request, *callback_args, **callback_kwargs)
               ^^^^^^^^^^^^^^^^^^^^^^^^^^^^^^^^^^^^^^^^^^^^^^^^^^^^^^^^^^^^
  File "C:\Users\Rodrigo\Desktop\appointment_management\venv\Lib\site-packages\django\contrib\auth\decorators.py", line 23, in _wrapper_view
    return view_func(request, *args, **kwargs)
           ^^^^^^^^^^^^^^^^^^^^^^^^^^^^^^^^^^^
  File "C:\Users\Rodrigo\Desktop\appointment_management\core\views.py", line 193, in book_appointment
    appointment = Appointment.objects.create(
                  ^^^^^^^^^^^^^^^^^^^^^^^^^^^
  File "C:\Users\Rodrigo\Desktop\appointment_management\venv\Lib\site-packages\django\db\models\manager.py", line 87, in manager_method
    return getattr(self.get_queryset(), name)(*args, **kwargs)
           ^^^^^^^^^^^^^^^^^^^^^^^^^^^^^^^^^^^^^^^^^^^^^^^^^^^
  File "C:\Users\Rodrigo\Desktop\appointment_management\venv\Lib\site-packages\django\db\models\query.py", line 679, in create
    obj.save(force_insert=True, using=self.db)
  File "C:\Users\Rodrigo\Desktop\appointment_management\core\models.py", line 119, in save
    self.full_clean()
  File "C:\Users\Rodrigo\Desktop\appointment_management\venv\Lib\site-packages\django\db\models\base.py", line 1556, in full_clean
    raise ValidationError(errors)
django.core.exceptions.ValidationError: {'speciality': ['Este campo no puede ser nulo.']}
"POST /core/book-appointment/ HTTP/1.1" 500 94828
Not Found: /favicon.ico
"GET /favicon.ico HTTP/1.1" 404 2440
Bad Request: /core/book-appointment/
"POST /core/book-appointment/ HTTP/1.1" 400 74
Bad Request: /core/book-appointment/
"POST /core/book-appointment/ HTTP/1.1" 400 74
Not Found: /favicon.ico
"GET /favicon.ico HTTP/1.1" 404 2440
Not Found: /favicon.ico
"GET /favicon.ico HTTP/1.1" 404 2440
"GET /static/bootstrap/css/bootstrap.min.css.map HTTP/1.1" 404 1864
Not Found: /favicon.ico
"GET /favicon.ico HTTP/1.1" 404 2440
Not Found: /favicon.ico
"GET /favicon.ico HTTP/1.1" 404 2440
Not Found: /favicon.ico
"GET /favicon.ico HTTP/1.1" 404 2440
Not Found: /favicon.ico
"GET /favicon.ico HTTP/1.1" 404 2440
Not Found: /favicon.ico
"GET /favicon.ico HTTP/1.1" 404 2440
Not Found: /favicon.ico
"GET /favicon.ico HTTP/1.1" 404 2440
Not Found: /favicon.ico
"GET /favicon.ico HTTP/1.1" 404 2440
Internal Server Error: /core/book-appointment/
Traceback (most recent call last):
  File "C:\Users\Rodrigo\Desktop\appointment_management\venv\Lib\site-packages\django\db\models\fields\__init__.py", line 2117, in get_prep_value
    return int(value)
           ^^^^^^^^^^
ValueError: invalid literal for int() with base 10: ''

The above exception was the direct cause of the following exception:

Traceback (most recent call last):
  File "C:\Users\Rodrigo\Desktop\appointment_management\venv\Lib\site-packages\django\core\handlers\exception.py", line 55, in inner
    response = get_response(request)
               ^^^^^^^^^^^^^^^^^^^^^
  File "C:\Users\Rodrigo\Desktop\appointment_management\venv\Lib\site-packages\django\core\handlers\base.py", line 197, in _get_response
    response = wrapped_callback(request, *callback_args, **callback_kwargs)
               ^^^^^^^^^^^^^^^^^^^^^^^^^^^^^^^^^^^^^^^^^^^^^^^^^^^^^^^^^^^^
  File "C:\Users\Rodrigo\Desktop\appointment_management\venv\Lib\site-packages\django\contrib\auth\decorators.py", line 23, in _wrapper_view
    return view_func(request, *args, **kwargs)
           ^^^^^^^^^^^^^^^^^^^^^^^^^^^^^^^^^^^
  File "C:\Users\Rodrigo\Desktop\appointment_management\core\views.py", line 202, in book_appointment
    doctor = get_object_or_404(Doctor, id=doctor_id)
             ^^^^^^^^^^^^^^^^^^^^^^^^^^^^^^^^^^^^^^^
  File "C:\Users\Rodrigo\Desktop\appointment_management\venv\Lib\site-packages\django\shortcuts.py", line 86, in get_object_or_404
    return queryset.get(*args, **kwargs)
           ^^^^^^^^^^^^^^^^^^^^^^^^^^^^^
  File "C:\Users\Rodrigo\Desktop\appointment_management\venv\Lib\site-packages\django\db\models\query.py", line 635, in get
    clone = self._chain() if self.query.combinator else self.filter(*args, **kwargs)
                                                        ^^^^^^^^^^^^^^^^^^^^^^^^^^^^
  File "C:\Users\Rodrigo\Desktop\appointment_management\venv\Lib\site-packages\django\db\models\query.py", line 1476, in filter
    return self._filter_or_exclude(False, args, kwargs)
           ^^^^^^^^^^^^^^^^^^^^^^^^^^^^^^^^^^^^^^^^^^^^
  File "C:\Users\Rodrigo\Desktop\appointment_management\venv\Lib\site-packages\django\db\models\query.py", line 1494, in _filter_or_exclude
    clone._filter_or_exclude_inplace(negate, args, kwargs)
  File "C:\Users\Rodrigo\Desktop\appointment_management\venv\Lib\site-packages\django\db\models\query.py", line 1501, in _filter_or_exclude_inplace
    self._query.add_q(Q(*args, **kwargs))
  File "C:\Users\Rodrigo\Desktop\appointment_management\venv\Lib\site-packages\django\db\models\sql\query.py", line 1613, in add_q
    clause, _ = self._add_q(q_object, self.used_aliases)
                ^^^^^^^^^^^^^^^^^^^^^^^^^^^^^^^^^^^^^^^^
  File "C:\Users\Rodrigo\Desktop\appointment_management\venv\Lib\site-packages\django\db\models\sql\query.py", line 1645, in _add_q
    child_clause, needed_inner = self.build_filter(
                                 ^^^^^^^^^^^^^^^^^^
  File "C:\Users\Rodrigo\Desktop\appointment_management\venv\Lib\site-packages\django\db\models\sql\query.py", line 1559, in build_filter
    condition = self.build_lookup(lookups, col, value)
                ^^^^^^^^^^^^^^^^^^^^^^^^^^^^^^^^^^^^^^
  File "C:\Users\Rodrigo\Desktop\appointment_management\venv\Lib\site-packages\django\db\models\sql\query.py", line 1389, in build_lookup
    lookup = lookup_class(lhs, rhs)
             ^^^^^^^^^^^^^^^^^^^^^^
  File "C:\Users\Rodrigo\Desktop\appointment_management\venv\Lib\site-packages\django\db\models\lookups.py", line 30, in __init__
    self.rhs = self.get_prep_lookup()
               ^^^^^^^^^^^^^^^^^^^^^^
  File "C:\Users\Rodrigo\Desktop\appointment_management\venv\Lib\site-packages\django\db\models\lookups.py", line 364, in get_prep_lookup
    return super().get_prep_lookup()
           ^^^^^^^^^^^^^^^^^^^^^^^^^
  File "C:\Users\Rodrigo\Desktop\appointment_management\venv\Lib\site-packages\django\db\models\lookups.py", line 88, in get_prep_lookup
    return self.lhs.output_field.get_prep_value(self.rhs)
           ^^^^^^^^^^^^^^^^^^^^^^^^^^^^^^^^^^^^^^^^^^^^^^
  File "C:\Users\Rodrigo\Desktop\appointment_management\venv\Lib\site-packages\django\db\models\fields\__init__.py", line 2119, in get_prep_value
    raise e.__class__(
ValueError: Field 'id' expected a number but got ''.
"POST /core/book-appointment/ HTTP/1.1" 500 143173
Internal Server Error: /core/book-appointment/
Traceback (most recent call last):
  File "C:\Users\Rodrigo\Desktop\appointment_management\venv\Lib\site-packages\django\db\models\fields\__init__.py", line 2117, in get_prep_value
    return int(value)
           ^^^^^^^^^^
ValueError: invalid literal for int() with base 10: ''

The above exception was the direct cause of the following exception:

Traceback (most recent call last):
  File "C:\Users\Rodrigo\Desktop\appointment_management\venv\Lib\site-packages\django\core\handlers\exception.py", line 55, in inner
    response = get_response(request)
               ^^^^^^^^^^^^^^^^^^^^^
  File "C:\Users\Rodrigo\Desktop\appointment_management\venv\Lib\site-packages\django\core\handlers\base.py", line 197, in _get_response
    response = wrapped_callback(request, *callback_args, **callback_kwargs)
               ^^^^^^^^^^^^^^^^^^^^^^^^^^^^^^^^^^^^^^^^^^^^^^^^^^^^^^^^^^^^
  File "C:\Users\Rodrigo\Desktop\appointment_management\venv\Lib\site-packages\django\contrib\auth\decorators.py", line 23, in _wrapper_view
    return view_func(request, *args, **kwargs)
           ^^^^^^^^^^^^^^^^^^^^^^^^^^^^^^^^^^^
  File "C:\Users\Rodrigo\Desktop\appointment_management\core\views.py", line 202, in book_appointment
    doctor = get_object_or_404(Doctor, id=doctor_id)
             ^^^^^^^^^^^^^^^^^^^^^^^^^^^^^^^^^^^^^^^
  File "C:\Users\Rodrigo\Desktop\appointment_management\venv\Lib\site-packages\django\shortcuts.py", line 86, in get_object_or_404
    return queryset.get(*args, **kwargs)
           ^^^^^^^^^^^^^^^^^^^^^^^^^^^^^
  File "C:\Users\Rodrigo\Desktop\appointment_management\venv\Lib\site-packages\django\db\models\query.py", line 635, in get
    clone = self._chain() if self.query.combinator else self.filter(*args, **kwargs)
                                                        ^^^^^^^^^^^^^^^^^^^^^^^^^^^^
  File "C:\Users\Rodrigo\Desktop\appointment_management\venv\Lib\site-packages\django\db\models\query.py", line 1476, in filter
    return self._filter_or_exclude(False, args, kwargs)
           ^^^^^^^^^^^^^^^^^^^^^^^^^^^^^^^^^^^^^^^^^^^^
  File "C:\Users\Rodrigo\Desktop\appointment_management\venv\Lib\site-packages\django\db\models\query.py", line 1494, in _filter_or_exclude
    clone._filter_or_exclude_inplace(negate, args, kwargs)
  File "C:\Users\Rodrigo\Desktop\appointment_management\venv\Lib\site-packages\django\db\models\query.py", line 1501, in _filter_or_exclude_inplace
    self._query.add_q(Q(*args, **kwargs))
  File "C:\Users\Rodrigo\Desktop\appointment_management\venv\Lib\site-packages\django\db\models\sql\query.py", line 1613, in add_q
    clause, _ = self._add_q(q_object, self.used_aliases)
                ^^^^^^^^^^^^^^^^^^^^^^^^^^^^^^^^^^^^^^^^
  File "C:\Users\Rodrigo\Desktop\appointment_management\venv\Lib\site-packages\django\db\models\sql\query.py", line 1645, in _add_q
    child_clause, needed_inner = self.build_filter(
                                 ^^^^^^^^^^^^^^^^^^
  File "C:\Users\Rodrigo\Desktop\appointment_management\venv\Lib\site-packages\django\db\models\sql\query.py", line 1559, in build_filter
    condition = self.build_lookup(lookups, col, value)
                ^^^^^^^^^^^^^^^^^^^^^^^^^^^^^^^^^^^^^^
  File "C:\Users\Rodrigo\Desktop\appointment_management\venv\Lib\site-packages\django\db\models\sql\query.py", line 1389, in build_lookup
    lookup = lookup_class(lhs, rhs)
             ^^^^^^^^^^^^^^^^^^^^^^
  File "C:\Users\Rodrigo\Desktop\appointment_management\venv\Lib\site-packages\django\db\models\lookups.py", line 30, in __init__
    self.rhs = self.get_prep_lookup()
               ^^^^^^^^^^^^^^^^^^^^^^
  File "C:\Users\Rodrigo\Desktop\appointment_management\venv\Lib\site-packages\django\db\models\lookups.py", line 364, in get_prep_lookup
    return super().get_prep_lookup()
           ^^^^^^^^^^^^^^^^^^^^^^^^^
  File "C:\Users\Rodrigo\Desktop\appointment_management\venv\Lib\site-packages\django\db\models\lookups.py", line 88, in get_prep_lookup
    return self.lhs.output_field.get_prep_value(self.rhs)
           ^^^^^^^^^^^^^^^^^^^^^^^^^^^^^^^^^^^^^^^^^^^^^^
  File "C:\Users\Rodrigo\Desktop\appointment_management\venv\Lib\site-packages\django\db\models\fields\__init__.py", line 2119, in get_prep_value
    raise e.__class__(
ValueError: Field 'id' expected a number but got ''.
"POST /core/book-appointment/ HTTP/1.1" 500 143173
Internal Server Error: /core/book-appointment/
Traceback (most recent call last):
  File "C:\Users\Rodrigo\Desktop\appointment_management\venv\Lib\site-packages\django\db\models\fields\__init__.py", line 2117, in get_prep_value
    return int(value)
           ^^^^^^^^^^
ValueError: invalid literal for int() with base 10: ''

The above exception was the direct cause of the following exception:

Traceback (most recent call last):
  File "C:\Users\Rodrigo\Desktop\appointment_management\venv\Lib\site-packages\django\core\handlers\exception.py", line 55, in inner
    response = get_response(request)
               ^^^^^^^^^^^^^^^^^^^^^
  File "C:\Users\Rodrigo\Desktop\appointment_management\venv\Lib\site-packages\django\core\handlers\base.py", line 197, in _get_response
    response = wrapped_callback(request, *callback_args, **callback_kwargs)
               ^^^^^^^^^^^^^^^^^^^^^^^^^^^^^^^^^^^^^^^^^^^^^^^^^^^^^^^^^^^^
  File "C:\Users\Rodrigo\Desktop\appointment_management\venv\Lib\site-packages\django\contrib\auth\decorators.py", line 23, in _wrapper_view
    return view_func(request, *args, **kwargs)
           ^^^^^^^^^^^^^^^^^^^^^^^^^^^^^^^^^^^
  File "C:\Users\Rodrigo\Desktop\appointment_management\core\views.py", line 202, in book_appointment
    doctor = get_object_or_404(Doctor, id=doctor_id)
             ^^^^^^^^^^^^^^^^^^^^^^^^^^^^^^^^^^^^^^^
  File "C:\Users\Rodrigo\Desktop\appointment_management\venv\Lib\site-packages\django\shortcuts.py", line 86, in get_object_or_404
    return queryset.get(*args, **kwargs)
           ^^^^^^^^^^^^^^^^^^^^^^^^^^^^^
  File "C:\Users\Rodrigo\Desktop\appointment_management\venv\Lib\site-packages\django\db\models\query.py", line 635, in get
    clone = self._chain() if self.query.combinator else self.filter(*args, **kwargs)
                                                        ^^^^^^^^^^^^^^^^^^^^^^^^^^^^
  File "C:\Users\Rodrigo\Desktop\appointment_management\venv\Lib\site-packages\django\db\models\query.py", line 1476, in filter
    return self._filter_or_exclude(False, args, kwargs)
           ^^^^^^^^^^^^^^^^^^^^^^^^^^^^^^^^^^^^^^^^^^^^
  File "C:\Users\Rodrigo\Desktop\appointment_management\venv\Lib\site-packages\django\db\models\query.py", line 1494, in _filter_or_exclude
    clone._filter_or_exclude_inplace(negate, args, kwargs)
  File "C:\Users\Rodrigo\Desktop\appointment_management\venv\Lib\site-packages\django\db\models\query.py", line 1501, in _filter_or_exclude_inplace
    self._query.add_q(Q(*args, **kwargs))
  File "C:\Users\Rodrigo\Desktop\appointment_management\venv\Lib\site-packages\django\db\models\sql\query.py", line 1613, in add_q
    clause, _ = self._add_q(q_object, self.used_aliases)
                ^^^^^^^^^^^^^^^^^^^^^^^^^^^^^^^^^^^^^^^^
  File "C:\Users\Rodrigo\Desktop\appointment_management\venv\Lib\site-packages\django\db\models\sql\query.py", line 1645, in _add_q
    child_clause, needed_inner = self.build_filter(
                                 ^^^^^^^^^^^^^^^^^^
  File "C:\Users\Rodrigo\Desktop\appointment_management\venv\Lib\site-packages\django\db\models\sql\query.py", line 1559, in build_filter
    condition = self.build_lookup(lookups, col, value)
                ^^^^^^^^^^^^^^^^^^^^^^^^^^^^^^^^^^^^^^
  File "C:\Users\Rodrigo\Desktop\appointment_management\venv\Lib\site-packages\django\db\models\sql\query.py", line 1389, in build_lookup
    lookup = lookup_class(lhs, rhs)
             ^^^^^^^^^^^^^^^^^^^^^^
  File "C:\Users\Rodrigo\Desktop\appointment_management\venv\Lib\site-packages\django\db\models\lookups.py", line 30, in __init__
    self.rhs = self.get_prep_lookup()
               ^^^^^^^^^^^^^^^^^^^^^^
  File "C:\Users\Rodrigo\Desktop\appointment_management\venv\Lib\site-packages\django\db\models\lookups.py", line 364, in get_prep_lookup
    return super().get_prep_lookup()
           ^^^^^^^^^^^^^^^^^^^^^^^^^
  File "C:\Users\Rodrigo\Desktop\appointment_management\venv\Lib\site-packages\django\db\models\lookups.py", line 88, in get_prep_lookup
    return self.lhs.output_field.get_prep_value(self.rhs)
           ^^^^^^^^^^^^^^^^^^^^^^^^^^^^^^^^^^^^^^^^^^^^^^
  File "C:\Users\Rodrigo\Desktop\appointment_management\venv\Lib\site-packages\django\db\models\fields\__init__.py", line 2119, in get_prep_value
    raise e.__class__(
ValueError: Field 'id' expected a number but got ''.
"POST /core/book-appointment/ HTTP/1.1" 500 143161
Internal Server Error: /core/book-appointment/
Traceback (most recent call last):
  File "C:\Users\Rodrigo\Desktop\appointment_management\venv\Lib\site-packages\django\db\models\fields\__init__.py", line 2117, in get_prep_value
    return int(value)
           ^^^^^^^^^^
ValueError: invalid literal for int() with base 10: ''

The above exception was the direct cause of the following exception:

Traceback (most recent call last):
  File "C:\Users\Rodrigo\Desktop\appointment_management\venv\Lib\site-packages\django\core\handlers\exception.py", line 55, in inner
    response = get_response(request)
               ^^^^^^^^^^^^^^^^^^^^^
  File "C:\Users\Rodrigo\Desktop\appointment_management\venv\Lib\site-packages\django\core\handlers\base.py", line 197, in _get_response
    response = wrapped_callback(request, *callback_args, **callback_kwargs)
               ^^^^^^^^^^^^^^^^^^^^^^^^^^^^^^^^^^^^^^^^^^^^^^^^^^^^^^^^^^^^
  File "C:\Users\Rodrigo\Desktop\appointment_management\venv\Lib\site-packages\django\contrib\auth\decorators.py", line 23, in _wrapper_view
    return view_func(request, *args, **kwargs)
           ^^^^^^^^^^^^^^^^^^^^^^^^^^^^^^^^^^^
  File "C:\Users\Rodrigo\Desktop\appointment_management\core\views.py", line 202, in book_appointment
    doctor = get_object_or_404(Doctor, id=doctor_id)
             ^^^^^^^^^^^^^^^^^^^^^^^^^^^^^^^^^^^^^^^
  File "C:\Users\Rodrigo\Desktop\appointment_management\venv\Lib\site-packages\django\shortcuts.py", line 86, in get_object_or_404
    return queryset.get(*args, **kwargs)
           ^^^^^^^^^^^^^^^^^^^^^^^^^^^^^
  File "C:\Users\Rodrigo\Desktop\appointment_management\venv\Lib\site-packages\django\db\models\query.py", line 635, in get
    clone = self._chain() if self.query.combinator else self.filter(*args, **kwargs)
                                                        ^^^^^^^^^^^^^^^^^^^^^^^^^^^^
  File "C:\Users\Rodrigo\Desktop\appointment_management\venv\Lib\site-packages\django\db\models\query.py", line 1476, in filter
    return self._filter_or_exclude(False, args, kwargs)
           ^^^^^^^^^^^^^^^^^^^^^^^^^^^^^^^^^^^^^^^^^^^^
  File "C:\Users\Rodrigo\Desktop\appointment_management\venv\Lib\site-packages\django\db\models\query.py", line 1494, in _filter_or_exclude
    clone._filter_or_exclude_inplace(negate, args, kwargs)
  File "C:\Users\Rodrigo\Desktop\appointment_management\venv\Lib\site-packages\django\db\models\query.py", line 1501, in _filter_or_exclude_inplace
    self._query.add_q(Q(*args, **kwargs))
  File "C:\Users\Rodrigo\Desktop\appointment_management\venv\Lib\site-packages\django\db\models\sql\query.py", line 1613, in add_q
    clause, _ = self._add_q(q_object, self.used_aliases)
                ^^^^^^^^^^^^^^^^^^^^^^^^^^^^^^^^^^^^^^^^
  File "C:\Users\Rodrigo\Desktop\appointment_management\venv\Lib\site-packages\django\db\models\sql\query.py", line 1645, in _add_q
    child_clause, needed_inner = self.build_filter(
                                 ^^^^^^^^^^^^^^^^^^
  File "C:\Users\Rodrigo\Desktop\appointment_management\venv\Lib\site-packages\django\db\models\sql\query.py", line 1559, in build_filter
    condition = self.build_lookup(lookups, col, value)
                ^^^^^^^^^^^^^^^^^^^^^^^^^^^^^^^^^^^^^^
  File "C:\Users\Rodrigo\Desktop\appointment_management\venv\Lib\site-packages\django\db\models\sql\query.py", line 1389, in build_lookup
    lookup = lookup_class(lhs, rhs)
             ^^^^^^^^^^^^^^^^^^^^^^
  File "C:\Users\Rodrigo\Desktop\appointment_management\venv\Lib\site-packages\django\db\models\lookups.py", line 30, in __init__
    self.rhs = self.get_prep_lookup()
               ^^^^^^^^^^^^^^^^^^^^^^
  File "C:\Users\Rodrigo\Desktop\appointment_management\venv\Lib\site-packages\django\db\models\lookups.py", line 364, in get_prep_lookup
    return super().get_prep_lookup()
           ^^^^^^^^^^^^^^^^^^^^^^^^^
  File "C:\Users\Rodrigo\Desktop\appointment_management\venv\Lib\site-packages\django\db\models\lookups.py", line 88, in get_prep_lookup
    return self.lhs.output_field.get_prep_value(self.rhs)
           ^^^^^^^^^^^^^^^^^^^^^^^^^^^^^^^^^^^^^^^^^^^^^^
  File "C:\Users\Rodrigo\Desktop\appointment_management\venv\Lib\site-packages\django\db\models\fields\__init__.py", line 2119, in get_prep_value
    raise e.__class__(
ValueError: Field 'id' expected a number but got ''.
"POST /core/book-appointment/ HTTP/1.1" 500 143161
Internal Server Error: /core/book-appointment/
Traceback (most recent call last):
  File "C:\Users\Rodrigo\Desktop\appointment_management\venv\Lib\site-packages\django\db\models\fields\__init__.py", line 2117, in get_prep_value
    return int(value)
           ^^^^^^^^^^
ValueError: invalid literal for int() with base 10: ''

The above exception was the direct cause of the following exception:

Traceback (most recent call last):
  File "C:\Users\Rodrigo\Desktop\appointment_management\venv\Lib\site-packages\django\core\handlers\exception.py", line 55, in inner
    response = get_response(request)
               ^^^^^^^^^^^^^^^^^^^^^
  File "C:\Users\Rodrigo\Desktop\appointment_management\venv\Lib\site-packages\django\core\handlers\base.py", line 197, in _get_response
    response = wrapped_callback(request, *callback_args, **callback_kwargs)
               ^^^^^^^^^^^^^^^^^^^^^^^^^^^^^^^^^^^^^^^^^^^^^^^^^^^^^^^^^^^^
  File "C:\Users\Rodrigo\Desktop\appointment_management\venv\Lib\site-packages\django\contrib\auth\decorators.py", line 23, in _wrapper_view
    return view_func(request, *args, **kwargs)
           ^^^^^^^^^^^^^^^^^^^^^^^^^^^^^^^^^^^
  File "C:\Users\Rodrigo\Desktop\appointment_management\core\views.py", line 202, in book_appointment
    doctor = get_object_or_404(Doctor, id=doctor_id)
             ^^^^^^^^^^^^^^^^^^^^^^^^^^^^^^^^^^^^^^^
  File "C:\Users\Rodrigo\Desktop\appointment_management\venv\Lib\site-packages\django\shortcuts.py", line 86, in get_object_or_404
    return queryset.get(*args, **kwargs)
           ^^^^^^^^^^^^^^^^^^^^^^^^^^^^^
  File "C:\Users\Rodrigo\Desktop\appointment_management\venv\Lib\site-packages\django\db\models\query.py", line 635, in get
    clone = self._chain() if self.query.combinator else self.filter(*args, **kwargs)
                                                        ^^^^^^^^^^^^^^^^^^^^^^^^^^^^
  File "C:\Users\Rodrigo\Desktop\appointment_management\venv\Lib\site-packages\django\db\models\query.py", line 1476, in filter
    return self._filter_or_exclude(False, args, kwargs)
           ^^^^^^^^^^^^^^^^^^^^^^^^^^^^^^^^^^^^^^^^^^^^
  File "C:\Users\Rodrigo\Desktop\appointment_management\venv\Lib\site-packages\django\db\models\query.py", line 1494, in _filter_or_exclude
    clone._filter_or_exclude_inplace(negate, args, kwargs)
  File "C:\Users\Rodrigo\Desktop\appointment_management\venv\Lib\site-packages\django\db\models\query.py", line 1501, in _filter_or_exclude_inplace
    self._query.add_q(Q(*args, **kwargs))
  File "C:\Users\Rodrigo\Desktop\appointment_management\venv\Lib\site-packages\django\db\models\sql\query.py", line 1613, in add_q
    clause, _ = self._add_q(q_object, self.used_aliases)
                ^^^^^^^^^^^^^^^^^^^^^^^^^^^^^^^^^^^^^^^^
  File "C:\Users\Rodrigo\Desktop\appointment_management\venv\Lib\site-packages\django\db\models\sql\query.py", line 1645, in _add_q
    child_clause, needed_inner = self.build_filter(
                                 ^^^^^^^^^^^^^^^^^^
  File "C:\Users\Rodrigo\Desktop\appointment_management\venv\Lib\site-packages\django\db\models\sql\query.py", line 1559, in build_filter
    condition = self.build_lookup(lookups, col, value)
                ^^^^^^^^^^^^^^^^^^^^^^^^^^^^^^^^^^^^^^
  File "C:\Users\Rodrigo\Desktop\appointment_management\venv\Lib\site-packages\django\db\models\sql\query.py", line 1389, in build_lookup
    lookup = lookup_class(lhs, rhs)
             ^^^^^^^^^^^^^^^^^^^^^^
  File "C:\Users\Rodrigo\Desktop\appointment_management\venv\Lib\site-packages\django\db\models\lookups.py", line 30, in __init__
    self.rhs = self.get_prep_lookup()
               ^^^^^^^^^^^^^^^^^^^^^^
  File "C:\Users\Rodrigo\Desktop\appointment_management\venv\Lib\site-packages\django\db\models\lookups.py", line 364, in get_prep_lookup
    return super().get_prep_lookup()
           ^^^^^^^^^^^^^^^^^^^^^^^^^
  File "C:\Users\Rodrigo\Desktop\appointment_management\venv\Lib\site-packages\django\db\models\lookups.py", line 88, in get_prep_lookup
    return self.lhs.output_field.get_prep_value(self.rhs)
           ^^^^^^^^^^^^^^^^^^^^^^^^^^^^^^^^^^^^^^^^^^^^^^
  File "C:\Users\Rodrigo\Desktop\appointment_management\venv\Lib\site-packages\django\db\models\fields\__init__.py", line 2119, in get_prep_value
    raise e.__class__(
ValueError: Field 'id' expected a number but got ''.
"POST /core/book-appointment/ HTTP/1.1" 500 143161
Internal Server Error: /core/book-appointment/
Traceback (most recent call last):
  File "C:\Users\Rodrigo\Desktop\appointment_management\venv\Lib\site-packages\django\db\models\fields\__init__.py", line 2117, in get_prep_value
    return int(value)
           ^^^^^^^^^^
ValueError: invalid literal for int() with base 10: ''

The above exception was the direct cause of the following exception:

Traceback (most recent call last):
  File "C:\Users\Rodrigo\Desktop\appointment_management\venv\Lib\site-packages\django\core\handlers\exception.py", line 55, in inner
    response = get_response(request)
               ^^^^^^^^^^^^^^^^^^^^^
  File "C:\Users\Rodrigo\Desktop\appointment_management\venv\Lib\site-packages\django\core\handlers\base.py", line 197, in _get_response
    response = wrapped_callback(request, *callback_args, **callback_kwargs)
               ^^^^^^^^^^^^^^^^^^^^^^^^^^^^^^^^^^^^^^^^^^^^^^^^^^^^^^^^^^^^
  File "C:\Users\Rodrigo\Desktop\appointment_management\venv\Lib\site-packages\django\contrib\auth\decorators.py", line 23, in _wrapper_view
    return view_func(request, *args, **kwargs)
           ^^^^^^^^^^^^^^^^^^^^^^^^^^^^^^^^^^^
  File "C:\Users\Rodrigo\Desktop\appointment_management\core\views.py", line 202, in book_appointment
    doctor = get_object_or_404(Doctor, id=doctor_id)
             ^^^^^^^^^^^^^^^^^^^^^^^^^^^^^^^^^^^^^^^
  File "C:\Users\Rodrigo\Desktop\appointment_management\venv\Lib\site-packages\django\shortcuts.py", line 86, in get_object_or_404
    return queryset.get(*args, **kwargs)
           ^^^^^^^^^^^^^^^^^^^^^^^^^^^^^
  File "C:\Users\Rodrigo\Desktop\appointment_management\venv\Lib\site-packages\django\db\models\query.py", line 635, in get
    clone = self._chain() if self.query.combinator else self.filter(*args, **kwargs)
                                                        ^^^^^^^^^^^^^^^^^^^^^^^^^^^^
  File "C:\Users\Rodrigo\Desktop\appointment_management\venv\Lib\site-packages\django\db\models\query.py", line 1476, in filter
    return self._filter_or_exclude(False, args, kwargs)
           ^^^^^^^^^^^^^^^^^^^^^^^^^^^^^^^^^^^^^^^^^^^^
  File "C:\Users\Rodrigo\Desktop\appointment_management\venv\Lib\site-packages\django\db\models\query.py", line 1494, in _filter_or_exclude
    clone._filter_or_exclude_inplace(negate, args, kwargs)
  File "C:\Users\Rodrigo\Desktop\appointment_management\venv\Lib\site-packages\django\db\models\query.py", line 1501, in _filter_or_exclude_inplace
    self._query.add_q(Q(*args, **kwargs))
  File "C:\Users\Rodrigo\Desktop\appointment_management\venv\Lib\site-packages\django\db\models\sql\query.py", line 1613, in add_q
    clause, _ = self._add_q(q_object, self.used_aliases)
                ^^^^^^^^^^^^^^^^^^^^^^^^^^^^^^^^^^^^^^^^
  File "C:\Users\Rodrigo\Desktop\appointment_management\venv\Lib\site-packages\django\db\models\sql\query.py", line 1645, in _add_q
    child_clause, needed_inner = self.build_filter(
                                 ^^^^^^^^^^^^^^^^^^
  File "C:\Users\Rodrigo\Desktop\appointment_management\venv\Lib\site-packages\django\db\models\sql\query.py", line 1559, in build_filter
    condition = self.build_lookup(lookups, col, value)
                ^^^^^^^^^^^^^^^^^^^^^^^^^^^^^^^^^^^^^^
  File "C:\Users\Rodrigo\Desktop\appointment_management\venv\Lib\site-packages\django\db\models\sql\query.py", line 1389, in build_lookup
    lookup = lookup_class(lhs, rhs)
             ^^^^^^^^^^^^^^^^^^^^^^
  File "C:\Users\Rodrigo\Desktop\appointment_management\venv\Lib\site-packages\django\db\models\lookups.py", line 30, in __init__
    self.rhs = self.get_prep_lookup()
               ^^^^^^^^^^^^^^^^^^^^^^
  File "C:\Users\Rodrigo\Desktop\appointment_management\venv\Lib\site-packages\django\db\models\lookups.py", line 364, in get_prep_lookup
    return super().get_prep_lookup()
           ^^^^^^^^^^^^^^^^^^^^^^^^^
  File "C:\Users\Rodrigo\Desktop\appointment_management\venv\Lib\site-packages\django\db\models\lookups.py", line 88, in get_prep_lookup
    return self.lhs.output_field.get_prep_value(self.rhs)
           ^^^^^^^^^^^^^^^^^^^^^^^^^^^^^^^^^^^^^^^^^^^^^^
  File "C:\Users\Rodrigo\Desktop\appointment_management\venv\Lib\site-packages\django\db\models\fields\__init__.py", line 2119, in get_prep_value
    raise e.__class__(
ValueError: Field 'id' expected a number but got ''.
"POST /core/book-appointment/ HTTP/1.1" 500 143181
Internal Server Error: /core/book-appointment/
Traceback (most recent call last):
  File "C:\Users\Rodrigo\Desktop\appointment_management\venv\Lib\site-packages\django\db\models\fields\__init__.py", line 2117, in get_prep_value
    return int(value)
           ^^^^^^^^^^
ValueError: invalid literal for int() with base 10: ''

The above exception was the direct cause of the following exception:

Traceback (most recent call last):
  File "C:\Users\Rodrigo\Desktop\appointment_management\venv\Lib\site-packages\django\core\handlers\exception.py", line 55, in inner
    response = get_response(request)
               ^^^^^^^^^^^^^^^^^^^^^
  File "C:\Users\Rodrigo\Desktop\appointment_management\venv\Lib\site-packages\django\core\handlers\base.py", line 197, in _get_response
    response = wrapped_callback(request, *callback_args, **callback_kwargs)
               ^^^^^^^^^^^^^^^^^^^^^^^^^^^^^^^^^^^^^^^^^^^^^^^^^^^^^^^^^^^^
  File "C:\Users\Rodrigo\Desktop\appointment_management\venv\Lib\site-packages\django\contrib\auth\decorators.py", line 23, in _wrapper_view
    return view_func(request, *args, **kwargs)
           ^^^^^^^^^^^^^^^^^^^^^^^^^^^^^^^^^^^
  File "C:\Users\Rodrigo\Desktop\appointment_management\core\views.py", line 202, in book_appointment
    doctor = get_object_or_404(Doctor, id=doctor_id)
             ^^^^^^^^^^^^^^^^^^^^^^^^^^^^^^^^^^^^^^^
  File "C:\Users\Rodrigo\Desktop\appointment_management\venv\Lib\site-packages\django\shortcuts.py", line 86, in get_object_or_404
    return queryset.get(*args, **kwargs)
           ^^^^^^^^^^^^^^^^^^^^^^^^^^^^^
  File "C:\Users\Rodrigo\Desktop\appointment_management\venv\Lib\site-packages\django\db\models\query.py", line 635, in get
    clone = self._chain() if self.query.combinator else self.filter(*args, **kwargs)
                                                        ^^^^^^^^^^^^^^^^^^^^^^^^^^^^
  File "C:\Users\Rodrigo\Desktop\appointment_management\venv\Lib\site-packages\django\db\models\query.py", line 1476, in filter
    return self._filter_or_exclude(False, args, kwargs)
           ^^^^^^^^^^^^^^^^^^^^^^^^^^^^^^^^^^^^^^^^^^^^
  File "C:\Users\Rodrigo\Desktop\appointment_management\venv\Lib\site-packages\django\db\models\query.py", line 1494, in _filter_or_exclude
    clone._filter_or_exclude_inplace(negate, args, kwargs)
  File "C:\Users\Rodrigo\Desktop\appointment_management\venv\Lib\site-packages\django\db\models\query.py", line 1501, in _filter_or_exclude_inplace
    self._query.add_q(Q(*args, **kwargs))
  File "C:\Users\Rodrigo\Desktop\appointment_management\venv\Lib\site-packages\django\db\models\sql\query.py", line 1613, in add_q
    clause, _ = self._add_q(q_object, self.used_aliases)
                ^^^^^^^^^^^^^^^^^^^^^^^^^^^^^^^^^^^^^^^^
  File "C:\Users\Rodrigo\Desktop\appointment_management\venv\Lib\site-packages\django\db\models\sql\query.py", line 1645, in _add_q
    child_clause, needed_inner = self.build_filter(
                                 ^^^^^^^^^^^^^^^^^^
  File "C:\Users\Rodrigo\Desktop\appointment_management\venv\Lib\site-packages\django\db\models\sql\query.py", line 1559, in build_filter
    condition = self.build_lookup(lookups, col, value)
                ^^^^^^^^^^^^^^^^^^^^^^^^^^^^^^^^^^^^^^
  File "C:\Users\Rodrigo\Desktop\appointment_management\venv\Lib\site-packages\django\db\models\sql\query.py", line 1389, in build_lookup
    lookup = lookup_class(lhs, rhs)
             ^^^^^^^^^^^^^^^^^^^^^^
  File "C:\Users\Rodrigo\Desktop\appointment_management\venv\Lib\site-packages\django\db\models\lookups.py", line 30, in __init__
    self.rhs = self.get_prep_lookup()
               ^^^^^^^^^^^^^^^^^^^^^^
  File "C:\Users\Rodrigo\Desktop\appointment_management\venv\Lib\site-packages\django\db\models\lookups.py", line 364, in get_prep_lookup
    return super().get_prep_lookup()
           ^^^^^^^^^^^^^^^^^^^^^^^^^
  File "C:\Users\Rodrigo\Desktop\appointment_management\venv\Lib\site-packages\django\db\models\lookups.py", line 88, in get_prep_lookup
    return self.lhs.output_field.get_prep_value(self.rhs)
           ^^^^^^^^^^^^^^^^^^^^^^^^^^^^^^^^^^^^^^^^^^^^^^
  File "C:\Users\Rodrigo\Desktop\appointment_management\venv\Lib\site-packages\django\db\models\fields\__init__.py", line 2119, in get_prep_value
    raise e.__class__(
ValueError: Field 'id' expected a number but got ''.
"POST /core/book-appointment/ HTTP/1.1" 500 143181
Not Found: /favicon.ico
"GET /favicon.ico HTTP/1.1" 404 2440
Internal Server Error: /core/patient/schedule_appointment/
Traceback (most recent call last):
  File "C:\Users\Rodrigo\Desktop\appointment_management\venv\Lib\site-packages\django\core\handlers\exception.py", line 55, in inner
    response = get_response(request)
               ^^^^^^^^^^^^^^^^^^^^^
  File "C:\Users\Rodrigo\Desktop\appointment_management\venv\Lib\site-packages\django\core\handlers\base.py", line 197, in _get_response
    response = wrapped_callback(request, *callback_args, **callback_kwargs)
               ^^^^^^^^^^^^^^^^^^^^^^^^^^^^^^^^^^^^^^^^^^^^^^^^^^^^^^^^^^^^
  File "C:\Users\Rodrigo\Desktop\appointment_management\venv\Lib\site-packages\django\contrib\auth\decorators.py", line 23, in _wrapper_view
    return view_func(request, *args, **kwargs)
           ^^^^^^^^^^^^^^^^^^^^^^^^^^^^^^^^^^^
  File "C:\Users\Rodrigo\Desktop\appointment_management\venv\Lib\site-packages\django\contrib\auth\decorators.py", line 23, in _wrapper_view
    return view_func(request, *args, **kwargs)
           ^^^^^^^^^^^^^^^^^^^^^^^^^^^^^^^^^^^
  File "C:\Users\Rodrigo\Desktop\appointment_management\core\views.py", line 53, in schedule_appointment_patient
    return render(request, 'patient/schedule_appointment.html', {
           ^^^^^^^^^^^^^^^^^^^^^^^^^^^^^^^^^^^^^^^^^^^^^^^^^^^^^^
  File "C:\Users\Rodrigo\Desktop\appointment_management\venv\Lib\site-packages\django\shortcuts.py", line 25, in render
    content = loader.render_to_string(template_name, context, request, using=using)
              ^^^^^^^^^^^^^^^^^^^^^^^^^^^^^^^^^^^^^^^^^^^^^^^^^^^^^^^^^^^^^^^^^^^^^
  File "C:\Users\Rodrigo\Desktop\appointment_management\venv\Lib\site-packages\django\template\loader.py", line 61, in render_to_string
    template = get_template(template_name, using=using)
               ^^^^^^^^^^^^^^^^^^^^^^^^^^^^^^^^^^^^^^^^
  File "C:\Users\Rodrigo\Desktop\appointment_management\venv\Lib\site-packages\django\template\loader.py", line 15, in get_template
    return engine.get_template(template_name)
           ^^^^^^^^^^^^^^^^^^^^^^^^^^^^^^^^^^
  File "C:\Users\Rodrigo\Desktop\appointment_management\venv\Lib\site-packages\django\template\backends\django.py", line 33, in get_template
    return Template(self.engine.get_template(template_name), self)
                    ^^^^^^^^^^^^^^^^^^^^^^^^^^^^^^^^^^^^^^^
  File "C:\Users\Rodrigo\Desktop\appointment_management\venv\Lib\site-packages\django\template\engine.py", line 177, in get_template
    template, origin = self.find_template(template_name)
                       ^^^^^^^^^^^^^^^^^^^^^^^^^^^^^^^^^
  File "C:\Users\Rodrigo\Desktop\appointment_management\venv\Lib\site-packages\django\template\engine.py", line 159, in find_template
    template = loader.get_template(name, skip=skip)
               ^^^^^^^^^^^^^^^^^^^^^^^^^^^^^^^^^^^^
  File "C:\Users\Rodrigo\Desktop\appointment_management\venv\Lib\site-packages\django\template\loaders\cached.py", line 57, in get_template
    template = super().get_template(template_name, skip)
               ^^^^^^^^^^^^^^^^^^^^^^^^^^^^^^^^^^^^^^^^^
  File "C:\Users\Rodrigo\Desktop\appointment_management\venv\Lib\site-packages\django\template\loaders\base.py", line 28, in get_template
    return Template(
           ^^^^^^^^^
  File "C:\Users\Rodrigo\Desktop\appointment_management\venv\Lib\site-packages\django\template\base.py", line 154, in __init__
    self.nodelist = self.compile_nodelist()
                    ^^^^^^^^^^^^^^^^^^^^^^^
  File "C:\Users\Rodrigo\Desktop\appointment_management\venv\Lib\site-packages\django\template\base.py", line 196, in compile_nodelist
    return parser.parse()
           ^^^^^^^^^^^^^^
  File "C:\Users\Rodrigo\Desktop\appointment_management\venv\Lib\site-packages\django\template\base.py", line 510, in parse
    raise self.error(token, e)
  File "C:\Users\Rodrigo\Desktop\appointment_management\venv\Lib\site-packages\django\template\base.py", line 508, in parse
    compiled_result = compile_func(self, token)
                      ^^^^^^^^^^^^^^^^^^^^^^^^^
  File "C:\Users\Rodrigo\Desktop\appointment_management\venv\Lib\site-packages\django\template\loader_tags.py", line 295, in do_extends
    nodelist = parser.parse()
               ^^^^^^^^^^^^^^
  File "C:\Users\Rodrigo\Desktop\appointment_management\venv\Lib\site-packages\django\template\base.py", line 510, in parse
    raise self.error(token, e)
  File "C:\Users\Rodrigo\Desktop\appointment_management\venv\Lib\site-packages\django\template\base.py", line 508, in parse
    compiled_result = compile_func(self, token)
                      ^^^^^^^^^^^^^^^^^^^^^^^^^
  File "C:\Users\Rodrigo\Desktop\appointment_management\venv\Lib\site-packages\django\template\loader_tags.py", line 234, in do_block
    nodelist = parser.parse(("endblock",))
               ^^^^^^^^^^^^^^^^^^^^^^^^^^^
  File "C:\Users\Rodrigo\Desktop\appointment_management\venv\Lib\site-packages\django\template\base.py", line 481, in parse
    raise self.error(token, e)
  File "C:\Users\Rodrigo\Desktop\appointment_management\venv\Lib\site-packages\django\template\base.py", line 479, in parse
    filter_expression = self.compile_filter(token.contents)
                        ^^^^^^^^^^^^^^^^^^^^^^^^^^^^^^^^^^^
  File "C:\Users\Rodrigo\Desktop\appointment_management\venv\Lib\site-packages\django\template\base.py", line 597, in compile_filter
    return FilterExpression(token, self)
           ^^^^^^^^^^^^^^^^^^^^^^^^^^^^^
  File "C:\Users\Rodrigo\Desktop\appointment_management\venv\Lib\site-packages\django\template\base.py", line 698, in __init__
    raise TemplateSyntaxError(
django.template.exceptions.TemplateSyntaxError: Could not parse the remainder: '(class="form-label")' from 'form.speciality.label_tag(class="form-label")'
"GET /core/patient/schedule_appointment/ HTTP/1.1" 500 216062
Not Found: /core/book-appointment/
"POST /core/book-appointment/ HTTP/1.1" 404 5648
Not Found: /core/book-appointment/
"POST /core/book-appointment/ HTTP/1.1" 404 5648
Not Found: /core/book-appointment/
"POST /core/book-appointment/ HTTP/1.1" 404 5648
Not Found: /core/book-appointment/
"POST /core/book-appointment/ HTTP/1.1" 404 5648
Not Found: /favicon.ico
"GET /favicon.ico HTTP/1.1" 404 2440
Internal Server Error: /core/book-appointment/
Traceback (most recent call last):
  File "C:\Users\Rodrigo\Desktop\appointment_management\venv\Lib\site-packages\django\db\models\fields\__init__.py", line 2117, in get_prep_value
    return int(value)
           ^^^^^^^^^^
ValueError: invalid literal for int() with base 10: ''

The above exception was the direct cause of the following exception:

Traceback (most recent call last):
  File "C:\Users\Rodrigo\Desktop\appointment_management\venv\Lib\site-packages\django\core\handlers\exception.py", line 55, in inner
    response = get_response(request)
               ^^^^^^^^^^^^^^^^^^^^^
  File "C:\Users\Rodrigo\Desktop\appointment_management\venv\Lib\site-packages\django\core\handlers\base.py", line 197, in _get_response
    response = wrapped_callback(request, *callback_args, **callback_kwargs)
               ^^^^^^^^^^^^^^^^^^^^^^^^^^^^^^^^^^^^^^^^^^^^^^^^^^^^^^^^^^^^
  File "C:\Users\Rodrigo\Desktop\appointment_management\venv\Lib\site-packages\django\contrib\auth\decorators.py", line 23, in _wrapper_view
    return view_func(request, *args, **kwargs)
           ^^^^^^^^^^^^^^^^^^^^^^^^^^^^^^^^^^^
  File "C:\Users\Rodrigo\Desktop\appointment_management\core\views.py", line 202, in book_appointment
    doctor = get_object_or_404(Doctor, id=doctor_id)
             ^^^^^^^^^^^^^^^^^^^^^^^^^^^^^^^^^^^^^^^
  File "C:\Users\Rodrigo\Desktop\appointment_management\venv\Lib\site-packages\django\shortcuts.py", line 86, in get_object_or_404
    return queryset.get(*args, **kwargs)
           ^^^^^^^^^^^^^^^^^^^^^^^^^^^^^
  File "C:\Users\Rodrigo\Desktop\appointment_management\venv\Lib\site-packages\django\db\models\query.py", line 635, in get
    clone = self._chain() if self.query.combinator else self.filter(*args, **kwargs)
                                                        ^^^^^^^^^^^^^^^^^^^^^^^^^^^^
  File "C:\Users\Rodrigo\Desktop\appointment_management\venv\Lib\site-packages\django\db\models\query.py", line 1476, in filter
    return self._filter_or_exclude(False, args, kwargs)
           ^^^^^^^^^^^^^^^^^^^^^^^^^^^^^^^^^^^^^^^^^^^^
  File "C:\Users\Rodrigo\Desktop\appointment_management\venv\Lib\site-packages\django\db\models\query.py", line 1494, in _filter_or_exclude
    clone._filter_or_exclude_inplace(negate, args, kwargs)
  File "C:\Users\Rodrigo\Desktop\appointment_management\venv\Lib\site-packages\django\db\models\query.py", line 1501, in _filter_or_exclude_inplace
    self._query.add_q(Q(*args, **kwargs))
  File "C:\Users\Rodrigo\Desktop\appointment_management\venv\Lib\site-packages\django\db\models\sql\query.py", line 1613, in add_q
    clause, _ = self._add_q(q_object, self.used_aliases)
                ^^^^^^^^^^^^^^^^^^^^^^^^^^^^^^^^^^^^^^^^
  File "C:\Users\Rodrigo\Desktop\appointment_management\venv\Lib\site-packages\django\db\models\sql\query.py", line 1645, in _add_q
    child_clause, needed_inner = self.build_filter(
                                 ^^^^^^^^^^^^^^^^^^
  File "C:\Users\Rodrigo\Desktop\appointment_management\venv\Lib\site-packages\django\db\models\sql\query.py", line 1559, in build_filter
    condition = self.build_lookup(lookups, col, value)
                ^^^^^^^^^^^^^^^^^^^^^^^^^^^^^^^^^^^^^^
  File "C:\Users\Rodrigo\Desktop\appointment_management\venv\Lib\site-packages\django\db\models\sql\query.py", line 1389, in build_lookup
    lookup = lookup_class(lhs, rhs)
             ^^^^^^^^^^^^^^^^^^^^^^
  File "C:\Users\Rodrigo\Desktop\appointment_management\venv\Lib\site-packages\django\db\models\lookups.py", line 30, in __init__
    self.rhs = self.get_prep_lookup()
               ^^^^^^^^^^^^^^^^^^^^^^
  File "C:\Users\Rodrigo\Desktop\appointment_management\venv\Lib\site-packages\django\db\models\lookups.py", line 364, in get_prep_lookup
    return super().get_prep_lookup()
           ^^^^^^^^^^^^^^^^^^^^^^^^^
  File "C:\Users\Rodrigo\Desktop\appointment_management\venv\Lib\site-packages\django\db\models\lookups.py", line 88, in get_prep_lookup
    return self.lhs.output_field.get_prep_value(self.rhs)
           ^^^^^^^^^^^^^^^^^^^^^^^^^^^^^^^^^^^^^^^^^^^^^^
  File "C:\Users\Rodrigo\Desktop\appointment_management\venv\Lib\site-packages\django\db\models\fields\__init__.py", line 2119, in get_prep_value
    raise e.__class__(
ValueError: Field 'id' expected a number but got ''.
"POST /core/book-appointment/ HTTP/1.1" 500 143423
Internal Server Error: /core/book-appointment/
Traceback (most recent call last):
  File "C:\Users\Rodrigo\Desktop\appointment_management\venv\Lib\site-packages\django\db\models\fields\__init__.py", line 2117, in get_prep_value
    return int(value)
           ^^^^^^^^^^
ValueError: invalid literal for int() with base 10: ''

The above exception was the direct cause of the following exception:

Traceback (most recent call last):
  File "C:\Users\Rodrigo\Desktop\appointment_management\venv\Lib\site-packages\django\core\handlers\exception.py", line 55, in inner
    response = get_response(request)
               ^^^^^^^^^^^^^^^^^^^^^
  File "C:\Users\Rodrigo\Desktop\appointment_management\venv\Lib\site-packages\django\core\handlers\base.py", line 197, in _get_response
    response = wrapped_callback(request, *callback_args, **callback_kwargs)
               ^^^^^^^^^^^^^^^^^^^^^^^^^^^^^^^^^^^^^^^^^^^^^^^^^^^^^^^^^^^^
  File "C:\Users\Rodrigo\Desktop\appointment_management\venv\Lib\site-packages\django\contrib\auth\decorators.py", line 23, in _wrapper_view
    return view_func(request, *args, **kwargs)
           ^^^^^^^^^^^^^^^^^^^^^^^^^^^^^^^^^^^
  File "C:\Users\Rodrigo\Desktop\appointment_management\core\views.py", line 202, in book_appointment
    doctor = get_object_or_404(Doctor, id=doctor_id)
             ^^^^^^^^^^^^^^^^^^^^^^^^^^^^^^^^^^^^^^^
  File "C:\Users\Rodrigo\Desktop\appointment_management\venv\Lib\site-packages\django\shortcuts.py", line 86, in get_object_or_404
    return queryset.get(*args, **kwargs)
           ^^^^^^^^^^^^^^^^^^^^^^^^^^^^^
  File "C:\Users\Rodrigo\Desktop\appointment_management\venv\Lib\site-packages\django\db\models\query.py", line 635, in get
    clone = self._chain() if self.query.combinator else self.filter(*args, **kwargs)
                                                        ^^^^^^^^^^^^^^^^^^^^^^^^^^^^
  File "C:\Users\Rodrigo\Desktop\appointment_management\venv\Lib\site-packages\django\db\models\query.py", line 1476, in filter
    return self._filter_or_exclude(False, args, kwargs)
           ^^^^^^^^^^^^^^^^^^^^^^^^^^^^^^^^^^^^^^^^^^^^
  File "C:\Users\Rodrigo\Desktop\appointment_management\venv\Lib\site-packages\django\db\models\query.py", line 1494, in _filter_or_exclude
    clone._filter_or_exclude_inplace(negate, args, kwargs)
  File "C:\Users\Rodrigo\Desktop\appointment_management\venv\Lib\site-packages\django\db\models\query.py", line 1501, in _filter_or_exclude_inplace
    self._query.add_q(Q(*args, **kwargs))
  File "C:\Users\Rodrigo\Desktop\appointment_management\venv\Lib\site-packages\django\db\models\sql\query.py", line 1613, in add_q
    clause, _ = self._add_q(q_object, self.used_aliases)
                ^^^^^^^^^^^^^^^^^^^^^^^^^^^^^^^^^^^^^^^^
  File "C:\Users\Rodrigo\Desktop\appointment_management\venv\Lib\site-packages\django\db\models\sql\query.py", line 1645, in _add_q
    child_clause, needed_inner = self.build_filter(
                                 ^^^^^^^^^^^^^^^^^^
  File "C:\Users\Rodrigo\Desktop\appointment_management\venv\Lib\site-packages\django\db\models\sql\query.py", line 1559, in build_filter
    condition = self.build_lookup(lookups, col, value)
                ^^^^^^^^^^^^^^^^^^^^^^^^^^^^^^^^^^^^^^
  File "C:\Users\Rodrigo\Desktop\appointment_management\venv\Lib\site-packages\django\db\models\sql\query.py", line 1389, in build_lookup
    lookup = lookup_class(lhs, rhs)
             ^^^^^^^^^^^^^^^^^^^^^^
  File "C:\Users\Rodrigo\Desktop\appointment_management\venv\Lib\site-packages\django\db\models\lookups.py", line 30, in __init__
    self.rhs = self.get_prep_lookup()
               ^^^^^^^^^^^^^^^^^^^^^^
  File "C:\Users\Rodrigo\Desktop\appointment_management\venv\Lib\site-packages\django\db\models\lookups.py", line 364, in get_prep_lookup
    return super().get_prep_lookup()
           ^^^^^^^^^^^^^^^^^^^^^^^^^
  File "C:\Users\Rodrigo\Desktop\appointment_management\venv\Lib\site-packages\django\db\models\lookups.py", line 88, in get_prep_lookup
    return self.lhs.output_field.get_prep_value(self.rhs)
           ^^^^^^^^^^^^^^^^^^^^^^^^^^^^^^^^^^^^^^^^^^^^^^
  File "C:\Users\Rodrigo\Desktop\appointment_management\venv\Lib\site-packages\django\db\models\fields\__init__.py", line 2119, in get_prep_value
    raise e.__class__(
ValueError: Field 'id' expected a number but got ''.
"POST /core/book-appointment/ HTTP/1.1" 500 143423
Internal Server Error: /core/book-appointment/
Traceback (most recent call last):
  File "C:\Users\Rodrigo\Desktop\appointment_management\venv\Lib\site-packages\django\db\models\fields\__init__.py", line 2117, in get_prep_value
    return int(value)
           ^^^^^^^^^^
ValueError: invalid literal for int() with base 10: ''

The above exception was the direct cause of the following exception:

Traceback (most recent call last):
  File "C:\Users\Rodrigo\Desktop\appointment_management\venv\Lib\site-packages\django\core\handlers\exception.py", line 55, in inner
    response = get_response(request)
               ^^^^^^^^^^^^^^^^^^^^^
  File "C:\Users\Rodrigo\Desktop\appointment_management\venv\Lib\site-packages\django\core\handlers\base.py", line 197, in _get_response
    response = wrapped_callback(request, *callback_args, **callback_kwargs)
               ^^^^^^^^^^^^^^^^^^^^^^^^^^^^^^^^^^^^^^^^^^^^^^^^^^^^^^^^^^^^
  File "C:\Users\Rodrigo\Desktop\appointment_management\venv\Lib\site-packages\django\contrib\auth\decorators.py", line 23, in _wrapper_view
    return view_func(request, *args, **kwargs)
           ^^^^^^^^^^^^^^^^^^^^^^^^^^^^^^^^^^^
  File "C:\Users\Rodrigo\Desktop\appointment_management\core\views.py", line 202, in book_appointment
    doctor = get_object_or_404(Doctor, id=doctor_id)
             ^^^^^^^^^^^^^^^^^^^^^^^^^^^^^^^^^^^^^^^
  File "C:\Users\Rodrigo\Desktop\appointment_management\venv\Lib\site-packages\django\shortcuts.py", line 86, in get_object_or_404
    return queryset.get(*args, **kwargs)
           ^^^^^^^^^^^^^^^^^^^^^^^^^^^^^
  File "C:\Users\Rodrigo\Desktop\appointment_management\venv\Lib\site-packages\django\db\models\query.py", line 635, in get
    clone = self._chain() if self.query.combinator else self.filter(*args, **kwargs)
                                                        ^^^^^^^^^^^^^^^^^^^^^^^^^^^^
  File "C:\Users\Rodrigo\Desktop\appointment_management\venv\Lib\site-packages\django\db\models\query.py", line 1476, in filter
    return self._filter_or_exclude(False, args, kwargs)
           ^^^^^^^^^^^^^^^^^^^^^^^^^^^^^^^^^^^^^^^^^^^^
  File "C:\Users\Rodrigo\Desktop\appointment_management\venv\Lib\site-packages\django\db\models\query.py", line 1494, in _filter_or_exclude
    clone._filter_or_exclude_inplace(negate, args, kwargs)
  File "C:\Users\Rodrigo\Desktop\appointment_management\venv\Lib\site-packages\django\db\models\query.py", line 1501, in _filter_or_exclude_inplace
    self._query.add_q(Q(*args, **kwargs))
  File "C:\Users\Rodrigo\Desktop\appointment_management\venv\Lib\site-packages\django\db\models\sql\query.py", line 1613, in add_q
    clause, _ = self._add_q(q_object, self.used_aliases)
                ^^^^^^^^^^^^^^^^^^^^^^^^^^^^^^^^^^^^^^^^
  File "C:\Users\Rodrigo\Desktop\appointment_management\venv\Lib\site-packages\django\db\models\sql\query.py", line 1645, in _add_q
    child_clause, needed_inner = self.build_filter(
                                 ^^^^^^^^^^^^^^^^^^
  File "C:\Users\Rodrigo\Desktop\appointment_management\venv\Lib\site-packages\django\db\models\sql\query.py", line 1559, in build_filter
    condition = self.build_lookup(lookups, col, value)
                ^^^^^^^^^^^^^^^^^^^^^^^^^^^^^^^^^^^^^^
  File "C:\Users\Rodrigo\Desktop\appointment_management\venv\Lib\site-packages\django\db\models\sql\query.py", line 1389, in build_lookup
    lookup = lookup_class(lhs, rhs)
             ^^^^^^^^^^^^^^^^^^^^^^
  File "C:\Users\Rodrigo\Desktop\appointment_management\venv\Lib\site-packages\django\db\models\lookups.py", line 30, in __init__
    self.rhs = self.get_prep_lookup()
               ^^^^^^^^^^^^^^^^^^^^^^
  File "C:\Users\Rodrigo\Desktop\appointment_management\venv\Lib\site-packages\django\db\models\lookups.py", line 364, in get_prep_lookup
    return super().get_prep_lookup()
           ^^^^^^^^^^^^^^^^^^^^^^^^^
  File "C:\Users\Rodrigo\Desktop\appointment_management\venv\Lib\site-packages\django\db\models\lookups.py", line 88, in get_prep_lookup
    return self.lhs.output_field.get_prep_value(self.rhs)
           ^^^^^^^^^^^^^^^^^^^^^^^^^^^^^^^^^^^^^^^^^^^^^^
  File "C:\Users\Rodrigo\Desktop\appointment_management\venv\Lib\site-packages\django\db\models\fields\__init__.py", line 2119, in get_prep_value
    raise e.__class__(
ValueError: Field 'id' expected a number but got ''.
"POST /core/book-appointment/ HTTP/1.1" 500 143328
Internal Server Error: /core/book-appointment/
Traceback (most recent call last):
  File "C:\Users\Rodrigo\Desktop\appointment_management\venv\Lib\site-packages\django\db\models\fields\__init__.py", line 2117, in get_prep_value
    return int(value)
           ^^^^^^^^^^
ValueError: invalid literal for int() with base 10: ''

The above exception was the direct cause of the following exception:

Traceback (most recent call last):
  File "C:\Users\Rodrigo\Desktop\appointment_management\venv\Lib\site-packages\django\core\handlers\exception.py", line 55, in inner
    response = get_response(request)
               ^^^^^^^^^^^^^^^^^^^^^
  File "C:\Users\Rodrigo\Desktop\appointment_management\venv\Lib\site-packages\django\core\handlers\base.py", line 197, in _get_response
    response = wrapped_callback(request, *callback_args, **callback_kwargs)
               ^^^^^^^^^^^^^^^^^^^^^^^^^^^^^^^^^^^^^^^^^^^^^^^^^^^^^^^^^^^^
  File "C:\Users\Rodrigo\Desktop\appointment_management\venv\Lib\site-packages\django\contrib\auth\decorators.py", line 23, in _wrapper_view
    return view_func(request, *args, **kwargs)
           ^^^^^^^^^^^^^^^^^^^^^^^^^^^^^^^^^^^
  File "C:\Users\Rodrigo\Desktop\appointment_management\core\views.py", line 202, in book_appointment
    doctor = get_object_or_404(Doctor, id=doctor_id)
             ^^^^^^^^^^^^^^^^^^^^^^^^^^^^^^^^^^^^^^^
  File "C:\Users\Rodrigo\Desktop\appointment_management\venv\Lib\site-packages\django\shortcuts.py", line 86, in get_object_or_404
    return queryset.get(*args, **kwargs)
           ^^^^^^^^^^^^^^^^^^^^^^^^^^^^^
  File "C:\Users\Rodrigo\Desktop\appointment_management\venv\Lib\site-packages\django\db\models\query.py", line 635, in get
    clone = self._chain() if self.query.combinator else self.filter(*args, **kwargs)
                                                        ^^^^^^^^^^^^^^^^^^^^^^^^^^^^
  File "C:\Users\Rodrigo\Desktop\appointment_management\venv\Lib\site-packages\django\db\models\query.py", line 1476, in filter
    return self._filter_or_exclude(False, args, kwargs)
           ^^^^^^^^^^^^^^^^^^^^^^^^^^^^^^^^^^^^^^^^^^^^
  File "C:\Users\Rodrigo\Desktop\appointment_management\venv\Lib\site-packages\django\db\models\query.py", line 1494, in _filter_or_exclude
    clone._filter_or_exclude_inplace(negate, args, kwargs)
  File "C:\Users\Rodrigo\Desktop\appointment_management\venv\Lib\site-packages\django\db\models\query.py", line 1501, in _filter_or_exclude_inplace
    self._query.add_q(Q(*args, **kwargs))
  File "C:\Users\Rodrigo\Desktop\appointment_management\venv\Lib\site-packages\django\db\models\sql\query.py", line 1613, in add_q
    clause, _ = self._add_q(q_object, self.used_aliases)
                ^^^^^^^^^^^^^^^^^^^^^^^^^^^^^^^^^^^^^^^^
  File "C:\Users\Rodrigo\Desktop\appointment_management\venv\Lib\site-packages\django\db\models\sql\query.py", line 1645, in _add_q
    child_clause, needed_inner = self.build_filter(
                                 ^^^^^^^^^^^^^^^^^^
  File "C:\Users\Rodrigo\Desktop\appointment_management\venv\Lib\site-packages\django\db\models\sql\query.py", line 1559, in build_filter
    condition = self.build_lookup(lookups, col, value)
                ^^^^^^^^^^^^^^^^^^^^^^^^^^^^^^^^^^^^^^
  File "C:\Users\Rodrigo\Desktop\appointment_management\venv\Lib\site-packages\django\db\models\sql\query.py", line 1389, in build_lookup
    lookup = lookup_class(lhs, rhs)
             ^^^^^^^^^^^^^^^^^^^^^^
  File "C:\Users\Rodrigo\Desktop\appointment_management\venv\Lib\site-packages\django\db\models\lookups.py", line 30, in __init__
    self.rhs = self.get_prep_lookup()
               ^^^^^^^^^^^^^^^^^^^^^^
  File "C:\Users\Rodrigo\Desktop\appointment_management\venv\Lib\site-packages\django\db\models\lookups.py", line 364, in get_prep_lookup
    return super().get_prep_lookup()
           ^^^^^^^^^^^^^^^^^^^^^^^^^
  File "C:\Users\Rodrigo\Desktop\appointment_management\venv\Lib\site-packages\django\db\models\lookups.py", line 88, in get_prep_lookup
    return self.lhs.output_field.get_prep_value(self.rhs)
           ^^^^^^^^^^^^^^^^^^^^^^^^^^^^^^^^^^^^^^^^^^^^^^
  File "C:\Users\Rodrigo\Desktop\appointment_management\venv\Lib\site-packages\django\db\models\fields\__init__.py", line 2119, in get_prep_value
    raise e.__class__(
ValueError: Field 'id' expected a number but got ''.
"POST /core/book-appointment/ HTTP/1.1" 500 143354
Internal Server Error: /core/book-appointment/
Traceback (most recent call last):
  File "C:\Users\Rodrigo\Desktop\appointment_management\venv\Lib\site-packages\django\db\models\fields\__init__.py", line 2117, in get_prep_value
    return int(value)
           ^^^^^^^^^^
ValueError: invalid literal for int() with base 10: ''

The above exception was the direct cause of the following exception:

Traceback (most recent call last):
  File "C:\Users\Rodrigo\Desktop\appointment_management\venv\Lib\site-packages\django\core\handlers\exception.py", line 55, in inner
    response = get_response(request)
               ^^^^^^^^^^^^^^^^^^^^^
  File "C:\Users\Rodrigo\Desktop\appointment_management\venv\Lib\site-packages\django\core\handlers\base.py", line 197, in _get_response
    response = wrapped_callback(request, *callback_args, **callback_kwargs)
               ^^^^^^^^^^^^^^^^^^^^^^^^^^^^^^^^^^^^^^^^^^^^^^^^^^^^^^^^^^^^
  File "C:\Users\Rodrigo\Desktop\appointment_management\venv\Lib\site-packages\django\contrib\auth\decorators.py", line 23, in _wrapper_view
    return view_func(request, *args, **kwargs)
           ^^^^^^^^^^^^^^^^^^^^^^^^^^^^^^^^^^^
  File "C:\Users\Rodrigo\Desktop\appointment_management\core\views.py", line 202, in book_appointment
    doctor = get_object_or_404(Doctor, id=doctor_id)
             ^^^^^^^^^^^^^^^^^^^^^^^^^^^^^^^^^^^^^^^
  File "C:\Users\Rodrigo\Desktop\appointment_management\venv\Lib\site-packages\django\shortcuts.py", line 86, in get_object_or_404
    return queryset.get(*args, **kwargs)
           ^^^^^^^^^^^^^^^^^^^^^^^^^^^^^
  File "C:\Users\Rodrigo\Desktop\appointment_management\venv\Lib\site-packages\django\db\models\query.py", line 635, in get
    clone = self._chain() if self.query.combinator else self.filter(*args, **kwargs)
                                                        ^^^^^^^^^^^^^^^^^^^^^^^^^^^^
  File "C:\Users\Rodrigo\Desktop\appointment_management\venv\Lib\site-packages\django\db\models\query.py", line 1476, in filter
    return self._filter_or_exclude(False, args, kwargs)
           ^^^^^^^^^^^^^^^^^^^^^^^^^^^^^^^^^^^^^^^^^^^^
  File "C:\Users\Rodrigo\Desktop\appointment_management\venv\Lib\site-packages\django\db\models\query.py", line 1494, in _filter_or_exclude
    clone._filter_or_exclude_inplace(negate, args, kwargs)
  File "C:\Users\Rodrigo\Desktop\appointment_management\venv\Lib\site-packages\django\db\models\query.py", line 1501, in _filter_or_exclude_inplace
    self._query.add_q(Q(*args, **kwargs))
  File "C:\Users\Rodrigo\Desktop\appointment_management\venv\Lib\site-packages\django\db\models\sql\query.py", line 1613, in add_q
    clause, _ = self._add_q(q_object, self.used_aliases)
                ^^^^^^^^^^^^^^^^^^^^^^^^^^^^^^^^^^^^^^^^
  File "C:\Users\Rodrigo\Desktop\appointment_management\venv\Lib\site-packages\django\db\models\sql\query.py", line 1645, in _add_q
    child_clause, needed_inner = self.build_filter(
                                 ^^^^^^^^^^^^^^^^^^
  File "C:\Users\Rodrigo\Desktop\appointment_management\venv\Lib\site-packages\django\db\models\sql\query.py", line 1559, in build_filter
    condition = self.build_lookup(lookups, col, value)
                ^^^^^^^^^^^^^^^^^^^^^^^^^^^^^^^^^^^^^^
  File "C:\Users\Rodrigo\Desktop\appointment_management\venv\Lib\site-packages\django\db\models\sql\query.py", line 1389, in build_lookup
    lookup = lookup_class(lhs, rhs)
             ^^^^^^^^^^^^^^^^^^^^^^
  File "C:\Users\Rodrigo\Desktop\appointment_management\venv\Lib\site-packages\django\db\models\lookups.py", line 30, in __init__
    self.rhs = self.get_prep_lookup()
               ^^^^^^^^^^^^^^^^^^^^^^
  File "C:\Users\Rodrigo\Desktop\appointment_management\venv\Lib\site-packages\django\db\models\lookups.py", line 364, in get_prep_lookup
    return super().get_prep_lookup()
           ^^^^^^^^^^^^^^^^^^^^^^^^^
  File "C:\Users\Rodrigo\Desktop\appointment_management\venv\Lib\site-packages\django\db\models\lookups.py", line 88, in get_prep_lookup
    return self.lhs.output_field.get_prep_value(self.rhs)
           ^^^^^^^^^^^^^^^^^^^^^^^^^^^^^^^^^^^^^^^^^^^^^^
  File "C:\Users\Rodrigo\Desktop\appointment_management\venv\Lib\site-packages\django\db\models\fields\__init__.py", line 2119, in get_prep_value
    raise e.__class__(
ValueError: Field 'id' expected a number but got ''.
"POST /core/book-appointment/ HTTP/1.1" 500 143354
Not Found: /favicon.ico
"GET /favicon.ico HTTP/1.1" 404 2440
Internal Server Error: /core/book-appointment/
Traceback (most recent call last):
  File "C:\Users\Rodrigo\Desktop\appointment_management\venv\Lib\site-packages\django\db\models\fields\__init__.py", line 2117, in get_prep_value
    return int(value)
           ^^^^^^^^^^
ValueError: invalid literal for int() with base 10: ''

The above exception was the direct cause of the following exception:

Traceback (most recent call last):
  File "C:\Users\Rodrigo\Desktop\appointment_management\venv\Lib\site-packages\django\core\handlers\exception.py", line 55, in inner
    response = get_response(request)
               ^^^^^^^^^^^^^^^^^^^^^
  File "C:\Users\Rodrigo\Desktop\appointment_management\venv\Lib\site-packages\django\core\handlers\base.py", line 197, in _get_response
    response = wrapped_callback(request, *callback_args, **callback_kwargs)
               ^^^^^^^^^^^^^^^^^^^^^^^^^^^^^^^^^^^^^^^^^^^^^^^^^^^^^^^^^^^^
  File "C:\Users\Rodrigo\Desktop\appointment_management\venv\Lib\site-packages\django\contrib\auth\decorators.py", line 23, in _wrapper_view
    return view_func(request, *args, **kwargs)
           ^^^^^^^^^^^^^^^^^^^^^^^^^^^^^^^^^^^
  File "C:\Users\Rodrigo\Desktop\appointment_management\core\views.py", line 202, in book_appointment
    doctor = get_object_or_404(Doctor, id=doctor_id)
             ^^^^^^^^^^^^^^^^^^^^^^^^^^^^^^^^^^^^^^^
  File "C:\Users\Rodrigo\Desktop\appointment_management\venv\Lib\site-packages\django\shortcuts.py", line 86, in get_object_or_404
    return queryset.get(*args, **kwargs)
           ^^^^^^^^^^^^^^^^^^^^^^^^^^^^^
  File "C:\Users\Rodrigo\Desktop\appointment_management\venv\Lib\site-packages\django\db\models\query.py", line 635, in get
    clone = self._chain() if self.query.combinator else self.filter(*args, **kwargs)
                                                        ^^^^^^^^^^^^^^^^^^^^^^^^^^^^
  File "C:\Users\Rodrigo\Desktop\appointment_management\venv\Lib\site-packages\django\db\models\query.py", line 1476, in filter
    return self._filter_or_exclude(False, args, kwargs)
           ^^^^^^^^^^^^^^^^^^^^^^^^^^^^^^^^^^^^^^^^^^^^
  File "C:\Users\Rodrigo\Desktop\appointment_management\venv\Lib\site-packages\django\db\models\query.py", line 1494, in _filter_or_exclude
    clone._filter_or_exclude_inplace(negate, args, kwargs)
  File "C:\Users\Rodrigo\Desktop\appointment_management\venv\Lib\site-packages\django\db\models\query.py", line 1501, in _filter_or_exclude_inplace
    self._query.add_q(Q(*args, **kwargs))
  File "C:\Users\Rodrigo\Desktop\appointment_management\venv\Lib\site-packages\django\db\models\sql\query.py", line 1613, in add_q
    clause, _ = self._add_q(q_object, self.used_aliases)
                ^^^^^^^^^^^^^^^^^^^^^^^^^^^^^^^^^^^^^^^^
  File "C:\Users\Rodrigo\Desktop\appointment_management\venv\Lib\site-packages\django\db\models\sql\query.py", line 1645, in _add_q
    child_clause, needed_inner = self.build_filter(
                                 ^^^^^^^^^^^^^^^^^^
  File "C:\Users\Rodrigo\Desktop\appointment_management\venv\Lib\site-packages\django\db\models\sql\query.py", line 1559, in build_filter
    condition = self.build_lookup(lookups, col, value)
                ^^^^^^^^^^^^^^^^^^^^^^^^^^^^^^^^^^^^^^
  File "C:\Users\Rodrigo\Desktop\appointment_management\venv\Lib\site-packages\django\db\models\sql\query.py", line 1389, in build_lookup
    lookup = lookup_class(lhs, rhs)
             ^^^^^^^^^^^^^^^^^^^^^^
  File "C:\Users\Rodrigo\Desktop\appointment_management\venv\Lib\site-packages\django\db\models\lookups.py", line 30, in __init__
    self.rhs = self.get_prep_lookup()
               ^^^^^^^^^^^^^^^^^^^^^^
  File "C:\Users\Rodrigo\Desktop\appointment_management\venv\Lib\site-packages\django\db\models\lookups.py", line 364, in get_prep_lookup
    return super().get_prep_lookup()
           ^^^^^^^^^^^^^^^^^^^^^^^^^
  File "C:\Users\Rodrigo\Desktop\appointment_management\venv\Lib\site-packages\django\db\models\lookups.py", line 88, in get_prep_lookup
    return self.lhs.output_field.get_prep_value(self.rhs)
           ^^^^^^^^^^^^^^^^^^^^^^^^^^^^^^^^^^^^^^^^^^^^^^
  File "C:\Users\Rodrigo\Desktop\appointment_management\venv\Lib\site-packages\django\db\models\fields\__init__.py", line 2119, in get_prep_value
    raise e.__class__(
ValueError: Field 'id' expected a number but got ''.
"POST /core/book-appointment/ HTTP/1.1" 500 143354
Not Found: /favicon.ico
"GET /favicon.ico HTTP/1.1" 404 2440
Internal Server Error: /core/book-appointment/
Traceback (most recent call last):
  File "C:\Users\Rodrigo\Desktop\appointment_management\venv\Lib\site-packages\django\db\models\fields\__init__.py", line 2117, in get_prep_value
    return int(value)
           ^^^^^^^^^^
ValueError: invalid literal for int() with base 10: ''

The above exception was the direct cause of the following exception:

Traceback (most recent call last):
  File "C:\Users\Rodrigo\Desktop\appointment_management\venv\Lib\site-packages\django\core\handlers\exception.py", line 55, in inner
    response = get_response(request)
               ^^^^^^^^^^^^^^^^^^^^^
  File "C:\Users\Rodrigo\Desktop\appointment_management\venv\Lib\site-packages\django\core\handlers\base.py", line 197, in _get_response
    response = wrapped_callback(request, *callback_args, **callback_kwargs)
               ^^^^^^^^^^^^^^^^^^^^^^^^^^^^^^^^^^^^^^^^^^^^^^^^^^^^^^^^^^^^
  File "C:\Users\Rodrigo\Desktop\appointment_management\venv\Lib\site-packages\django\contrib\auth\decorators.py", line 23, in _wrapper_view
    return view_func(request, *args, **kwargs)
           ^^^^^^^^^^^^^^^^^^^^^^^^^^^^^^^^^^^
  File "C:\Users\Rodrigo\Desktop\appointment_management\core\views.py", line 202, in book_appointment
    doctor = get_object_or_404(Doctor, id=doctor_id)
             ^^^^^^^^^^^^^^^^^^^^^^^^^^^^^^^^^^^^^^^
  File "C:\Users\Rodrigo\Desktop\appointment_management\venv\Lib\site-packages\django\shortcuts.py", line 86, in get_object_or_404
    return queryset.get(*args, **kwargs)
           ^^^^^^^^^^^^^^^^^^^^^^^^^^^^^
  File "C:\Users\Rodrigo\Desktop\appointment_management\venv\Lib\site-packages\django\db\models\query.py", line 635, in get
    clone = self._chain() if self.query.combinator else self.filter(*args, **kwargs)
                                                        ^^^^^^^^^^^^^^^^^^^^^^^^^^^^
  File "C:\Users\Rodrigo\Desktop\appointment_management\venv\Lib\site-packages\django\db\models\query.py", line 1476, in filter
    return self._filter_or_exclude(False, args, kwargs)
           ^^^^^^^^^^^^^^^^^^^^^^^^^^^^^^^^^^^^^^^^^^^^
  File "C:\Users\Rodrigo\Desktop\appointment_management\venv\Lib\site-packages\django\db\models\query.py", line 1494, in _filter_or_exclude
    clone._filter_or_exclude_inplace(negate, args, kwargs)
  File "C:\Users\Rodrigo\Desktop\appointment_management\venv\Lib\site-packages\django\db\models\query.py", line 1501, in _filter_or_exclude_inplace
    self._query.add_q(Q(*args, **kwargs))
  File "C:\Users\Rodrigo\Desktop\appointment_management\venv\Lib\site-packages\django\db\models\sql\query.py", line 1613, in add_q
    clause, _ = self._add_q(q_object, self.used_aliases)
                ^^^^^^^^^^^^^^^^^^^^^^^^^^^^^^^^^^^^^^^^
  File "C:\Users\Rodrigo\Desktop\appointment_management\venv\Lib\site-packages\django\db\models\sql\query.py", line 1645, in _add_q
    child_clause, needed_inner = self.build_filter(
                                 ^^^^^^^^^^^^^^^^^^
  File "C:\Users\Rodrigo\Desktop\appointment_management\venv\Lib\site-packages\django\db\models\sql\query.py", line 1559, in build_filter
    condition = self.build_lookup(lookups, col, value)
                ^^^^^^^^^^^^^^^^^^^^^^^^^^^^^^^^^^^^^^
  File "C:\Users\Rodrigo\Desktop\appointment_management\venv\Lib\site-packages\django\db\models\sql\query.py", line 1389, in build_lookup
    lookup = lookup_class(lhs, rhs)
             ^^^^^^^^^^^^^^^^^^^^^^
  File "C:\Users\Rodrigo\Desktop\appointment_management\venv\Lib\site-packages\django\db\models\lookups.py", line 30, in __init__
    self.rhs = self.get_prep_lookup()
               ^^^^^^^^^^^^^^^^^^^^^^
  File "C:\Users\Rodrigo\Desktop\appointment_management\venv\Lib\site-packages\django\db\models\lookups.py", line 364, in get_prep_lookup
    return super().get_prep_lookup()
           ^^^^^^^^^^^^^^^^^^^^^^^^^
  File "C:\Users\Rodrigo\Desktop\appointment_management\venv\Lib\site-packages\django\db\models\lookups.py", line 88, in get_prep_lookup
    return self.lhs.output_field.get_prep_value(self.rhs)
           ^^^^^^^^^^^^^^^^^^^^^^^^^^^^^^^^^^^^^^^^^^^^^^
  File "C:\Users\Rodrigo\Desktop\appointment_management\venv\Lib\site-packages\django\db\models\fields\__init__.py", line 2119, in get_prep_value
    raise e.__class__(
ValueError: Field 'id' expected a number but got ''.
"POST /core/book-appointment/ HTTP/1.1" 500 143354
Not Found: /favicon.ico
"GET /favicon.ico HTTP/1.1" 404 2440
Not Found: /favicon.ico
"GET /favicon.ico HTTP/1.1" 404 2440
Not Found: /favicon.ico
"GET /favicon.ico HTTP/1.1" 404 2440
Not Found: /favicon.ico
"GET /favicon.ico HTTP/1.1" 404 2440
Not Found: /favicon.ico
"GET /favicon.ico HTTP/1.1" 404 2440
Not Found: /favicon.ico
"GET /favicon.ico HTTP/1.1" 404 2440
Not Found: /favicon.ico
"GET /favicon.ico HTTP/1.1" 404 2440
Not Found: /favicon.ico
"GET /favicon.ico HTTP/1.1" 404 2440
Not Found: /favicon.ico
"GET /favicon.ico HTTP/1.1" 404 2440
Not Found: /favicon.ico
"GET /favicon.ico HTTP/1.1" 404 2440
Not Found: /favicon.ico
"GET /favicon.ico HTTP/1.1" 404 2440
Not Found: /favicon.ico
"GET /favicon.ico HTTP/1.1" 404 2440
Internal Server Error: /core/home/
Traceback (most recent call last):
  File "C:\Users\Rodrigo\Desktop\appointment_management\venv\Lib\site-packages\django\core\handlers\exception.py", line 55, in inner
    response = get_response(request)
               ^^^^^^^^^^^^^^^^^^^^^
  File "C:\Users\Rodrigo\Desktop\appointment_management\venv\Lib\site-packages\django\core\handlers\base.py", line 197, in _get_response
    response = wrapped_callback(request, *callback_args, **callback_kwargs)
               ^^^^^^^^^^^^^^^^^^^^^^^^^^^^^^^^^^^^^^^^^^^^^^^^^^^^^^^^^^^^
  File "C:\Users\Rodrigo\Desktop\appointment_management\venv\Lib\site-packages\django\contrib\auth\decorators.py", line 23, in _wrapper_view
    return view_func(request, *args, **kwargs)
           ^^^^^^^^^^^^^^^^^^^^^^^^^^^^^^^^^^^
  File "C:\Users\Rodrigo\Desktop\appointment_management\core\views.py", line 36, in home
    return render(request, 'home.html')
           ^^^^^^^^^^^^^^^^^^^^^^^^^^^^
  File "C:\Users\Rodrigo\Desktop\appointment_management\venv\Lib\site-packages\django\shortcuts.py", line 25, in render
    content = loader.render_to_string(template_name, context, request, using=using)
              ^^^^^^^^^^^^^^^^^^^^^^^^^^^^^^^^^^^^^^^^^^^^^^^^^^^^^^^^^^^^^^^^^^^^^
  File "C:\Users\Rodrigo\Desktop\appointment_management\venv\Lib\site-packages\django\template\loader.py", line 62, in render_to_string
    return template.render(context, request)
           ^^^^^^^^^^^^^^^^^^^^^^^^^^^^^^^^^
  File "C:\Users\Rodrigo\Desktop\appointment_management\venv\Lib\site-packages\django\template\backends\django.py", line 61, in render
    return self.template.render(context)
           ^^^^^^^^^^^^^^^^^^^^^^^^^^^^^
  File "C:\Users\Rodrigo\Desktop\appointment_management\venv\Lib\site-packages\django\template\base.py", line 171, in render
    return self._render(context)
           ^^^^^^^^^^^^^^^^^^^^^
  File "C:\Users\Rodrigo\Desktop\appointment_management\venv\Lib\site-packages\django\template\base.py", line 163, in _render
    return self.nodelist.render(context)
           ^^^^^^^^^^^^^^^^^^^^^^^^^^^^^
  File "C:\Users\Rodrigo\Desktop\appointment_management\venv\Lib\site-packages\django\template\base.py", line 1000, in render
    return SafeString("".join([node.render_annotated(context) for node in self]))
                              ^^^^^^^^^^^^^^^^^^^^^^^^^^^^^^^^^^^^^^^^^^^^^^^^^
  File "C:\Users\Rodrigo\Desktop\appointment_management\venv\Lib\site-packages\django\template\base.py", line 1000, in <listcomp>
    return SafeString("".join([node.render_annotated(context) for node in self]))
                               ^^^^^^^^^^^^^^^^^^^^^^^^^^^^^^
  File "C:\Users\Rodrigo\Desktop\appointment_management\venv\Lib\site-packages\django\template\base.py", line 961, in render_annotated
    return self.render(context)
           ^^^^^^^^^^^^^^^^^^^^
  File "C:\Users\Rodrigo\Desktop\appointment_management\venv\Lib\site-packages\django\template\loader_tags.py", line 159, in render
    return compiled_parent._render(context)
           ^^^^^^^^^^^^^^^^^^^^^^^^^^^^^^^^
  File "C:\Users\Rodrigo\Desktop\appointment_management\venv\Lib\site-packages\django\template\base.py", line 163, in _render
    return self.nodelist.render(context)
           ^^^^^^^^^^^^^^^^^^^^^^^^^^^^^
  File "C:\Users\Rodrigo\Desktop\appointment_management\venv\Lib\site-packages\django\template\base.py", line 1000, in render
    return SafeString("".join([node.render_annotated(context) for node in self]))
                              ^^^^^^^^^^^^^^^^^^^^^^^^^^^^^^^^^^^^^^^^^^^^^^^^^
  File "C:\Users\Rodrigo\Desktop\appointment_management\venv\Lib\site-packages\django\template\base.py", line 1000, in <listcomp>
    return SafeString("".join([node.render_annotated(context) for node in self]))
                               ^^^^^^^^^^^^^^^^^^^^^^^^^^^^^^
  File "C:\Users\Rodrigo\Desktop\appointment_management\venv\Lib\site-packages\django\template\base.py", line 961, in render_annotated
    return self.render(context)
           ^^^^^^^^^^^^^^^^^^^^
  File "C:\Users\Rodrigo\Desktop\appointment_management\venv\Lib\site-packages\django\template\defaulttags.py", line 326, in render
    return nodelist.render(context)
           ^^^^^^^^^^^^^^^^^^^^^^^^
  File "C:\Users\Rodrigo\Desktop\appointment_management\venv\Lib\site-packages\django\template\base.py", line 1000, in render
    return SafeString("".join([node.render_annotated(context) for node in self]))
                              ^^^^^^^^^^^^^^^^^^^^^^^^^^^^^^^^^^^^^^^^^^^^^^^^^
  File "C:\Users\Rodrigo\Desktop\appointment_management\venv\Lib\site-packages\django\template\base.py", line 1000, in <listcomp>
    return SafeString("".join([node.render_annotated(context) for node in self]))
                               ^^^^^^^^^^^^^^^^^^^^^^^^^^^^^^
  File "C:\Users\Rodrigo\Desktop\appointment_management\venv\Lib\site-packages\django\template\base.py", line 961, in render_annotated
    return self.render(context)
           ^^^^^^^^^^^^^^^^^^^^
  File "C:\Users\Rodrigo\Desktop\appointment_management\venv\Lib\site-packages\django\template\defaulttags.py", line 479, in render
    url = reverse(view_name, args=args, kwargs=kwargs, current_app=current_app)
          ^^^^^^^^^^^^^^^^^^^^^^^^^^^^^^^^^^^^^^^^^^^^^^^^^^^^^^^^^^^^^^^^^^^^^
  File "C:\Users\Rodrigo\Desktop\appointment_management\venv\Lib\site-packages\django\urls\base.py", line 88, in reverse
    return resolver._reverse_with_prefix(view, prefix, *args, **kwargs)
           ^^^^^^^^^^^^^^^^^^^^^^^^^^^^^^^^^^^^^^^^^^^^^^^^^^^^^^^^^^^^
  File "C:\Users\Rodrigo\Desktop\appointment_management\venv\Lib\site-packages\django\urls\resolvers.py", line 851, in _reverse_with_prefix
    raise NoReverseMatch(msg)
django.urls.exceptions.NoReverseMatch: Reverse for 'my_appointment' not found. 'my_appointment' is not a valid view function or pattern name.
"GET /core/home/ HTTP/1.1" 500 171391
Internal Server Error: /core/future_appointments/
Traceback (most recent call last):
  File "C:\Users\Rodrigo\Desktop\appointment_management\venv\Lib\site-packages\django\core\handlers\exception.py", line 55, in inner
    response = get_response(request)
               ^^^^^^^^^^^^^^^^^^^^^
  File "C:\Users\Rodrigo\Desktop\appointment_management\venv\Lib\site-packages\django\core\handlers\base.py", line 197, in _get_response
    response = wrapped_callback(request, *callback_args, **callback_kwargs)
               ^^^^^^^^^^^^^^^^^^^^^^^^^^^^^^^^^^^^^^^^^^^^^^^^^^^^^^^^^^^^
  File "C:\Users\Rodrigo\Desktop\appointment_management\core\views.py", line 262, in future_appointments
    if request.htmx:
       ^^^^^^^^^^^^
AttributeError: 'WSGIRequest' object has no attribute 'htmx'
"GET /core/future_appointments/ HTTP/1.1" 500 68907
Internal Server Error: /core/future_appointments/
Traceback (most recent call last):
  File "C:\Users\Rodrigo\Desktop\appointment_management\venv\Lib\site-packages\django\core\handlers\exception.py", line 55, in inner
    response = get_response(request)
               ^^^^^^^^^^^^^^^^^^^^^
  File "C:\Users\Rodrigo\Desktop\appointment_management\venv\Lib\site-packages\django\core\handlers\base.py", line 197, in _get_response
    response = wrapped_callback(request, *callback_args, **callback_kwargs)
               ^^^^^^^^^^^^^^^^^^^^^^^^^^^^^^^^^^^^^^^^^^^^^^^^^^^^^^^^^^^^
  File "C:\Users\Rodrigo\Desktop\appointment_management\core\views.py", line 262, in future_appointments
    if request.htmx:
       ^^^^^^^^^^^^
AttributeError: 'WSGIRequest' object has no attribute 'htmx'
"GET /core/future_appointments/ HTTP/1.1" 500 68907
Internal Server Error: /core/future_appointments/
Traceback (most recent call last):
  File "C:\Users\Rodrigo\Desktop\appointment_management\venv\Lib\site-packages\django\core\handlers\exception.py", line 55, in inner
    response = get_response(request)
               ^^^^^^^^^^^^^^^^^^^^^
  File "C:\Users\Rodrigo\Desktop\appointment_management\venv\Lib\site-packages\django\core\handlers\base.py", line 197, in _get_response
    response = wrapped_callback(request, *callback_args, **callback_kwargs)
               ^^^^^^^^^^^^^^^^^^^^^^^^^^^^^^^^^^^^^^^^^^^^^^^^^^^^^^^^^^^^
  File "C:\Users\Rodrigo\Desktop\appointment_management\core\views.py", line 262, in future_appointments
    if request.htmx:
       ^^^^^^^^^^^^
AttributeError: 'WSGIRequest' object has no attribute 'htmx'
"GET /core/future_appointments/ HTTP/1.1" 500 68907
Not Found: /core/available_times/No hay doctores disponibles/2024-10-04
"GET /core/available_times/No%20hay%20doctores%20disponibles/2024-10-04 HTTP/1.1" 404 5801
Not Found: /core/available_times/No hay doctores disponibles/2024-10-11
"GET /core/available_times/No%20hay%20doctores%20disponibles/2024-10-11 HTTP/1.1" 404 5801
Not Found: /core/available_times/No hay doctores disponibles/2024-10-22
"GET /core/available_times/No%20hay%20doctores%20disponibles/2024-10-22 HTTP/1.1" 404 5801
Internal Server Error: /core/future_appointments/
Traceback (most recent call last):
  File "C:\Users\Rodrigo\Desktop\appointment_management\venv\Lib\site-packages\django\core\handlers\exception.py", line 55, in inner
    response = get_response(request)
               ^^^^^^^^^^^^^^^^^^^^^
  File "C:\Users\Rodrigo\Desktop\appointment_management\venv\Lib\site-packages\django\core\handlers\base.py", line 197, in _get_response
    response = wrapped_callback(request, *callback_args, **callback_kwargs)
               ^^^^^^^^^^^^^^^^^^^^^^^^^^^^^^^^^^^^^^^^^^^^^^^^^^^^^^^^^^^^
  File "C:\Users\Rodrigo\Desktop\appointment_management\core\views.py", line 262, in future_appointments
    if request.htmx:
       ^^^^^^^^^^^^
AttributeError: 'WSGIRequest' object has no attribute 'htmx'
"GET /core/future_appointments/ HTTP/1.1" 500 68907
Internal Server Error: /admin/core/user/2/delete/
Traceback (most recent call last):
  File "C:\Users\Rodrigo\Desktop\appointment_management\venv\Lib\site-packages\django\db\backends\utils.py", line 105, in _execute
    return self.cursor.execute(sql, params)
           ^^^^^^^^^^^^^^^^^^^^^^^^^^^^^^^^
  File "C:\Users\Rodrigo\Desktop\appointment_management\venv\Lib\site-packages\django\db\backends\sqlite3\base.py", line 329, in execute
    return super().execute(query, params)
           ^^^^^^^^^^^^^^^^^^^^^^^^^^^^^^
sqlite3.OperationalError: no such column: core_appointment.attended

The above exception was the direct cause of the following exception:

Traceback (most recent call last):
  File "C:\Users\Rodrigo\Desktop\appointment_management\venv\Lib\site-packages\django\core\handlers\exception.py", line 55, in inner
    response = get_response(request)
               ^^^^^^^^^^^^^^^^^^^^^
  File "C:\Users\Rodrigo\Desktop\appointment_management\venv\Lib\site-packages\django\core\handlers\base.py", line 197, in _get_response
    response = wrapped_callback(request, *callback_args, **callback_kwargs)
               ^^^^^^^^^^^^^^^^^^^^^^^^^^^^^^^^^^^^^^^^^^^^^^^^^^^^^^^^^^^^
  File "C:\Users\Rodrigo\Desktop\appointment_management\venv\Lib\site-packages\django\contrib\admin\options.py", line 716, in wrapper
    return self.admin_site.admin_view(view)(*args, **kwargs)
           ^^^^^^^^^^^^^^^^^^^^^^^^^^^^^^^^^^^^^^^^^^^^^^^^^
  File "C:\Users\Rodrigo\Desktop\appointment_management\venv\Lib\site-packages\django\utils\decorators.py", line 188, in _view_wrapper
    result = _process_exception(request, e)
             ^^^^^^^^^^^^^^^^^^^^^^^^^^^^^^
  File "C:\Users\Rodrigo\Desktop\appointment_management\venv\Lib\site-packages\django\utils\decorators.py", line 186, in _view_wrapper
    response = view_func(request, *args, **kwargs)
               ^^^^^^^^^^^^^^^^^^^^^^^^^^^^^^^^^^^
  File "C:\Users\Rodrigo\Desktop\appointment_management\venv\Lib\site-packages\django\views\decorators\cache.py", line 80, in _view_wrapper
    response = view_func(request, *args, **kwargs)
               ^^^^^^^^^^^^^^^^^^^^^^^^^^^^^^^^^^^
  File "C:\Users\Rodrigo\Desktop\appointment_management\venv\Lib\site-packages\django\contrib\admin\sites.py", line 240, in inner
    return view(request, *args, **kwargs)
           ^^^^^^^^^^^^^^^^^^^^^^^^^^^^^^
  File "C:\Users\Rodrigo\Desktop\appointment_management\venv\Lib\site-packages\django\utils\decorators.py", line 48, in _wrapper
    return bound_method(*args, **kwargs)
           ^^^^^^^^^^^^^^^^^^^^^^^^^^^^^
  File "C:\Users\Rodrigo\Desktop\appointment_management\venv\Lib\site-packages\django\utils\decorators.py", line 188, in _view_wrapper
    result = _process_exception(request, e)
             ^^^^^^^^^^^^^^^^^^^^^^^^^^^^^^
  File "C:\Users\Rodrigo\Desktop\appointment_management\venv\Lib\site-packages\django\utils\decorators.py", line 186, in _view_wrapper
    response = view_func(request, *args, **kwargs)
               ^^^^^^^^^^^^^^^^^^^^^^^^^^^^^^^^^^^
  File "C:\Users\Rodrigo\Desktop\appointment_management\venv\Lib\site-packages\django\contrib\admin\options.py", line 2165, in delete_view
    return self._delete_view(request, object_id, extra_context)
           ^^^^^^^^^^^^^^^^^^^^^^^^^^^^^^^^^^^^^^^^^^^^^^^^^^^^
  File "C:\Users\Rodrigo\Desktop\appointment_management\venv\Lib\site-packages\django\contrib\admin\options.py", line 2192, in _delete_view
    ) = self.get_deleted_objects([obj], request)
        ^^^^^^^^^^^^^^^^^^^^^^^^^^^^^^^^^^^^^^^^
  File "C:\Users\Rodrigo\Desktop\appointment_management\venv\Lib\site-packages\django\contrib\admin\options.py", line 2160, in get_deleted_objects
    return get_deleted_objects(objs, request, self.admin_site)
           ^^^^^^^^^^^^^^^^^^^^^^^^^^^^^^^^^^^^^^^^^^^^^^^^^^^
  File "C:\Users\Rodrigo\Desktop\appointment_management\venv\Lib\site-packages\django\contrib\admin\utils.py", line 137, in get_deleted_objects
    collector.collect(objs)
  File "C:\Users\Rodrigo\Desktop\appointment_management\venv\Lib\site-packages\django\contrib\admin\utils.py", line 204, in collect
    return super().collect(objs, source_attr=source_attr, **kwargs)
           ^^^^^^^^^^^^^^^^^^^^^^^^^^^^^^^^^^^^^^^^^^^^^^^^^^^^^^^^
  File "C:\Users\Rodrigo\Desktop\appointment_management\venv\Lib\site-packages\django\db\models\deletion.py", line 348, in collect
    if getattr(on_delete, "lazy_sub_objs", False) or sub_objs:
  File "C:\Users\Rodrigo\Desktop\appointment_management\venv\Lib\site-packages\django\db\models\query.py", line 414, in __bool__
    self._fetch_all()
  File "C:\Users\Rodrigo\Desktop\appointment_management\venv\Lib\site-packages\django\db\models\query.py", line 1928, in _fetch_all
    self._result_cache = list(self._iterable_class(self))
                         ^^^^^^^^^^^^^^^^^^^^^^^^^^^^^^^^
  File "C:\Users\Rodrigo\Desktop\appointment_management\venv\Lib\site-packages\django\db\models\query.py", line 91, in __iter__
    results = compiler.execute_sql(
              ^^^^^^^^^^^^^^^^^^^^^
  File "C:\Users\Rodrigo\Desktop\appointment_management\venv\Lib\site-packages\django\db\models\sql\compiler.py", line 1562, in execute_sql
    cursor.execute(sql, params)
  File "C:\Users\Rodrigo\Desktop\appointment_management\venv\Lib\site-packages\django\db\backends\utils.py", line 122, in execute
    return super().execute(sql, params)
           ^^^^^^^^^^^^^^^^^^^^^^^^^^^^
  File "C:\Users\Rodrigo\Desktop\appointment_management\venv\Lib\site-packages\django\db\backends\utils.py", line 79, in execute
    return self._execute_with_wrappers(
           ^^^^^^^^^^^^^^^^^^^^^^^^^^^^
  File "C:\Users\Rodrigo\Desktop\appointment_management\venv\Lib\site-packages\django\db\backends\utils.py", line 92, in _execute_with_wrappers
    return executor(sql, params, many, context)
           ^^^^^^^^^^^^^^^^^^^^^^^^^^^^^^^^^^^^
  File "C:\Users\Rodrigo\Desktop\appointment_management\venv\Lib\site-packages\django\db\backends\utils.py", line 100, in _execute
    with self.db.wrap_database_errors:
  File "C:\Users\Rodrigo\Desktop\appointment_management\venv\Lib\site-packages\django\db\utils.py", line 91, in __exit__
    raise dj_exc_value.with_traceback(traceback) from exc_value
  File "C:\Users\Rodrigo\Desktop\appointment_management\venv\Lib\site-packages\django\db\backends\utils.py", line 105, in _execute
    return self.cursor.execute(sql, params)
           ^^^^^^^^^^^^^^^^^^^^^^^^^^^^^^^^
  File "C:\Users\Rodrigo\Desktop\appointment_management\venv\Lib\site-packages\django\db\backends\sqlite3\base.py", line 329, in execute
    return super().execute(query, params)
           ^^^^^^^^^^^^^^^^^^^^^^^^^^^^^^
django.db.utils.OperationalError: no such column: core_appointment.attended
"GET /admin/core/user/2/delete/?_to_field=id&_popup=1 HTTP/1.1" 500 213241
Internal Server Error: /admin/core/user/2/delete/
Traceback (most recent call last):
  File "C:\Users\Rodrigo\Desktop\appointment_management\venv\Lib\site-packages\django\db\backends\utils.py", line 105, in _execute
    return self.cursor.execute(sql, params)
           ^^^^^^^^^^^^^^^^^^^^^^^^^^^^^^^^
  File "C:\Users\Rodrigo\Desktop\appointment_management\venv\Lib\site-packages\django\db\backends\sqlite3\base.py", line 329, in execute
    return super().execute(query, params)
           ^^^^^^^^^^^^^^^^^^^^^^^^^^^^^^
sqlite3.OperationalError: no such column: core_appointment.attended

The above exception was the direct cause of the following exception:

Traceback (most recent call last):
  File "C:\Users\Rodrigo\Desktop\appointment_management\venv\Lib\site-packages\django\core\handlers\exception.py", line 55, in inner
    response = get_response(request)
               ^^^^^^^^^^^^^^^^^^^^^
  File "C:\Users\Rodrigo\Desktop\appointment_management\venv\Lib\site-packages\django\core\handlers\base.py", line 197, in _get_response
    response = wrapped_callback(request, *callback_args, **callback_kwargs)
               ^^^^^^^^^^^^^^^^^^^^^^^^^^^^^^^^^^^^^^^^^^^^^^^^^^^^^^^^^^^^
  File "C:\Users\Rodrigo\Desktop\appointment_management\venv\Lib\site-packages\django\contrib\admin\options.py", line 716, in wrapper
    return self.admin_site.admin_view(view)(*args, **kwargs)
           ^^^^^^^^^^^^^^^^^^^^^^^^^^^^^^^^^^^^^^^^^^^^^^^^^
  File "C:\Users\Rodrigo\Desktop\appointment_management\venv\Lib\site-packages\django\utils\decorators.py", line 188, in _view_wrapper
    result = _process_exception(request, e)
             ^^^^^^^^^^^^^^^^^^^^^^^^^^^^^^
  File "C:\Users\Rodrigo\Desktop\appointment_management\venv\Lib\site-packages\django\utils\decorators.py", line 186, in _view_wrapper
    response = view_func(request, *args, **kwargs)
               ^^^^^^^^^^^^^^^^^^^^^^^^^^^^^^^^^^^
  File "C:\Users\Rodrigo\Desktop\appointment_management\venv\Lib\site-packages\django\views\decorators\cache.py", line 80, in _view_wrapper
    response = view_func(request, *args, **kwargs)
               ^^^^^^^^^^^^^^^^^^^^^^^^^^^^^^^^^^^
  File "C:\Users\Rodrigo\Desktop\appointment_management\venv\Lib\site-packages\django\contrib\admin\sites.py", line 240, in inner
    return view(request, *args, **kwargs)
           ^^^^^^^^^^^^^^^^^^^^^^^^^^^^^^
  File "C:\Users\Rodrigo\Desktop\appointment_management\venv\Lib\site-packages\django\utils\decorators.py", line 48, in _wrapper
    return bound_method(*args, **kwargs)
           ^^^^^^^^^^^^^^^^^^^^^^^^^^^^^
  File "C:\Users\Rodrigo\Desktop\appointment_management\venv\Lib\site-packages\django\utils\decorators.py", line 188, in _view_wrapper
    result = _process_exception(request, e)
             ^^^^^^^^^^^^^^^^^^^^^^^^^^^^^^
  File "C:\Users\Rodrigo\Desktop\appointment_management\venv\Lib\site-packages\django\utils\decorators.py", line 186, in _view_wrapper
    response = view_func(request, *args, **kwargs)
               ^^^^^^^^^^^^^^^^^^^^^^^^^^^^^^^^^^^
  File "C:\Users\Rodrigo\Desktop\appointment_management\venv\Lib\site-packages\django\contrib\admin\options.py", line 2165, in delete_view
    return self._delete_view(request, object_id, extra_context)
           ^^^^^^^^^^^^^^^^^^^^^^^^^^^^^^^^^^^^^^^^^^^^^^^^^^^^
  File "C:\Users\Rodrigo\Desktop\appointment_management\venv\Lib\site-packages\django\contrib\admin\options.py", line 2192, in _delete_view
    ) = self.get_deleted_objects([obj], request)
        ^^^^^^^^^^^^^^^^^^^^^^^^^^^^^^^^^^^^^^^^
  File "C:\Users\Rodrigo\Desktop\appointment_management\venv\Lib\site-packages\django\contrib\admin\options.py", line 2160, in get_deleted_objects
    return get_deleted_objects(objs, request, self.admin_site)
           ^^^^^^^^^^^^^^^^^^^^^^^^^^^^^^^^^^^^^^^^^^^^^^^^^^^
  File "C:\Users\Rodrigo\Desktop\appointment_management\venv\Lib\site-packages\django\contrib\admin\utils.py", line 137, in get_deleted_objects
    collector.collect(objs)
  File "C:\Users\Rodrigo\Desktop\appointment_management\venv\Lib\site-packages\django\contrib\admin\utils.py", line 204, in collect
    return super().collect(objs, source_attr=source_attr, **kwargs)
           ^^^^^^^^^^^^^^^^^^^^^^^^^^^^^^^^^^^^^^^^^^^^^^^^^^^^^^^^
  File "C:\Users\Rodrigo\Desktop\appointment_management\venv\Lib\site-packages\django\db\models\deletion.py", line 348, in collect
    if getattr(on_delete, "lazy_sub_objs", False) or sub_objs:
  File "C:\Users\Rodrigo\Desktop\appointment_management\venv\Lib\site-packages\django\db\models\query.py", line 414, in __bool__
    self._fetch_all()
  File "C:\Users\Rodrigo\Desktop\appointment_management\venv\Lib\site-packages\django\db\models\query.py", line 1928, in _fetch_all
    self._result_cache = list(self._iterable_class(self))
                         ^^^^^^^^^^^^^^^^^^^^^^^^^^^^^^^^
  File "C:\Users\Rodrigo\Desktop\appointment_management\venv\Lib\site-packages\django\db\models\query.py", line 91, in __iter__
    results = compiler.execute_sql(
              ^^^^^^^^^^^^^^^^^^^^^
  File "C:\Users\Rodrigo\Desktop\appointment_management\venv\Lib\site-packages\django\db\models\sql\compiler.py", line 1562, in execute_sql
    cursor.execute(sql, params)
  File "C:\Users\Rodrigo\Desktop\appointment_management\venv\Lib\site-packages\django\db\backends\utils.py", line 122, in execute
    return super().execute(sql, params)
           ^^^^^^^^^^^^^^^^^^^^^^^^^^^^
  File "C:\Users\Rodrigo\Desktop\appointment_management\venv\Lib\site-packages\django\db\backends\utils.py", line 79, in execute
    return self._execute_with_wrappers(
           ^^^^^^^^^^^^^^^^^^^^^^^^^^^^
  File "C:\Users\Rodrigo\Desktop\appointment_management\venv\Lib\site-packages\django\db\backends\utils.py", line 92, in _execute_with_wrappers
    return executor(sql, params, many, context)
           ^^^^^^^^^^^^^^^^^^^^^^^^^^^^^^^^^^^^
  File "C:\Users\Rodrigo\Desktop\appointment_management\venv\Lib\site-packages\django\db\backends\utils.py", line 100, in _execute
    with self.db.wrap_database_errors:
  File "C:\Users\Rodrigo\Desktop\appointment_management\venv\Lib\site-packages\django\db\utils.py", line 91, in __exit__
    raise dj_exc_value.with_traceback(traceback) from exc_value
  File "C:\Users\Rodrigo\Desktop\appointment_management\venv\Lib\site-packages\django\db\backends\utils.py", line 105, in _execute
    return self.cursor.execute(sql, params)
           ^^^^^^^^^^^^^^^^^^^^^^^^^^^^^^^^
  File "C:\Users\Rodrigo\Desktop\appointment_management\venv\Lib\site-packages\django\db\backends\sqlite3\base.py", line 329, in execute
    return super().execute(query, params)
           ^^^^^^^^^^^^^^^^^^^^^^^^^^^^^^
django.db.utils.OperationalError: no such column: core_appointment.attended
"GET /admin/core/user/2/delete/?_to_field=id&_popup=1 HTTP/1.1" 500 213241
Internal Server Error: /core/future_appointments/
Traceback (most recent call last):
  File "C:\Users\Rodrigo\Desktop\appointment_management\venv\Lib\site-packages\django\core\handlers\exception.py", line 55, in inner
    response = get_response(request)
               ^^^^^^^^^^^^^^^^^^^^^
  File "C:\Users\Rodrigo\Desktop\appointment_management\venv\Lib\site-packages\django\core\handlers\base.py", line 197, in _get_response
    response = wrapped_callback(request, *callback_args, **callback_kwargs)
               ^^^^^^^^^^^^^^^^^^^^^^^^^^^^^^^^^^^^^^^^^^^^^^^^^^^^^^^^^^^^
  File "C:\Users\Rodrigo\Desktop\appointment_management\core\views.py", line 264, in future_appointments
    if request.htmx:
       ^^^^^^^^^^^^
AttributeError: 'WSGIRequest' object has no attribute 'htmx'
"GET /core/future_appointments/ HTTP/1.1" 500 68907
Not Found: /favicon.ico
"GET /favicon.ico HTTP/1.1" 404 2440
Not Found: /favicon.ico
"GET /favicon.ico HTTP/1.1" 404 2440
Not Found: /favicon.ico
"GET /favicon.ico HTTP/1.1" 404 2440
Internal Server Error: /core/future_appointments/
Traceback (most recent call last):
  File "C:\Users\Rodrigo\Desktop\appointment_management\venv\Lib\site-packages\django\core\handlers\exception.py", line 55, in inner
    response = get_response(request)
               ^^^^^^^^^^^^^^^^^^^^^
  File "C:\Users\Rodrigo\Desktop\appointment_management\venv\Lib\site-packages\django\core\handlers\base.py", line 197, in _get_response
    response = wrapped_callback(request, *callback_args, **callback_kwargs)
               ^^^^^^^^^^^^^^^^^^^^^^^^^^^^^^^^^^^^^^^^^^^^^^^^^^^^^^^^^^^^
  File "C:\Users\Rodrigo\Desktop\appointment_management\core\views.py", line 264, in future_appointments
    if request.htmx:
       ^^^^^^^^^^^^
AttributeError: 'WSGIRequest' object has no attribute 'htmx'
"GET /core/future_appointments/ HTTP/1.1" 500 68883
Not Found: /favicon.ico
"GET /favicon.ico HTTP/1.1" 404 2440
Internal Server Error: /core/future_appointments/
Traceback (most recent call last):
  File "C:\Users\Rodrigo\Desktop\appointment_management\venv\Lib\site-packages\django\core\handlers\exception.py", line 55, in inner
    response = get_response(request)
               ^^^^^^^^^^^^^^^^^^^^^
  File "C:\Users\Rodrigo\Desktop\appointment_management\venv\Lib\site-packages\django\core\handlers\base.py", line 197, in _get_response
    response = wrapped_callback(request, *callback_args, **callback_kwargs)
               ^^^^^^^^^^^^^^^^^^^^^^^^^^^^^^^^^^^^^^^^^^^^^^^^^^^^^^^^^^^^
  File "C:\Users\Rodrigo\Desktop\appointment_management\core\views.py", line 264, in future_appointments
    if request.htmx:
       ^^^^^^^^^^^^
AttributeError: 'WSGIRequest' object has no attribute 'htmx'
"GET /core/future_appointments/ HTTP/1.1" 500 71123
Internal Server Error: /core/future_appointments/
Traceback (most recent call last):
  File "C:\Users\Rodrigo\Desktop\appointment_management\venv\Lib\site-packages\django\core\handlers\exception.py", line 55, in inner
    response = get_response(request)
               ^^^^^^^^^^^^^^^^^^^^^
  File "C:\Users\Rodrigo\Desktop\appointment_management\venv\Lib\site-packages\django\core\handlers\base.py", line 197, in _get_response
    response = wrapped_callback(request, *callback_args, **callback_kwargs)
               ^^^^^^^^^^^^^^^^^^^^^^^^^^^^^^^^^^^^^^^^^^^^^^^^^^^^^^^^^^^^
  File "C:\Users\Rodrigo\Desktop\appointment_management\core\views.py", line 265, in future_appointments
    if request.htmx:
       ^^^^^^^^^^^^
AttributeError: 'WSGIRequest' object has no attribute 'htmx'
"GET /core/future_appointments/ HTTP/1.1" 500 71123
Internal Server Error: /core/future_appointments/
Traceback (most recent call last):
  File "C:\Users\Rodrigo\Desktop\appointment_management\venv\Lib\site-packages\django\core\handlers\exception.py", line 55, in inner
    response = get_response(request)
               ^^^^^^^^^^^^^^^^^^^^^
  File "C:\Users\Rodrigo\Desktop\appointment_management\venv\Lib\site-packages\django\core\handlers\base.py", line 197, in _get_response
    response = wrapped_callback(request, *callback_args, **callback_kwargs)
               ^^^^^^^^^^^^^^^^^^^^^^^^^^^^^^^^^^^^^^^^^^^^^^^^^^^^^^^^^^^^
  File "C:\Users\Rodrigo\Desktop\appointment_management\core\views.py", line 265, in future_appointments
    if request.htmx:
       ^^^^^^^^^^^^
AttributeError: 'WSGIRequest' object has no attribute 'htmx'
"GET /core/future_appointments/ HTTP/1.1" 500 71123
Internal Server Error: /core/future_appointments/
Traceback (most recent call last):
  File "C:\Users\Rodrigo\Desktop\appointment_management\venv\Lib\site-packages\django\core\handlers\exception.py", line 55, in inner
    response = get_response(request)
               ^^^^^^^^^^^^^^^^^^^^^
  File "C:\Users\Rodrigo\Desktop\appointment_management\venv\Lib\site-packages\django\core\handlers\base.py", line 197, in _get_response
    response = wrapped_callback(request, *callback_args, **callback_kwargs)
               ^^^^^^^^^^^^^^^^^^^^^^^^^^^^^^^^^^^^^^^^^^^^^^^^^^^^^^^^^^^^
  File "C:\Users\Rodrigo\Desktop\appointment_management\core\views.py", line 265, in future_appointments
    if request.htmx:
       ^^^^^^^^^^^^
AttributeError: 'WSGIRequest' object has no attribute 'htmx'
"GET /core/future_appointments/ HTTP/1.1" 500 71006
Internal Server Error: /core/future_appointments/
Traceback (most recent call last):
  File "C:\Users\Rodrigo\Desktop\appointment_management\venv\Lib\site-packages\django\core\handlers\exception.py", line 55, in inner
    response = get_response(request)
               ^^^^^^^^^^^^^^^^^^^^^
  File "C:\Users\Rodrigo\Desktop\appointment_management\venv\Lib\site-packages\django\core\handlers\base.py", line 197, in _get_response
    response = wrapped_callback(request, *callback_args, **callback_kwargs)
               ^^^^^^^^^^^^^^^^^^^^^^^^^^^^^^^^^^^^^^^^^^^^^^^^^^^^^^^^^^^^
  File "C:\Users\Rodrigo\Desktop\appointment_management\core\views.py", line 265, in future_appointments
    if request.htmx:
       ^^^^^^^^^^^^
AttributeError: 'WSGIRequest' object has no attribute 'htmx'
"GET /core/future_appointments/ HTTP/1.1" 500 71006
"GET /static/bootstrap/css/bootstrap.min.css.map HTTP/1.1" 404 1864
"GET /static/bootstrap/css/bootstrap.min.css.map HTTP/1.1" 404 1864
"GET /static/bootstrap/css/bootstrap.min.css.map HTTP/1.1" 404 1864
"GET /static/bootstrap/css/bootstrap.min.css.map HTTP/1.1" 404 1864
"GET /static/bootstrap/css/bootstrap.min.css.map HTTP/1.1" 404 1864
"GET /static/bootstrap/css/bootstrap.min.css.map HTTP/1.1" 404 1864
"GET /static/bootstrap/css/bootstrap.min.css.map HTTP/1.1" 404 1864
"GET /static/bootstrap/css/bootstrap.min.css.map HTTP/1.1" 404 1864
"GET /static/bootstrap/css/bootstrap.min.css.map HTTP/1.1" 404 1864
"GET /static/bootstrap/css/bootstrap.min.css.map HTTP/1.1" 404 1864
Not Found: /favicon.ico
"GET /favicon.ico HTTP/1.1" 404 2440
Not Found: /favicon.ico
"GET /favicon.ico HTTP/1.1" 404 2440
Internal Server Error: /core/patient/my_appointments/
Traceback (most recent call last):
  File "C:\Users\Rodrigo\Desktop\appointment_management\venv\Lib\site-packages\django\core\handlers\exception.py", line 55, in inner
    response = get_response(request)
               ^^^^^^^^^^^^^^^^^^^^^
  File "C:\Users\Rodrigo\Desktop\appointment_management\venv\Lib\site-packages\django\core\handlers\base.py", line 197, in _get_response
    response = wrapped_callback(request, *callback_args, **callback_kwargs)
               ^^^^^^^^^^^^^^^^^^^^^^^^^^^^^^^^^^^^^^^^^^^^^^^^^^^^^^^^^^^^
  File "C:\Users\Rodrigo\Desktop\appointment_management\venv\Lib\site-packages\django\contrib\auth\decorators.py", line 23, in _wrapper_view
    return view_func(request, *args, **kwargs)
           ^^^^^^^^^^^^^^^^^^^^^^^^^^^^^^^^^^^
  File "C:\Users\Rodrigo\Desktop\appointment_management\venv\Lib\site-packages\django\contrib\auth\decorators.py", line 23, in _wrapper_view
    return view_func(request, *args, **kwargs)
           ^^^^^^^^^^^^^^^^^^^^^^^^^^^^^^^^^^^
  File "C:\Users\Rodrigo\Desktop\appointment_management\core\views.py", line 64, in my_appointments
    return render(request, 'patient/my_appointments.html')
           ^^^^^^^^^^^^^^^^^^^^^^^^^^^^^^^^^^^^^^^^^^^^^^^
  File "C:\Users\Rodrigo\Desktop\appointment_management\venv\Lib\site-packages\django\shortcuts.py", line 25, in render
    content = loader.render_to_string(template_name, context, request, using=using)
              ^^^^^^^^^^^^^^^^^^^^^^^^^^^^^^^^^^^^^^^^^^^^^^^^^^^^^^^^^^^^^^^^^^^^^
  File "C:\Users\Rodrigo\Desktop\appointment_management\venv\Lib\site-packages\django\template\loader.py", line 62, in render_to_string
    return template.render(context, request)
           ^^^^^^^^^^^^^^^^^^^^^^^^^^^^^^^^^
  File "C:\Users\Rodrigo\Desktop\appointment_management\venv\Lib\site-packages\django\template\backends\django.py", line 61, in render
    return self.template.render(context)
           ^^^^^^^^^^^^^^^^^^^^^^^^^^^^^
  File "C:\Users\Rodrigo\Desktop\appointment_management\venv\Lib\site-packages\django\template\base.py", line 171, in render
    return self._render(context)
           ^^^^^^^^^^^^^^^^^^^^^
  File "C:\Users\Rodrigo\Desktop\appointment_management\venv\Lib\site-packages\django\template\base.py", line 163, in _render
    return self.nodelist.render(context)
           ^^^^^^^^^^^^^^^^^^^^^^^^^^^^^
  File "C:\Users\Rodrigo\Desktop\appointment_management\venv\Lib\site-packages\django\template\base.py", line 1000, in render
    return SafeString("".join([node.render_annotated(context) for node in self]))
                              ^^^^^^^^^^^^^^^^^^^^^^^^^^^^^^^^^^^^^^^^^^^^^^^^^
  File "C:\Users\Rodrigo\Desktop\appointment_management\venv\Lib\site-packages\django\template\base.py", line 1000, in <listcomp>
    return SafeString("".join([node.render_annotated(context) for node in self]))
                               ^^^^^^^^^^^^^^^^^^^^^^^^^^^^^^
  File "C:\Users\Rodrigo\Desktop\appointment_management\venv\Lib\site-packages\django\template\base.py", line 961, in render_annotated
    return self.render(context)
           ^^^^^^^^^^^^^^^^^^^^
  File "C:\Users\Rodrigo\Desktop\appointment_management\venv\Lib\site-packages\django\template\loader_tags.py", line 159, in render
    return compiled_parent._render(context)
           ^^^^^^^^^^^^^^^^^^^^^^^^^^^^^^^^
  File "C:\Users\Rodrigo\Desktop\appointment_management\venv\Lib\site-packages\django\template\base.py", line 163, in _render
    return self.nodelist.render(context)
           ^^^^^^^^^^^^^^^^^^^^^^^^^^^^^
  File "C:\Users\Rodrigo\Desktop\appointment_management\venv\Lib\site-packages\django\template\base.py", line 1000, in render
    return SafeString("".join([node.render_annotated(context) for node in self]))
                              ^^^^^^^^^^^^^^^^^^^^^^^^^^^^^^^^^^^^^^^^^^^^^^^^^
  File "C:\Users\Rodrigo\Desktop\appointment_management\venv\Lib\site-packages\django\template\base.py", line 1000, in <listcomp>
    return SafeString("".join([node.render_annotated(context) for node in self]))
                               ^^^^^^^^^^^^^^^^^^^^^^^^^^^^^^
  File "C:\Users\Rodrigo\Desktop\appointment_management\venv\Lib\site-packages\django\template\base.py", line 961, in render_annotated
    return self.render(context)
           ^^^^^^^^^^^^^^^^^^^^
  File "C:\Users\Rodrigo\Desktop\appointment_management\venv\Lib\site-packages\django\template\defaulttags.py", line 479, in render
    url = reverse(view_name, args=args, kwargs=kwargs, current_app=current_app)
          ^^^^^^^^^^^^^^^^^^^^^^^^^^^^^^^^^^^^^^^^^^^^^^^^^^^^^^^^^^^^^^^^^^^^^
  File "C:\Users\Rodrigo\Desktop\appointment_management\venv\Lib\site-packages\django\urls\base.py", line 88, in reverse
    return resolver._reverse_with_prefix(view, prefix, *args, **kwargs)
           ^^^^^^^^^^^^^^^^^^^^^^^^^^^^^^^^^^^^^^^^^^^^^^^^^^^^^^^^^^^^
  File "C:\Users\Rodrigo\Desktop\appointment_management\venv\Lib\site-packages\django\urls\resolvers.py", line 851, in _reverse_with_prefix
    raise NoReverseMatch(msg)
django.urls.exceptions.NoReverseMatch: Reverse for 'cancel_appointment' with no arguments not found. 1 pattern(s) tried: ['core/appointment/(?P<appointment_id>[0-9]+)/cancel/\\Z']
"GET /core/patient/my_appointments/ HTTP/1.1" 500 161658
Not Found: /favicon.ico
"GET /favicon.ico HTTP/1.1" 404 2440
Not Found: /appointment//cancel/
"DELETE /appointment//cancel/ HTTP/1.1" 404 2470
Not Found: /appointment//cancel/
"DELETE /appointment//cancel/ HTTP/1.1" 404 2470
Not Found: /appointment//cancel/
"DELETE /appointment//cancel/ HTTP/1.1" 404 2470
Not Found: /appointment//cancel/
"DELETE /appointment//cancel/ HTTP/1.1" 404 2470
Not Found: /appointment//cancel/
"DELETE /appointment//cancel/ HTTP/1.1" 404 2470
Not Found: /appointment//cancel/
"DELETE /appointment//cancel/ HTTP/1.1" 404 2470
Not Found: /appointment//cancel/
"DELETE /appointment//cancel/ HTTP/1.1" 404 2470
Not Found: /appointment//cancel/
"DELETE /appointment//cancel/ HTTP/1.1" 404 2470
Not Found: /appointment//cancel/
"DELETE /appointment//cancel/ HTTP/1.1" 404 2470
Not Found: /appointment//cancel/
"DELETE /appointment//cancel/ HTTP/1.1" 404 2470
Not Found: /favicon.ico
"GET /favicon.ico HTTP/1.1" 404 2440
Not Found: /appointment//cancel/
"DELETE /appointment//cancel/ HTTP/1.1" 404 2470
Not Found: /appointment//cancel/
"DELETE /appointment//cancel/ HTTP/1.1" 404 2470
"GET /static/bootstrap/css/bootstrap.min.css.map HTTP/1.1" 404 1864
Not Found: /favicon.ico
"GET /favicon.ico HTTP/1.1" 404 2440
Not Found: /appointment//cancel/
"DELETE /appointment//cancel/ HTTP/1.1" 404 2470
Not Found: /appointment//cancel/
"DELETE /appointment//cancel/ HTTP/1.1" 404 2470
Not Found: /appointment//cancel/
"DELETE /appointment//cancel/ HTTP/1.1" 404 2470
Not Found: /favicon.ico
"GET /favicon.ico HTTP/1.1" 404 2440
Not Found: /appointment//cancel/
"DELETE /appointment//cancel/ HTTP/1.1" 404 2470
Not Found: /appointment//cancel/
"DELETE /appointment//cancel/ HTTP/1.1" 404 2470
Not Found: /appointment//cancel/
"DELETE /appointment//cancel/ HTTP/1.1" 404 2470
Not Found: /appointment//cancel/
"DELETE /appointment//cancel/ HTTP/1.1" 404 2470
Not Found: /favicon.ico
"GET /favicon.ico HTTP/1.1" 404 2440
Not Found: /appointment//cancel/
"DELETE /appointment//cancel/ HTTP/1.1" 404 2470
Not Found: /appointment//cancel/
"DELETE /appointment//cancel/ HTTP/1.1" 404 2470
Not Found: /appointment//cancel/
"DELETE /appointment//cancel/ HTTP/1.1" 404 2470
Not Found: /appointment//cancel/
"DELETE /appointment//cancel/ HTTP/1.1" 404 2470
Internal Server Error: /core/appointment/11/cancel/
"GET /core/appointment/11/cancel/ HTTP/1.1" 500 0
Internal Server Error: /core/appointment/11/cancel/
"GET /core/appointment/11/cancel/ HTTP/1.1" 500 0
Not Found: /appointment//cancel/
"DELETE /appointment//cancel/ HTTP/1.1" 404 2470
Not Found: /appointment/11/cancel/
"GET /appointment/11/cancel/ HTTP/1.1" 404 2473
Not Found: /appointment/11/cancel/
"GET /appointment/11/cancel/ HTTP/1.1" 404 2473
Not Found: /core/patient/appointment/11/cancel/
"GET /core/patient/appointment/11/cancel/ HTTP/1.1" 404 6175
Not Found: /favicon.ico
"GET /favicon.ico HTTP/1.1" 404 2440
Not Found: /appointment//cancel/
"DELETE /appointment//cancel/ HTTP/1.1" 404 2470
Not Found: /appointment//cancel/
"DELETE /appointment//cancel/ HTTP/1.1" 404 2470
Not Found: /appointment//cancel/
"DELETE /appointment//cancel/ HTTP/1.1" 404 2470
Not Found: /appointment//cancel/
"DELETE /appointment//cancel/ HTTP/1.1" 404 2470
Not Found: /appointment//cancel/
"DELETE /appointment//cancel/ HTTP/1.1" 404 2470
Not Found: /appointment//cancel/
"DELETE /appointment//cancel/ HTTP/1.1" 404 2470
Not Found: /appointment//cancel/
"DELETE /appointment//cancel/ HTTP/1.1" 404 2470
Not Found: /appointment//cancel/
"DELETE /appointment//cancel/ HTTP/1.1" 404 2470
Not Found: /appointment//cancel/
"DELETE /appointment//cancel/ HTTP/1.1" 404 2470
Not Found: /appointment/12/cancel/
"DELETE /appointment/12/cancel/ HTTP/1.1" 404 2476
Not Found: /appointment//cancel/
"DELETE /appointment//cancel/ HTTP/1.1" 404 2470
Not Found: /appointment//cancel/
"DELETE /appointment//cancel/ HTTP/1.1" 404 2470
Not Found: /appointment//cancel/
"GET /appointment//cancel/ HTTP/1.1" 404 2467
Not Found: /appointment/12/cancel/
"GET /appointment/12/cancel/ HTTP/1.1" 404 2473
Forbidden (CSRF token missing.): /core/appointment/12/cancel/
"DELETE /core/appointment/12/cancel/ HTTP/1.1" 403 2516
Forbidden (CSRF token missing.): /core/appointment/12/cancel/
"DELETE /core/appointment/12/cancel/ HTTP/1.1" 403 2516
Forbidden (CSRF token missing.): /core/appointment/12/cancel/
"DELETE /core/appointment/12/cancel/ HTTP/1.1" 403 2516
Forbidden (CSRF token missing.): /core/appointment/12/cancel/
"DELETE /core/appointment/12/cancel/ HTTP/1.1" 403 2516
Forbidden (CSRF token missing.): /core/appointment/14/cancel/
"DELETE /core/appointment/14/cancel/ HTTP/1.1" 403 2516
Forbidden (CSRF token missing.): /core/appointment/14/cancel/
"DELETE /core/appointment/14/cancel/ HTTP/1.1" 403 2516
Forbidden (CSRF token missing.): /core/appointment/14/cancel/
"DELETE /core/appointment/14/cancel/ HTTP/1.1" 403 2516
Forbidden (CSRF token missing.): /core/appointment/14/cancel/
"DELETE /core/appointment/14/cancel/ HTTP/1.1" 403 2516
Forbidden (CSRF token missing.): /core/appointment/14/cancel/
"DELETE /core/appointment/14/cancel/ HTTP/1.1" 403 2516
Forbidden (CSRF token missing.): /core/appointment/15/cancel/
"DELETE /core/appointment/15/cancel/ HTTP/1.1" 403 2516
Not Found: /favicon.ico
"GET /favicon.ico HTTP/1.1" 404 2440
Not Found: /favicon.ico
"GET /favicon.ico HTTP/1.1" 404 2440
Not Found: /favicon.ico
"GET /favicon.ico HTTP/1.1" 404 2440
Not Found: /favicon.ico
"GET /favicon.ico HTTP/1.1" 404 2440
Not Found: /favicon.ico
"GET /favicon.ico HTTP/1.1" 404 2440
Not Found: /favicon.ico
"GET /favicon.ico HTTP/1.1" 404 2440
Forbidden (CSRF token missing.): /core/appointment/26/cancel/
"DELETE /core/appointment/26/cancel/ HTTP/1.1" 403 2516
Forbidden (CSRF token missing.): /core/appointment/26/cancel/
"DELETE /core/appointment/26/cancel/ HTTP/1.1" 403 2516
Forbidden (CSRF token missing.): /core/appointment/26/cancel/
"DELETE /core/appointment/26/cancel/ HTTP/1.1" 403 2516
Forbidden (CSRF token missing.): /core/appointment/26/cancel/
"DELETE /core/appointment/26/cancel/ HTTP/1.1" 403 2516
Forbidden (CSRF token missing.): /core/appointment/26/cancel/
"DELETE /core/appointment/26/cancel/ HTTP/1.1" 403 2516
Forbidden (CSRF token missing.): /core/appointment/26/cancel/
"DELETE /core/appointment/26/cancel/ HTTP/1.1" 403 2516
Forbidden (CSRF token missing.): /core/appointment/26/cancel/
"DELETE /core/appointment/26/cancel/ HTTP/1.1" 403 2516
Forbidden (CSRF token missing.): /core/appointment/26/cancel/
"DELETE /core/appointment/26/cancel/ HTTP/1.1" 403 2516
Not Found: /favicon.ico
"GET /favicon.ico HTTP/1.1" 404 2440
Forbidden (CSRF token missing.): /core/appointment/26/cancel/
"DELETE /core/appointment/26/cancel/ HTTP/1.1" 403 2516
Forbidden (CSRF token missing.): /core/appointment/26/cancel/
"DELETE /core/appointment/26/cancel/ HTTP/1.1" 403 2516
Not Found: /favicon.ico
"GET /favicon.ico HTTP/1.1" 404 2440
Not Found: /favicon.ico
"GET /favicon.ico HTTP/1.1" 404 2440
Not Found: /favicon.ico
"GET /favicon.ico HTTP/1.1" 404 2440
Forbidden (CSRF token from the 'X-Csrftoken' HTTP header has incorrect length.): /core/appointment/32/cancel/
"DELETE /core/appointment/32/cancel/ HTTP/1.1" 403 2574
Forbidden (CSRF token from the 'X-Csrftoken' HTTP header has incorrect length.): /core/appointment/32/cancel/
"DELETE /core/appointment/32/cancel/ HTTP/1.1" 403 2574
Forbidden (CSRF token from the 'X-Csrftoken' HTTP header has incorrect length.): /core/appointment/32/cancel/
"DELETE /core/appointment/32/cancel/ HTTP/1.1" 403 2574
Forbidden (CSRF token from the 'X-Csrftoken' HTTP header has incorrect length.): /core/appointment/32/cancel/
"DELETE /core/appointment/32/cancel/ HTTP/1.1" 403 2574
Not Found: /favicon.ico
"GET /favicon.ico HTTP/1.1" 404 2440
Not Found: /patient/appointment_history/
"POST /patient/appointment_history/ HTTP/1.1" 404 2492
Not Found: /favicon.ico
"GET /favicon.ico HTTP/1.1" 404 2440
Not Found: /patient/appointment-history/
"POST /patient/appointment-history/ HTTP/1.1" 404 2492
Not Found: /patient/appointment-history/
"POST /patient/appointment-history/ HTTP/1.1" 404 2492
Not Found: /patient/appointment-history/
"POST /patient/appointment-history/ HTTP/1.1" 404 2492
Not Found: /favicon.ico
"GET /favicon.ico HTTP/1.1" 404 2440
Internal Server Error: /core/appointment-history/
"POST /core/appointment-history/ HTTP/1.1" 500 78
Method Not Allowed: /core/appointment-history/
"GET /core/appointment-history/ HTTP/1.1" 405 39
Method Not Allowed: /core/appointment-history/
"GET /core/appointment-history/ HTTP/1.1" 405 39
Method Not Allowed: /core/appointment-history/
"GET /core/appointment-history/ HTTP/1.1" 405 39
Not Found: /favicon.ico
"GET /favicon.ico HTTP/1.1" 404 2440
Internal Server Error: /core/appointment-history/
"GET /core/appointment-history/ HTTP/1.1" 500 78
Internal Server Error: /core/appointment-history/
"GET /core/appointment-history/ HTTP/1.1" 500 78
Internal Server Error: /core/appointment-history/
"GET /core/appointment-history/ HTTP/1.1" 500 78
Not Found: /favicon.ico
"GET /favicon.ico HTTP/1.1" 404 2440
Not Found: /favicon.ico
"GET /favicon.ico HTTP/1.1" 404 2440
Not Found: /favicon.ico
"GET /favicon.ico HTTP/1.1" 404 2440
Not Found: /favicon.ico
"GET /favicon.ico HTTP/1.1" 404 2440
Not Found: /core/appointment-details/11/
"GET /core/appointment-details/11/ HTTP/1.1" 404 6354
Not Found: /core/appointment-details/11/
"GET /core/appointment-details/11/ HTTP/1.1" 404 6354
Not Found: /core/appointment-details/12/
"GET /core/appointment-details/12/ HTTP/1.1" 404 6354
Not Found: /core/appointment-details/12/
"GET /core/appointment-details/12/ HTTP/1.1" 404 6354
Not Found: /core/appointment-details/11/
"GET /core/appointment-details/11/ HTTP/1.1" 404 6354
Not Found: /core/appointment-details/11/
"GET /core/appointment-details/11/ HTTP/1.1" 404 6354
Not Found: /favicon.ico
"GET /favicon.ico HTTP/1.1" 404 2440
Not Found: /favicon.ico
"GET /favicon.ico HTTP/1.1" 404 2440
Not Found: /favicon.ico
"GET /favicon.ico HTTP/1.1" 404 2440
Not Found: /favicon.ico
"GET /favicon.ico HTTP/1.1" 404 2440
Not Found: /favicon.ico
"GET /favicon.ico HTTP/1.1" 404 2440
Not Found: /favicon.ico
"GET /favicon.ico HTTP/1.1" 404 2440
Not Found: /favicon.ico
"GET /favicon.ico HTTP/1.1" 404 2440
Not Found: /favicon.ico
"GET /favicon.ico HTTP/1.1" 404 2440
Not Found: /favicon.ico
"GET /favicon.ico HTTP/1.1" 404 2440
Not Found: /favicon.ico
"GET /favicon.ico HTTP/1.1" 404 2440
Not Found: /favicon.ico
"GET /favicon.ico HTTP/1.1" 404 2440
Not Found: /favicon.ico
"GET /favicon.ico HTTP/1.1" 404 2440
Not Found: /favicon.ico
"GET /favicon.ico HTTP/1.1" 404 2440
Not Found: /favicon.ico
"GET /favicon.ico HTTP/1.1" 404 2440
Not Found: /favicon.ico
"GET /favicon.ico HTTP/1.1" 404 2440
Not Found: /favicon.ico
"GET /favicon.ico HTTP/1.1" 404 2440
Not Found: /favicon.ico
"GET /favicon.ico HTTP/1.1" 404 2440
Not Found: /favicon.ico
"GET /favicon.ico HTTP/1.1" 404 2440
Not Found: /favicon.ico
"GET /favicon.ico HTTP/1.1" 404 2440
Not Found: /favicon.ico
"GET /favicon.ico HTTP/1.1" 404 2440
Not Found: /favicon.ico
"GET /favicon.ico HTTP/1.1" 404 2440
Not Found: /favicon.ico
"GET /favicon.ico HTTP/1.1" 404 2440
Not Found: /favicon.ico
"GET /favicon.ico HTTP/1.1" 404 2440
Not Found: /favicon.ico
"GET /favicon.ico HTTP/1.1" 404 2440
Not Found: /favicon.ico
"GET /favicon.ico HTTP/1.1" 404 2440
Not Found: /favicon.ico
"GET /favicon.ico HTTP/1.1" 404 2440
Not Found: /favicon.ico
"GET /favicon.ico HTTP/1.1" 404 2440
Internal Server Error: /core/diagnostics-history/
"GET /core/diagnostics-history/ HTTP/1.1" 500 80
Internal Server Error: /core/diagnostics-history/
"GET /core/diagnostics-history/ HTTP/1.1" 500 80
Internal Server Error: /core/diagnostics-history/
"GET /core/diagnostics-history/ HTTP/1.1" 500 80
Internal Server Error: /core/diagnostics-history/
"GET /core/diagnostics-history/ HTTP/1.1" 500 80
Internal Server Error: /core/diagnostics-history/
"GET /core/diagnostics-history/ HTTP/1.1" 500 80
Not Found: /favicon.ico
"GET /favicon.ico HTTP/1.1" 404 2440
Internal Server Error: /core/diagnostics-history/
"GET /core/diagnostics-history/ HTTP/1.1" 500 80
Internal Server Error: /core/diagnostics-history/
"GET /core/diagnostics-history/ HTTP/1.1" 500 80
Internal Server Error: /core/diagnostics-history/
"GET /core/diagnostics-history/ HTTP/1.1" 500 80
Internal Server Error: /core/diagnostic/2/details/
Traceback (most recent call last):
  File "C:\Users\Rodrigo\Desktop\appointment_management\venv\Lib\site-packages\django\core\handlers\exception.py", line 55, in inner
    response = get_response(request)
               ^^^^^^^^^^^^^^^^^^^^^
  File "C:\Users\Rodrigo\Desktop\appointment_management\venv\Lib\site-packages\django\core\handlers\base.py", line 197, in _get_response
    response = wrapped_callback(request, *callback_args, **callback_kwargs)
               ^^^^^^^^^^^^^^^^^^^^^^^^^^^^^^^^^^^^^^^^^^^^^^^^^^^^^^^^^^^^
  File "C:\Users\Rodrigo\Desktop\appointment_management\venv\Lib\site-packages\django\contrib\auth\decorators.py", line 23, in _wrapper_view
    return view_func(request, *args, **kwargs)
           ^^^^^^^^^^^^^^^^^^^^^^^^^^^^^^^^^^^
  File "C:\Users\Rodrigo\Desktop\appointment_management\core\views.py", line 430, in diagnostic_details
    return render(request, 'diagnostic_details.html', context)
           ^^^^^^^^^^^^^^^^^^^^^^^^^^^^^^^^^^^^^^^^^^^^^^^^^^^
  File "C:\Users\Rodrigo\Desktop\appointment_management\venv\Lib\site-packages\django\shortcuts.py", line 25, in render
    content = loader.render_to_string(template_name, context, request, using=using)
              ^^^^^^^^^^^^^^^^^^^^^^^^^^^^^^^^^^^^^^^^^^^^^^^^^^^^^^^^^^^^^^^^^^^^^
  File "C:\Users\Rodrigo\Desktop\appointment_management\venv\Lib\site-packages\django\template\loader.py", line 61, in render_to_string
    template = get_template(template_name, using=using)
               ^^^^^^^^^^^^^^^^^^^^^^^^^^^^^^^^^^^^^^^^
  File "C:\Users\Rodrigo\Desktop\appointment_management\venv\Lib\site-packages\django\template\loader.py", line 19, in get_template
    raise TemplateDoesNotExist(template_name, chain=chain)
django.template.exceptions.TemplateDoesNotExist: diagnostic_details.html
"GET /core/diagnostic/2/details/ HTTP/1.1" 500 91728
Internal Server Error: /core/diagnostic/2/details/
Traceback (most recent call last):
  File "C:\Users\Rodrigo\Desktop\appointment_management\venv\Lib\site-packages\django\core\handlers\exception.py", line 55, in inner
    response = get_response(request)
               ^^^^^^^^^^^^^^^^^^^^^
  File "C:\Users\Rodrigo\Desktop\appointment_management\venv\Lib\site-packages\django\core\handlers\base.py", line 197, in _get_response
    response = wrapped_callback(request, *callback_args, **callback_kwargs)
               ^^^^^^^^^^^^^^^^^^^^^^^^^^^^^^^^^^^^^^^^^^^^^^^^^^^^^^^^^^^^
  File "C:\Users\Rodrigo\Desktop\appointment_management\venv\Lib\site-packages\django\contrib\auth\decorators.py", line 23, in _wrapper_view
    return view_func(request, *args, **kwargs)
           ^^^^^^^^^^^^^^^^^^^^^^^^^^^^^^^^^^^
  File "C:\Users\Rodrigo\Desktop\appointment_management\core\views.py", line 430, in diagnostic_details
    return render(request, 'diagnostic_details.html', context)
           ^^^^^^^^^^^^^^^^^^^^^^^^^^^^^^^^^^^^^^^^^^^^^^^^^^^
  File "C:\Users\Rodrigo\Desktop\appointment_management\venv\Lib\site-packages\django\shortcuts.py", line 25, in render
    content = loader.render_to_string(template_name, context, request, using=using)
              ^^^^^^^^^^^^^^^^^^^^^^^^^^^^^^^^^^^^^^^^^^^^^^^^^^^^^^^^^^^^^^^^^^^^^
  File "C:\Users\Rodrigo\Desktop\appointment_management\venv\Lib\site-packages\django\template\loader.py", line 61, in render_to_string
    template = get_template(template_name, using=using)
               ^^^^^^^^^^^^^^^^^^^^^^^^^^^^^^^^^^^^^^^^
  File "C:\Users\Rodrigo\Desktop\appointment_management\venv\Lib\site-packages\django\template\loader.py", line 19, in get_template
    raise TemplateDoesNotExist(template_name, chain=chain)
django.template.exceptions.TemplateDoesNotExist: diagnostic_details.html
"GET /core/diagnostic/2/details/ HTTP/1.1" 500 91728
Internal Server Error: /core/diagnostic/2/details/
Traceback (most recent call last):
  File "C:\Users\Rodrigo\Desktop\appointment_management\venv\Lib\site-packages\django\core\handlers\exception.py", line 55, in inner
    response = get_response(request)
               ^^^^^^^^^^^^^^^^^^^^^
  File "C:\Users\Rodrigo\Desktop\appointment_management\venv\Lib\site-packages\django\core\handlers\base.py", line 197, in _get_response
    response = wrapped_callback(request, *callback_args, **callback_kwargs)
               ^^^^^^^^^^^^^^^^^^^^^^^^^^^^^^^^^^^^^^^^^^^^^^^^^^^^^^^^^^^^
  File "C:\Users\Rodrigo\Desktop\appointment_management\venv\Lib\site-packages\django\contrib\auth\decorators.py", line 23, in _wrapper_view
    return view_func(request, *args, **kwargs)
           ^^^^^^^^^^^^^^^^^^^^^^^^^^^^^^^^^^^
  File "C:\Users\Rodrigo\Desktop\appointment_management\core\views.py", line 430, in diagnostic_details
    return render(request, 'diagnostic_details.html', context)
           ^^^^^^^^^^^^^^^^^^^^^^^^^^^^^^^^^^^^^^^^^^^^^^^^^^^
  File "C:\Users\Rodrigo\Desktop\appointment_management\venv\Lib\site-packages\django\shortcuts.py", line 25, in render
    content = loader.render_to_string(template_name, context, request, using=using)
              ^^^^^^^^^^^^^^^^^^^^^^^^^^^^^^^^^^^^^^^^^^^^^^^^^^^^^^^^^^^^^^^^^^^^^
  File "C:\Users\Rodrigo\Desktop\appointment_management\venv\Lib\site-packages\django\template\loader.py", line 61, in render_to_string
    template = get_template(template_name, using=using)
               ^^^^^^^^^^^^^^^^^^^^^^^^^^^^^^^^^^^^^^^^
  File "C:\Users\Rodrigo\Desktop\appointment_management\venv\Lib\site-packages\django\template\loader.py", line 19, in get_template
    raise TemplateDoesNotExist(template_name, chain=chain)
django.template.exceptions.TemplateDoesNotExist: diagnostic_details.html
"GET /core/diagnostic/2/details/ HTTP/1.1" 500 91728
Internal Server Error: /core/diagnostic/2/details/
Traceback (most recent call last):
  File "C:\Users\Rodrigo\Desktop\appointment_management\venv\Lib\site-packages\django\core\handlers\exception.py", line 55, in inner
    response = get_response(request)
               ^^^^^^^^^^^^^^^^^^^^^
  File "C:\Users\Rodrigo\Desktop\appointment_management\venv\Lib\site-packages\django\core\handlers\base.py", line 197, in _get_response
    response = wrapped_callback(request, *callback_args, **callback_kwargs)
               ^^^^^^^^^^^^^^^^^^^^^^^^^^^^^^^^^^^^^^^^^^^^^^^^^^^^^^^^^^^^
  File "C:\Users\Rodrigo\Desktop\appointment_management\venv\Lib\site-packages\django\contrib\auth\decorators.py", line 23, in _wrapper_view
    return view_func(request, *args, **kwargs)
           ^^^^^^^^^^^^^^^^^^^^^^^^^^^^^^^^^^^
  File "C:\Users\Rodrigo\Desktop\appointment_management\core\views.py", line 430, in diagnostic_details
    return render(request, 'diagnostic_details.html', context)
           ^^^^^^^^^^^^^^^^^^^^^^^^^^^^^^^^^^^^^^^^^^^^^^^^^^^
  File "C:\Users\Rodrigo\Desktop\appointment_management\venv\Lib\site-packages\django\shortcuts.py", line 25, in render
    content = loader.render_to_string(template_name, context, request, using=using)
              ^^^^^^^^^^^^^^^^^^^^^^^^^^^^^^^^^^^^^^^^^^^^^^^^^^^^^^^^^^^^^^^^^^^^^
  File "C:\Users\Rodrigo\Desktop\appointment_management\venv\Lib\site-packages\django\template\loader.py", line 61, in render_to_string
    template = get_template(template_name, using=using)
               ^^^^^^^^^^^^^^^^^^^^^^^^^^^^^^^^^^^^^^^^
  File "C:\Users\Rodrigo\Desktop\appointment_management\venv\Lib\site-packages\django\template\loader.py", line 19, in get_template
    raise TemplateDoesNotExist(template_name, chain=chain)
django.template.exceptions.TemplateDoesNotExist: diagnostic_details.html
"GET /core/diagnostic/2/details/ HTTP/1.1" 500 91728
Internal Server Error: /core/diagnostic/2/details/
Traceback (most recent call last):
  File "C:\Users\Rodrigo\Desktop\appointment_management\venv\Lib\site-packages\django\core\handlers\exception.py", line 55, in inner
    response = get_response(request)
               ^^^^^^^^^^^^^^^^^^^^^
  File "C:\Users\Rodrigo\Desktop\appointment_management\venv\Lib\site-packages\django\core\handlers\base.py", line 197, in _get_response
    response = wrapped_callback(request, *callback_args, **callback_kwargs)
               ^^^^^^^^^^^^^^^^^^^^^^^^^^^^^^^^^^^^^^^^^^^^^^^^^^^^^^^^^^^^
  File "C:\Users\Rodrigo\Desktop\appointment_management\venv\Lib\site-packages\django\contrib\auth\decorators.py", line 23, in _wrapper_view
    return view_func(request, *args, **kwargs)
           ^^^^^^^^^^^^^^^^^^^^^^^^^^^^^^^^^^^
  File "C:\Users\Rodrigo\Desktop\appointment_management\core\views.py", line 430, in diagnostic_details
    return render(request, 'diagnostic_details.html', context)
           ^^^^^^^^^^^^^^^^^^^^^^^^^^^^^^^^^^^^^^^^^^^^^^^^^^^
  File "C:\Users\Rodrigo\Desktop\appointment_management\venv\Lib\site-packages\django\shortcuts.py", line 25, in render
    content = loader.render_to_string(template_name, context, request, using=using)
              ^^^^^^^^^^^^^^^^^^^^^^^^^^^^^^^^^^^^^^^^^^^^^^^^^^^^^^^^^^^^^^^^^^^^^
  File "C:\Users\Rodrigo\Desktop\appointment_management\venv\Lib\site-packages\django\template\loader.py", line 61, in render_to_string
    template = get_template(template_name, using=using)
               ^^^^^^^^^^^^^^^^^^^^^^^^^^^^^^^^^^^^^^^^
  File "C:\Users\Rodrigo\Desktop\appointment_management\venv\Lib\site-packages\django\template\loader.py", line 19, in get_template
    raise TemplateDoesNotExist(template_name, chain=chain)
django.template.exceptions.TemplateDoesNotExist: diagnostic_details.html
"GET /core/diagnostic/2/details/ HTTP/1.1" 500 91748
Internal Server Error: /core/diagnostic/2/details/
Traceback (most recent call last):
  File "C:\Users\Rodrigo\Desktop\appointment_management\venv\Lib\site-packages\django\core\handlers\exception.py", line 55, in inner
    response = get_response(request)
               ^^^^^^^^^^^^^^^^^^^^^
  File "C:\Users\Rodrigo\Desktop\appointment_management\venv\Lib\site-packages\django\core\handlers\base.py", line 197, in _get_response
    response = wrapped_callback(request, *callback_args, **callback_kwargs)
               ^^^^^^^^^^^^^^^^^^^^^^^^^^^^^^^^^^^^^^^^^^^^^^^^^^^^^^^^^^^^
  File "C:\Users\Rodrigo\Desktop\appointment_management\venv\Lib\site-packages\django\contrib\auth\decorators.py", line 23, in _wrapper_view
    return view_func(request, *args, **kwargs)
           ^^^^^^^^^^^^^^^^^^^^^^^^^^^^^^^^^^^
  File "C:\Users\Rodrigo\Desktop\appointment_management\core\views.py", line 430, in diagnostic_details
    return render(request, 'diagnostic_details.html', context)
           ^^^^^^^^^^^^^^^^^^^^^^^^^^^^^^^^^^^^^^^^^^^^^^^^^^^
  File "C:\Users\Rodrigo\Desktop\appointment_management\venv\Lib\site-packages\django\shortcuts.py", line 25, in render
    content = loader.render_to_string(template_name, context, request, using=using)
              ^^^^^^^^^^^^^^^^^^^^^^^^^^^^^^^^^^^^^^^^^^^^^^^^^^^^^^^^^^^^^^^^^^^^^
  File "C:\Users\Rodrigo\Desktop\appointment_management\venv\Lib\site-packages\django\template\loader.py", line 61, in render_to_string
    template = get_template(template_name, using=using)
               ^^^^^^^^^^^^^^^^^^^^^^^^^^^^^^^^^^^^^^^^
  File "C:\Users\Rodrigo\Desktop\appointment_management\venv\Lib\site-packages\django\template\loader.py", line 19, in get_template
    raise TemplateDoesNotExist(template_name, chain=chain)
django.template.exceptions.TemplateDoesNotExist: diagnostic_details.html
"GET /core/diagnostic/2/details/ HTTP/1.1" 500 91748
Internal Server Error: /core/diagnostic/2/details/
Traceback (most recent call last):
  File "C:\Users\Rodrigo\Desktop\appointment_management\venv\Lib\site-packages\django\core\handlers\exception.py", line 55, in inner
    response = get_response(request)
               ^^^^^^^^^^^^^^^^^^^^^
  File "C:\Users\Rodrigo\Desktop\appointment_management\venv\Lib\site-packages\django\core\handlers\base.py", line 197, in _get_response
    response = wrapped_callback(request, *callback_args, **callback_kwargs)
               ^^^^^^^^^^^^^^^^^^^^^^^^^^^^^^^^^^^^^^^^^^^^^^^^^^^^^^^^^^^^
  File "C:\Users\Rodrigo\Desktop\appointment_management\venv\Lib\site-packages\django\contrib\auth\decorators.py", line 23, in _wrapper_view
    return view_func(request, *args, **kwargs)
           ^^^^^^^^^^^^^^^^^^^^^^^^^^^^^^^^^^^
  File "C:\Users\Rodrigo\Desktop\appointment_management\core\views.py", line 430, in diagnostic_details
    return render(request, 'diagnostic_details.html', context)
           ^^^^^^^^^^^^^^^^^^^^^^^^^^^^^^^^^^^^^^^^^^^^^^^^^^^
  File "C:\Users\Rodrigo\Desktop\appointment_management\venv\Lib\site-packages\django\shortcuts.py", line 25, in render
    content = loader.render_to_string(template_name, context, request, using=using)
              ^^^^^^^^^^^^^^^^^^^^^^^^^^^^^^^^^^^^^^^^^^^^^^^^^^^^^^^^^^^^^^^^^^^^^
  File "C:\Users\Rodrigo\Desktop\appointment_management\venv\Lib\site-packages\django\template\loader.py", line 61, in render_to_string
    template = get_template(template_name, using=using)
               ^^^^^^^^^^^^^^^^^^^^^^^^^^^^^^^^^^^^^^^^
  File "C:\Users\Rodrigo\Desktop\appointment_management\venv\Lib\site-packages\django\template\loader.py", line 19, in get_template
    raise TemplateDoesNotExist(template_name, chain=chain)
django.template.exceptions.TemplateDoesNotExist: diagnostic_details.html
"GET /core/diagnostic/2/details/ HTTP/1.1" 500 91748
Internal Server Error: /core/diagnostic/2/details/
Traceback (most recent call last):
  File "C:\Users\Rodrigo\Desktop\appointment_management\venv\Lib\site-packages\django\core\handlers\exception.py", line 55, in inner
    response = get_response(request)
               ^^^^^^^^^^^^^^^^^^^^^
  File "C:\Users\Rodrigo\Desktop\appointment_management\venv\Lib\site-packages\django\core\handlers\base.py", line 197, in _get_response
    response = wrapped_callback(request, *callback_args, **callback_kwargs)
               ^^^^^^^^^^^^^^^^^^^^^^^^^^^^^^^^^^^^^^^^^^^^^^^^^^^^^^^^^^^^
  File "C:\Users\Rodrigo\Desktop\appointment_management\venv\Lib\site-packages\django\contrib\auth\decorators.py", line 23, in _wrapper_view
    return view_func(request, *args, **kwargs)
           ^^^^^^^^^^^^^^^^^^^^^^^^^^^^^^^^^^^
  File "C:\Users\Rodrigo\Desktop\appointment_management\core\views.py", line 430, in diagnostic_details
    return render(request, 'diagnostic_details.html', context)
           ^^^^^^^^^^^^^^^^^^^^^^^^^^^^^^^^^^^^^^^^^^^^^^^^^^^
  File "C:\Users\Rodrigo\Desktop\appointment_management\venv\Lib\site-packages\django\shortcuts.py", line 25, in render
    content = loader.render_to_string(template_name, context, request, using=using)
              ^^^^^^^^^^^^^^^^^^^^^^^^^^^^^^^^^^^^^^^^^^^^^^^^^^^^^^^^^^^^^^^^^^^^^
  File "C:\Users\Rodrigo\Desktop\appointment_management\venv\Lib\site-packages\django\template\loader.py", line 61, in render_to_string
    template = get_template(template_name, using=using)
               ^^^^^^^^^^^^^^^^^^^^^^^^^^^^^^^^^^^^^^^^
  File "C:\Users\Rodrigo\Desktop\appointment_management\venv\Lib\site-packages\django\template\loader.py", line 19, in get_template
    raise TemplateDoesNotExist(template_name, chain=chain)
django.template.exceptions.TemplateDoesNotExist: diagnostic_details.html
"GET /core/diagnostic/2/details/ HTTP/1.1" 500 91748
Internal Server Error: /core/diagnostic/2/details/
Traceback (most recent call last):
  File "C:\Users\Rodrigo\Desktop\appointment_management\venv\Lib\site-packages\django\core\handlers\exception.py", line 55, in inner
    response = get_response(request)
               ^^^^^^^^^^^^^^^^^^^^^
  File "C:\Users\Rodrigo\Desktop\appointment_management\venv\Lib\site-packages\django\core\handlers\base.py", line 197, in _get_response
    response = wrapped_callback(request, *callback_args, **callback_kwargs)
               ^^^^^^^^^^^^^^^^^^^^^^^^^^^^^^^^^^^^^^^^^^^^^^^^^^^^^^^^^^^^
  File "C:\Users\Rodrigo\Desktop\appointment_management\venv\Lib\site-packages\django\contrib\auth\decorators.py", line 23, in _wrapper_view
    return view_func(request, *args, **kwargs)
           ^^^^^^^^^^^^^^^^^^^^^^^^^^^^^^^^^^^
  File "C:\Users\Rodrigo\Desktop\appointment_management\core\views.py", line 430, in diagnostic_details
    return render(request, 'diagnostic_details.html', context)
           ^^^^^^^^^^^^^^^^^^^^^^^^^^^^^^^^^^^^^^^^^^^^^^^^^^^
  File "C:\Users\Rodrigo\Desktop\appointment_management\venv\Lib\site-packages\django\shortcuts.py", line 25, in render
    content = loader.render_to_string(template_name, context, request, using=using)
              ^^^^^^^^^^^^^^^^^^^^^^^^^^^^^^^^^^^^^^^^^^^^^^^^^^^^^^^^^^^^^^^^^^^^^
  File "C:\Users\Rodrigo\Desktop\appointment_management\venv\Lib\site-packages\django\template\loader.py", line 61, in render_to_string
    template = get_template(template_name, using=using)
               ^^^^^^^^^^^^^^^^^^^^^^^^^^^^^^^^^^^^^^^^
  File "C:\Users\Rodrigo\Desktop\appointment_management\venv\Lib\site-packages\django\template\loader.py", line 19, in get_template
    raise TemplateDoesNotExist(template_name, chain=chain)
django.template.exceptions.TemplateDoesNotExist: diagnostic_details.html
"GET /core/diagnostic/2/details/ HTTP/1.1" 500 91748
Not Found: /favicon.ico
"GET /favicon.ico HTTP/1.1" 404 2440
Internal Server Error: /core/diagnostics-history/
"GET /core/diagnostics-history/ HTTP/1.1" 500 83
Internal Server Error: /core/diagnostics-history/
"GET /core/diagnostics-history/ HTTP/1.1" 500 83
Internal Server Error: /admin/core/medicalhistory/add/
Traceback (most recent call last):
  File "C:\Users\Rodrigo\Desktop\appointment_management\venv\Lib\site-packages\django\contrib\admin\options.py", line 837, in get_form
    return modelform_factory(self.model, **defaults)
           ^^^^^^^^^^^^^^^^^^^^^^^^^^^^^^^^^^^^^^^^^
  File "C:\Users\Rodrigo\Desktop\appointment_management\venv\Lib\site-packages\django\forms\models.py", line 652, in modelform_factory
    return type(form)(class_name, (form,), form_class_attrs)
           ^^^^^^^^^^^^^^^^^^^^^^^^^^^^^^^^^^^^^^^^^^^^^^^^^
  File "C:\Users\Rodrigo\Desktop\appointment_management\venv\Lib\site-packages\django\forms\models.py", line 332, in __new__
    raise FieldError(message)
django.core.exceptions.FieldError: Unknown field(s) (appointment_id) specified for MedicalHistory

During handling of the above exception, another exception occurred:

Traceback (most recent call last):
  File "C:\Users\Rodrigo\Desktop\appointment_management\venv\Lib\site-packages\django\core\handlers\exception.py", line 55, in inner
    response = get_response(request)
               ^^^^^^^^^^^^^^^^^^^^^
  File "C:\Users\Rodrigo\Desktop\appointment_management\venv\Lib\site-packages\django\core\handlers\base.py", line 197, in _get_response
    response = wrapped_callback(request, *callback_args, **callback_kwargs)
               ^^^^^^^^^^^^^^^^^^^^^^^^^^^^^^^^^^^^^^^^^^^^^^^^^^^^^^^^^^^^
  File "C:\Users\Rodrigo\Desktop\appointment_management\venv\Lib\site-packages\django\contrib\admin\options.py", line 716, in wrapper
    return self.admin_site.admin_view(view)(*args, **kwargs)
           ^^^^^^^^^^^^^^^^^^^^^^^^^^^^^^^^^^^^^^^^^^^^^^^^^
  File "C:\Users\Rodrigo\Desktop\appointment_management\venv\Lib\site-packages\django\utils\decorators.py", line 188, in _view_wrapper
    result = _process_exception(request, e)
             ^^^^^^^^^^^^^^^^^^^^^^^^^^^^^^
  File "C:\Users\Rodrigo\Desktop\appointment_management\venv\Lib\site-packages\django\utils\decorators.py", line 186, in _view_wrapper
    response = view_func(request, *args, **kwargs)
               ^^^^^^^^^^^^^^^^^^^^^^^^^^^^^^^^^^^
  File "C:\Users\Rodrigo\Desktop\appointment_management\venv\Lib\site-packages\django\views\decorators\cache.py", line 80, in _view_wrapper
    response = view_func(request, *args, **kwargs)
               ^^^^^^^^^^^^^^^^^^^^^^^^^^^^^^^^^^^
  File "C:\Users\Rodrigo\Desktop\appointment_management\venv\Lib\site-packages\django\contrib\admin\sites.py", line 240, in inner
    return view(request, *args, **kwargs)
           ^^^^^^^^^^^^^^^^^^^^^^^^^^^^^^
  File "C:\Users\Rodrigo\Desktop\appointment_management\venv\Lib\site-packages\django\contrib\admin\options.py", line 1945, in add_view
    return self.changeform_view(request, None, form_url, extra_context)
           ^^^^^^^^^^^^^^^^^^^^^^^^^^^^^^^^^^^^^^^^^^^^^^^^^^^^^^^^^^^^
  File "C:\Users\Rodrigo\Desktop\appointment_management\venv\Lib\site-packages\django\utils\decorators.py", line 48, in _wrapper
    return bound_method(*args, **kwargs)
           ^^^^^^^^^^^^^^^^^^^^^^^^^^^^^
  File "C:\Users\Rodrigo\Desktop\appointment_management\venv\Lib\site-packages\django\utils\decorators.py", line 188, in _view_wrapper
    result = _process_exception(request, e)
             ^^^^^^^^^^^^^^^^^^^^^^^^^^^^^^
  File "C:\Users\Rodrigo\Desktop\appointment_management\venv\Lib\site-packages\django\utils\decorators.py", line 186, in _view_wrapper
    response = view_func(request, *args, **kwargs)
               ^^^^^^^^^^^^^^^^^^^^^^^^^^^^^^^^^^^
  File "C:\Users\Rodrigo\Desktop\appointment_management\venv\Lib\site-packages\django\contrib\admin\options.py", line 1804, in changeform_view
    return self._changeform_view(request, object_id, form_url, extra_context)
           ^^^^^^^^^^^^^^^^^^^^^^^^^^^^^^^^^^^^^^^^^^^^^^^^^^^^^^^^^^^^^^^^^^
  File "C:\Users\Rodrigo\Desktop\appointment_management\venv\Lib\site-packages\django\contrib\admin\options.py", line 1839, in _changeform_view
    ModelForm = self.get_form(
                ^^^^^^^^^^^^^^
  File "C:\Users\Rodrigo\Desktop\appointment_management\venv\Lib\site-packages\django\contrib\admin\options.py", line 839, in get_form
    raise FieldError(
django.core.exceptions.FieldError: Unknown field(s) (appointment_id) specified for MedicalHistory. Check fields/fieldsets/exclude attributes of class MedicalHistoryAdmin.
"GET /admin/core/medicalhistory/add/ HTTP/1.1" 500 151605
Not Found: /favicon.ico
"GET /favicon.ico HTTP/1.1" 404 2440
